Workbook

Sheet COVER
B1: M4Di | OI Tool + ALDi Budget Tracker
B2: 1212 Lobdel Avenue — Multi-Unit Affordable Infill | Document M2_2026_004 | Version v1
B3: April 9, 2026 | Gate: G0 — ROM | Lead: Merge 4 Design LLC (M4D) | (c) 2026 M4Di / M4D
B5: PROJECT IDENTITY
B6: Project Code | C6: M2_2026_004 | E6: ALDi document number
B7: Project Name | C7: 1212 Lobdel Avenue — Multi-Unit Affordable Infill
B8: Address | C8: 1212 Lobdel Avenue, Wilmington, DE 19801
B9: Client / Owner | C9: Wilmington Housing Authority (WHA)
B10: Lead Firm | C10: Merge 4 Design LLC (M4D) | E10: M4D holds prime WHA contract
B11: AOR | C11: Aubyn Architecture LLC (subconsultant) | E11: Subconsultant to M4D
B12: ALDi Gate | C12: G0 — ROM | E12: G0=ROM | G1=Feasibility | G2=75%DD | G3=GMP | G4=Closeout
B13: Document Date | C13: April 9, 2026
B14: Version | C14: v1 | E14: Each version is a fresh complete document
B15: Governing Code | C15: City of Wilmington R-3 — One-Family Row Houses (Ch.48) | E15: NOT NCC UDC — City of Wilmington Ch.48 only
B17: SITE & PROGRAM — DATA SPINE
B18: Site Area (SF) | C18: 61705 | E18: Confirmed: 175 ft x 352.6 ft
B19: Site Area (Acres) | C19: 1.39
B20: Site Dimensions | C20: 175 ft x 352.6 ft | E20: Width x Depth
B21: Former Use | C21: School facility — fully cleared | E21: No demolition assumed
B22: Zoning | C22: R-3 | E22: City of Wilmington One-Family Row Houses
B23: Construction Type | C23: B - Off-Site Modular | E23: A=CLT/SIP | B=Modular | C=Stick
B24: Total Units (Scen. I) | C24: 36 | E24: 4 rows x 9 units x 18 ft wide
B25: Units Per Row | C25: 9 | E25: Max 10 per Wilmington building code Sec.504.4.2
B26: Number of Rows | C26: 4 | E26: 4-row layout
B27: Unit Width (ft) | C27: 18 | E27: Exceeds existing 14-16 ft block face stock
B28: Unit Depth (ft) | C28: 35
B29: Unit Size (SF) | C29: 1260 | E29: 18 ft x 35 ft x 2 stories
B30: Total GFA (SF) | C30: 45360 | E30: 36 units x 1260 SF
B31: Front Setback (adopted, ft) | C31: 20 | E31: Exceeds <17 ft contextual avg. New standard.
B32: Rear Setback (required, ft) | C32: 20 | E32: Per Sec.48-155
B33: Site Depth Used (ft) | C33: 240 | E33: 20+4x35+3x20+20 = 240 ft
B34: Surplus Depth (ft) | C34: 112.6 | E34: Parking, garden, bio-retention
B37: COLUMN D — ROM (LOCKED AT GATE 0)
B38: LINE ITEM | C38: AMOUNT ($) | E38: NOTES
B39: Sitework / Civil | C39: 432000
B40: Foundations (modular-spec) | C40: 816480
B41: Modular Factory Units (factory-complete) | C41: 3009600
B42: Freight + Set (crane, ~200 mi) | C42: 540000
B43: Site MEP Tie-Ins + Utility Connections | C43: 306000
B44: Exterior Finish Completion | C44: 726000
...

Sheet ASSUMPTIONS
B1: PROJECT ASSUMPTIONS & CONTROLS
B2: Input | C2: Value | E2: Notes
B3: Project Name | C3: 1212 Lobdel Avenue — Multi-Unit Affordable Infill | E3: Use a short, consistent project code (e.g., WHACC-2026).
B4: Estimate Date | E4: Enter as MM/DD/YYYY. Update with each revision.
B5: Estimate Type | C5: ROM / Conceptual | E5: ROM / Conceptual | Schematic | Design Development | GMP
B6: Project Type | C6: Interior Improvement | E6: Interior Improvement | Adaptive Reuse | New Construction | Mixed-Use
B7: Client / Owner | E7: Legal entity name of the owner organization.
B8: Site Address | E8: Full property address for zoning lookup reference.
B9: Total Gross Area (SF) | C9: 8700 | E9: Total gross building SF affected by the scope.
B10: Base Region | C10: Delaware | E10: Delaware = M4Di baseline. All unit prices sourced from Delaware competitive bid market.
B11: Selected Pricing Region | C11: New Castle/Wilmington | E11: Must match a region defined in REGIONAL FACTORS sheet.
B12: Weighted Trade Labor Factor | C12: =IFERROR(INDEX('REGIONAL FACTORS'!H$4:H$20,MATCH(C11,'REGIONAL FACTORS'!A$4:A$20,0)),1) | E12: Auto-pulled from REGIONAL FACTORS. 1.000x = Delaware baseline. Philadelphia Metro ≈ 1.145x.
B13: COST ESCALATION
B14: ENR Construction Cost Index (CCI) Escalation % | C14: 0.027 | E14: Source: ENR CCI Q1 2026. Update quarterly. Applies to all labor-heavy items.
B15: ENR Building Cost Index (BCI) Escalation % | C15: 0.043 | E15: Source: ENR BCI Q1 2026. Update quarterly. Applies to material-heavy items.
B16: Blended Escalation Rate | C16: =AVERAGE(C14,C15) | E16: Formula: average of CCI and BCI. Used in unit price adjusted cost calculation.
B17: Material / Market Factor | C17: 1 | E17: Adjust for procurement pressure, bid climate volatility, or material shortages. 1.000x = neutral.
B18: MARKUPS & CONTINGENCIES
B19: General Conditions % | C19: 0.08 | E19: Typical range: 6%–10%. Covers on-site supervision, temporary facilities, insurance.
B20: Overhead & Profit (OH&P) % | C20: 0.1 | E20: Typical range: 8%–12%. Applied to subtotal after GC.
B21: Design Contingency % | C21: 0.12 | E21: Reduce to 8% at SD; 5% at DD; 0% at GMP. Reflects design development risk.
B22: Existing Conditions Contingency % | C22: 0.1 | E22: Higher for gut renovations (12%–15%). Covers concealed conditions and substrate damage.
B23: Equipment / Owner Selection Contingency % | C23: 0.08 | E23: Reduce as owner selections are confirmed. Set to 0% when all allowances are locked.
B24: Bid / Permit / Bonds % | C24: 0.02 | E24: Covers permitting fees, bid bonds, performance bonds. Adjust for municipality.
B25: Sales Tax % | C25: 0 | E25: Delaware: 0%. Adjust for other jurisdictions. Apply only to taxable material costs if split.
B26: Total Contingency % | C26: =C21+C22+C23 | E26: Sum of all contingency lines. For reference only.
B28: QUICK REFERENCE TOTALS (auto-calculated from BID SUMMARY)
B29: Base Building Subtotal | C29: ='BID SUMMARY'!C3
B30: Equipment Allowances | C30: ='BID SUMMARY'!C4
B31: Subtotal Before Markups | C31: ='BID SUMMARY'!C5
B32: General Conditions | C32: ='BID SUMMARY'!C6
B33: OH&P | C33: ='BID SUMMARY'!C7
B34: Total Contingencies | C34: ='BID SUMMARY'!C8
B35: Bid / Permit / Bonds | C35: ='BID SUMMARY'!C9
B36: TOTAL PROJECT ROM | C36: ='BID SUMMARY'!C10
B37: FEE SCHEDULE CONTROLS (feeds SOFT COSTS sheet)
B38: AIA Project Type Code | C38: C | E38: A=warehouse, B=office, C=school/fitness (M4Di default), D=clinic/theater, E=hospital/research.
B39: Renovation Project? | C39: Yes | E39: Yes adds renovation premium to base architecture fee. WHACC = Yes.

Sheet REGIONAL FACTORS
B1: REGIONAL MARKET FACTORS — Public Data-Based Labor Basket
B2: Region | C2: Carpenters $/hr | D2: Laborers $/hr | E2: Electricians $/hr | F2: Painters $/hr | G2: Concrete Finishers $/hr | H2: Drywall/Ceiling $/hr | I2: Weighted Labor Basket | J2: Region Factor vs. Delaware | K2: Trade | L2: Weight
B3: Delaware | C3: 29.3 | D3: 22.57 | E3: 30.93 | F3: 23.48 | G3: 25.47 | H3: 25.32 | I3: =C3*$L$3+D3*$L$4+E3*$L$5+F3*$L$6+G3*$L$7+H3*$L$8 | J3: =1 | K3: Carpenters | L3: 0.3 | M3: Baseline — Delaware statewide OEWS wages. Source: BLS OEWS 2024, State=DE.
B4: New Castle/Wilmington | C4: 29.5 | D4: 22.5 | E4: 30.5 | F4: 22.9 | G4: 25.3 | H4: 25.2 | I4: =C4*$L$3+D4*$L$4+E4*$L$5+F4*$L$6+G4*$L$7+H4*$L$8 | J4: =I4/I$3 | K4: Laborers | L4: 0.2 | M4: New Castle County sub-market proxy. Slightly above state average for urban premium.
B5: Philadelphia Metro | C5: 31.47 | D5: 27.82 | E5: 37.24 | F5: 26.36 | G5: 30.83 | H5: 28.7 | I5: =C5*$L$3+D5*$L$4+E5*$L$5+F5*$L$6+G5*$L$7+H5*$L$8 | J5: =I5/I$3 | K5: Electricians | L5: 0.1 | M5: Philadelphia-Camden-Wilmington MSA. Source: BLS OEWS 2024, MSA=37980.
B6: New Jersey | C6: 35.16 | D6: 34.27 | E6: 38.51 | F6: 31.16 | G6: 34.78 | H6: 29.5 | I6: =C6*$L$3+D6*$L$4+E6*$L$5+F6*$L$6+G6*$L$7+H6*$L$8 | J6: =I6/I$3 | K6: Painters | L6: 0.2 | M6: NJ statewide OEWS 2024, all industries. Higher union density drives premium.
B7: Baltimore Area | C7: 28.74 | D7: 22.99 | E7: 33.83 | F7: 27.86 | G7: 26.34 | H7: 24.13 | I7: =C7*$L$3+D7*$L$4+E7*$L$5+F7*$L$6+G7*$L$7+H7*$L$8 | J7: =I7/I$3 | K7: Concrete Finishers | L7: 0.1 | M7: Baltimore-Columbia-Towson MSA proxy. Source: BLS OEWS 2024, MSA=12580.
B8: Washington DC Metro | C8: 34.5 | D8: 27.1 | E8: 40.2 | F8: 29.5 | G8: 31.2 | H8: 30.4 | I8: =C8*$L$3+D8*$L$4+E8*$L$5+F8*$L$6+G8*$L$7+H8*$L$8 | J8: =I8/I$3 | K8: Drywall/Ceiling | L8: 0.1 | M8: DC-VA-MD-WV MSA. Source: BLS OEWS 2024, MSA=47900. High labor market tightness.
B9: Custom | C9: 0 | D9: 0 | E9: 0 | F9: 0 | G9: 0 | H9: 0 | I9: =C9*$L$3+D9*$L$4+E9*$L$5+F9*$L$6+G9*$L$7+H9*$L$8 | J9: =I9/I$3 | K9: TOTAL | L9: =SUM(L3:L8) | M9: Enter custom wage rates. Factor auto-calculates vs. Delaware baseline.
B11: NOTE: Weighted Labor Basket is an internal blended labor-only ROM index using BLS OEWS wage data and the trade weightings shown at right. It is not a full construction location factor. ENR City Cost Indexes should be used for full project-level location adjustment when available.

Sheet UNIT PRICE LIBRARY
B1: UNIT PRICE LIBRARY — Architectural / Athletic / Community Facility Scope
B2: Div | C2: Cost Code | D2: Spec Section | E2: Bid Package | F2: Scope Item | G2: Unit | H2: Base Unit Price (Baseline Region) | I2: Region Factor | J2: Escalation Factor | K2: Adjusted Unit Price | L2: Owner Selection Sensitive? | M2: Source / Basis
B3: 02 | C3: DEM-01 | D3: 02 41 19 | F3: Selective demolition – interior finishes | G3: SF | H3: 6.5 | I3: =IFERROR(INDEX('REGIONAL FACTORS'!I$3:I$10,MATCH(ASSUMPTIONS!$C$11,'REGIONAL FACTORS'!$A$3:$A$10,0)),1) | J3: =1+ASSUMPTIONS!$C$16 | K3: =H3*I3*J3 | L3: No | M3: Placeholder. Calibrate to local GC pricing. Range: $4–9/SF for interior gut renovation.
B4: 02 | C4: DEM-02 | D4: 02 41 19 | F4: Selective demolition – athletic equipment removal | G4: EA | H4: 450 | I4: =IFERROR(INDEX('REGIONAL FACTORS'!I$3:I$10,MATCH(ASSUMPTIONS!$C$11,'REGIONAL FACTORS'!$A$3:$A$10,0)),1) | J4: =1+ASSUMPTIONS!$C$16 | K4: =H4*I4*J4 | L4: Yes | M4: Allowance. Depends on equipment type. Coordinate with equipment supplier.
B5: 03 | C5: CON-01 | D5: 03 30 00 | F5: Concrete housekeeping pad, reinforced (4" slab) | G5: CY | H5: 1450 | I5: =IFERROR(INDEX('REGIONAL FACTORS'!I$3:I$10,MATCH(ASSUMPTIONS!$C$11,'REGIONAL FACTORS'!$A$3:$A$10,0)),1) | J5: =1+ASSUMPTIONS!$C$16 | K5: =H5*I5*J5 | L5: No | M5: Includes forming, rebar, pour, finish. Verify structural requirements.
B6: 04 | C6: MAS-01 | D6: 04 20 00 | F6: CMU infill / repair, reinforced | G6: SF | H6: 28 | I6: =IFERROR(INDEX('REGIONAL FACTORS'!I$3:I$10,MATCH(ASSUMPTIONS!$C$11,'REGIONAL FACTORS'!$A$3:$A$10,0)),1) | J6: =1+ASSUMPTIONS!$C$16 | K6: =H6*I6*J6 | L6: No | M6: For openings or damaged block. Includes masonry, grout, block.
B7: 05 | C7: MET-01 | D7: 05 52 13 | F7: Aluminum/glass guardrail, per ASTM F2923 | G7: LF | H7: 350 | I7: =IFERROR(INDEX('REGIONAL FACTORS'!I$3:I$10,MATCH(ASSUMPTIONS!$C$11,'REGIONAL FACTORS'!$A$3:$A$10,0)),1) | J7: =1+ASSUMPTIONS!$C$16 | K7: =H7*I7*J7 | L7: No | M7: IBC-compliant. Includes anchor system. Powder coat finish standard.
B8: 05 | C8: MET-02 | D8: 05 52 13 | F8: Painted aluminum handrail, 1.5" dia. | G8: LF | H8: 165 | I8: =IFERROR(INDEX('REGIONAL FACTORS'!I$3:I$10,MATCH(ASSUMPTIONS!$C$11,'REGIONAL FACTORS'!$A$3:$A$10,0)),1) | J8: =1+ASSUMPTIONS!$C$16 | K8: =H8*I8*J8 | L8: No | M8: Standard IBC rail. Field paint after installation.
B9: 06 | C9: CAR-01 | D9: 06 10 00 | F9: Rough carpentry, blocking and backing | G9: SF | H9: 18 | I9: =IFERROR(INDEX('REGIONAL FACTORS'!I$3:I$10,MATCH(ASSUMPTIONS!$C$11,'REGIONAL FACTORS'!$A$3:$A$10,0)),1) | J9: =1+ASSUMPTIONS!$C$16 | K9: =H9*I9*J9 | L9: No | M9: Includes lumber, installation labor. For equipment attachment points.
B10: 07 | C10: INS-01 | D10: 07 21 00 | F10: Batt insulation, 3.5" R-13 | G10: SF | H10: 2.5 | I10: =IFERROR(INDEX('REGIONAL FACTORS'!I$3:I$10,MATCH(ASSUMPTIONS!$C$11,'REGIONAL FACTORS'!$A$3:$A$10,0)),1) | J10: =1+ASSUMPTIONS!$C$16 | K10: =H10*I10*J10 | L10: No | M10: Faced batt in exterior walls. Energy code compliance item.
B11: 08 | C11: DOO-01 | D11: 08 11 13 | F11: New HM door frame + hollow metal door + hardware, complete | G11: EA | H11: 3800 | I11: =IFERROR(INDEX('REGIONAL FACTORS'!I$3:I$10,MATCH(ASSUMPTIONS!$C$11,'REGIONAL FACTORS'!$A$3:$A$10,0)),1) | J11: =1+ASSUMPTIONS!$C$16 | K11: =H11*I11*J11 | L11: No | M11: Complete unit: frame, door, closer, HW set. ADA lever required.
B12: 08 | C12: DOO-02 | D12: 08 11 13 | F12: Door frame only – existing door reused | G12: EA | H12: 1200 | I12: =IFERROR(INDEX('REGIONAL FACTORS'!I$3:I$10,MATCH(ASSUMPTIONS!$C$11,'REGIONAL FACTORS'!$A$3:$A$10,0)),1) | J12: =1+ASSUMPTIONS!$C$16 | K12: =H12*I12*J12 | L12: No | M12: Replace damaged frame, retain serviceable door and hardware.
B13: 09 | C13: FIN-01 | D13: 09 91 00 | F13: High-performance corrosion-resistant coating (2-coat system) | G13: SF | H13: 9.5 | I13: =IFERROR(INDEX('REGIONAL FACTORS'!I$3:I$10,MATCH(ASSUMPTIONS!$C$11,'REGIONAL FACTORS'!$A$3:$A$10,0)),1) | J13: =1+ASSUMPTIONS!$C$16 | K13: =H13*I13*J13 | L13: No | M13: For pool decks, pump rooms, humid athletic spaces. Tnemec or equal.
B14: 09 | C14: FIN-02 | D14: 09 91 00 | F14: Standard interior latex paint system (2 coats) | G14: SF | H14: 3.75 | I14: =IFERROR(INDEX('REGIONAL FACTORS'!I$3:I$10,MATCH(ASSUMPTIONS!$C$11,'REGIONAL FACTORS'!$A$3:$A$10,0)),1) | J14: =1+ASSUMPTIONS!$C$16 | K14: =H14*I14*J14 | L14: No | M14: Two coat system walls + ceiling. Does not include prep beyond light sanding.
... B31: 16 | C31: ELC-02 | D31: 26 05 00 | F31: Scoreboard/specialty equipment power feed | G31: EA | H31: 4500 | I31: =IFERROR(INDEX('REGIONAL FACTORS'!I$3:I$10,MATCH(ASSUMPTIONS!$C$11,'REGIONAL FACTORS'!$A$3:$A$10,0)),1) | J31: =1+ASSUMPTIONS!$C$16 | K31: =H31*I31*J31 | L31: Yes | M31: Dedicated circuit for scoreboard, PA, or specialty equip. Allowance pending design.
B32: → ADD NEW SCOPE ITEMS BELOW THIS ROW. Copy formulas in columns I–K from any row above.

Sheet TAKEOFF
B1: QUANTITY TAKEOFF — By Floor / Division / Scope Item
B2: Floor | C2: Area / Zone | D2: Div | E2: Spec Section | F2: Bid Package | G2: Cost Code | H2: Scope Item | I2: Unit | J2: Quantity Source | K2: Quantity | L2: Adj. Unit Cost (from Library) | M2: Line Total | N2: Included? | O2: Comments
B3: LL | C3: Pump Room/Pool Area | D3: 02 | E3: 02 41 19 | G3: DEM-01 | H3: Selective demolition – interior finishes | I3: SF | J3: Pump Rm Area | K3: 953 | L3: =IFERROR(VLOOKUP(G3,'UNIT PRICE LIBRARY'!$C$3:$K$60,9,0),0) | M3: =IF(OR(N3="No",N3="TBD"),0,K3*L3) | N3: Yes
B4: LL | C4: Pump Room/Pool Area | D4: 03 | E4: 03 30 00 | G4: CON-01 | H4: Concrete housekeeping pad, reinforced | I4: CY | J4: 11'x7'x6" calc | K4: 1.43 | L4: =IFERROR(VLOOKUP(G4,'UNIT PRICE LIBRARY'!$C$3:$K$60,9,0),0) | M4: =IF(OR(N4="No",N4="TBD"),0,K4*L4) | N4: Yes | O4: 11 ft x 7 ft x 0.5 ft / 27 = 1.43 CY
B5: LL | C5: Pump Room/Pool Area | D5: 09 | E5: 09 91 00 | G5: FIN-01 | H5: High-performance corrosion coating – pump room | I5: SF | J5: Pump Rm Area | K5: 3170 | L5: =IFERROR(VLOOKUP(G5,'UNIT PRICE LIBRARY'!$C$3:$K$60,9,0),0) | M5: =IF(OR(N5="No",N5="TBD"),0,K5*L5) | N5: Yes | O5: Walls + ceiling + 20% surface factor
B6: LL | C6: Pool Area | D6: 09 | E6: 09 91 00 | G6: FIN-01 | H6: High-performance corrosion coating – pool walls | I6: SF | J6: Pool Area | K6: 16300 | L6: =IFERROR(VLOOKUP(G6,'UNIT PRICE LIBRARY'!$C$3:$K$60,9,0),0) | M6: =IF(OR(N6="No",N6="TBD"),0,K6*L6) | N6: Yes | O6: Pool walls and ceiling + 15% surface factor
B7: LL | C7: Stair Tower | D7: 09 | E7: 09 91 00 | G7: FIN-01 | H7: High-performance corrosion coating – stair | I7: SF | J7: Stair Area | K7: 3070 | L7: =IFERROR(VLOOKUP(G7,'UNIT PRICE LIBRARY'!$C$3:$K$60,9,0),0) | M7: =IF(OR(N7="No",N7="TBD"),0,K7*L7) | N7: Yes | O7: Stair walls and ceiling + 35% surface factor
B8: 1F | C8: Bleachers/Balcony | D8: 02 | E8: 02 41 19 | G8: DEM-01 | H8: Selective demolition – interior finishes | I8: SF | J8: Balcony Area | K8: 1130 | L8: =IFERROR(VLOOKUP(G8,'UNIT PRICE LIBRARY'!$C$3:$K$60,9,0),0) | M8: =IF(OR(N8="No",N8="TBD"),0,K8*L8) | N8: Yes
B9: 1F | C9: Bleachers/Balcony | D9: 05 | E9: 05 52 13 | G9: MET-01 | H9: Aluminum/glass guardrail | I9: LF | J9: Field Measure | K9: 92 | L9: =IFERROR(VLOOKUP(G9,'UNIT PRICE LIBRARY'!$C$3:$K$60,9,0),0) | M9: =IF(OR(N9="No",N9="TBD"),0,K9*L9) | N9: Yes
B10: 1F | C10: Bleachers/Balcony | D10: 09 | E10: 09 65 66 | G10: FIN-04 | H10: Rubber athletic flooring system | I10: SF | J10: Balcony Area | K10: 1130 | L10: =IFERROR(VLOOKUP(G10,'UNIT PRICE LIBRARY'!$C$3:$K$60,9,0),0) | M10: =IF(OR(N10="No",N10="TBD"),0,K10*L10) | N10: Allowance | O10: Thickness TBD by owner
B11: 1F | C11: Bleachers/Balcony | D11: 05 | E11: 05 52 13 | G11: MET-02 | H11: Painted aluminum handrail | I11: LF | J11: Field Measure | K11: 28 | L11: =IFERROR(VLOOKUP(G11,'UNIT PRICE LIBRARY'!$C$3:$K$60,9,0),0) | M11: =IF(OR(N11="No",N11="TBD"),0,K11*L11) | N11: Yes | O11: 4 × 7-ft sections in center aisle
B12: 1F | C12: Stair Tower | D12: 09 | E12: 09 51 00 | G12: FIN-06 | H12: ACT ceiling replacement | I12: SF | J12: Actual Area | K12: 520 | L12: =IFERROR(VLOOKUP(G12,'UNIT PRICE LIBRARY'!$C$3:$K$60,9,0),0) | M12: =IF(OR(N12="No",N12="TBD"),0,K12*L12) | N12: Yes
B13: 2F | C13: Gymnasium/Practice | D13: 09 | E13: 09 64 66 | G13: FIN-03 | H13: Wood athletic floor refinishing | I13: SF | J13: Actual Area | K13: 6730 | L13: =IFERROR(VLOOKUP(G13,'UNIT PRICE LIBRARY'!$C$3:$K$60,9,0),0) | M13: =IF(OR(N13="No",N13="TBD"),0,K13*L13) | N13: Yes
B14: 2F | C14: Gymnasium/Practice | D14: 09 | E14: 09 65 00 | G14: FIN-05 | H14: VCT replacement/refinishing | I14: SF | J14: Actual Area | K14: 270 | L14: =IFERROR(VLOOKUP(G14,'UNIT PRICE LIBRARY'!$C$3:$K$60,9,0),0) | M14: =IF(OR(N14="No",N14="TBD"),0,K14*L14) | N14: Yes | O14: Practice room and instructor office
B15: 2F | C15: Gymnasium/Practice | D15: 08 | E15: 08 11 13 | G15: DOO-01 | H15: New HM door + frame + hardware | I15: EA | J15: Count | K15: 1 | L15: =IFERROR(VLOOKUP(G15,'UNIT PRICE LIBRARY'!$C$3:$K$60,9,0),0) | M15: =IF(OR(N15="No",N15="TBD"),0,K15*L15) | N15: Allowance
B16: 2F | C16: Gymnasium/Practice | D16: 11 | E16: 11 66 23 | G16: ATH-02 | H16: Scoreboard / control system | I16: EA | J16: Count | K16: 2 | L16: =IFERROR(VLOOKUP(G16,'UNIT PRICE LIBRARY'!$C$3:$K$60,9,0),0) | M16: =IF(OR(N16="No",N16="TBD"),0,K16*L16) | N16: Allowance | O16: One main + one practice
B17: 2F | C17: Gymnasium/Practice | D17: 11 | E17: 11 66 23 | G17: ATH-03 | H17: Telescoping bleacher system | I17: LS | J17: LS | K17: 1 | L17: =IFERROR(VLOOKUP(G17,'UNIT PRICE LIBRARY'!$C$3:$K$60,9,0),0) | M17: =IF(OR(N17="No",N17="TBD"),0,K17*L17) | N17: Allowance | O17: Row count and ADA layout TBD
B18: 2F | C18: Gymnasium/Practice | D18: 11 | E18: 11 66 23 | G18: ATH-04 | H18: Basketball backstop (single court) | I18: EA | J18: Count | K18: 4 | L18: =IFERROR(VLOOKUP(G18,'UNIT PRICE LIBRARY'!$C$3:$K$60,9,0),0) | M18: =IF(OR(N18="No",N18="TBD"),0,K18*L18) | N18: Allowance | O18: Main + 3 side courts
B19: 2F | C19: Gymnasium/Practice | D19: 11 | E19: 11 66 23 | G19: ATH-05 | H19: Volleyball post/sleeve system | I19: EA | J19: Count | K19: 1 | L19: =IFERROR(VLOOKUP(G19,'UNIT PRICE LIBRARY'!$C$3:$K$60,9,0),0) | M19: =IF(OR(N19="No",N19="TBD"),0,K19*L19) | N19: Allowance
B20: 2F | C20: Gymnasium/Practice | D20: 11 | E20: 11 66 23 | G20: ATH-01 | H20: Gymnasium wall padding | I20: SF | J20: Actual Area | K20: 900 | L20: =IFERROR(VLOOKUP(G20,'UNIT PRICE LIBRARY'!$C$3:$K$60,9,0),0) | M20: =IF(OR(N20="No",N20="TBD"),0,K20*L20) | N20: Allowance | O20: 75 × 2x6 pads
B21: 2F | C21: Gymnasium/Practice | D21: 11 | E21: 11 66 23 | G21: ATH-01 | H21: Gymnasium wall padding – pillar wraps | I21: SF | J21: Actual Area | K21: 119 | L21: =IFERROR(VLOOKUP(G21,'UNIT PRICE LIBRARY'!$C$3:$K$60,9,0),0) | M21: =IF(OR(N21="No",N21="TBD"),0,K21*L21) | N21: Allowance | O21: 17 × 2x3.5 pads
B22: 3F | C22: Boxing Gym | D22: 02 | E22: 02 41 19 | G22: DEM-01 | H22: Selective demolition – interior finishes | I22: SF | J22: Actual Area | K22: 2700 | L22: =IFERROR(VLOOKUP(G22,'UNIT PRICE LIBRARY'!$C$3:$K$60,9,0),0) | M22: =IF(OR(N22="No",N22="TBD"),0,K22*L22) | N22: Yes
B23: 3F | C23: Boxing Gym | D23: 06 | E23: 06 10 00 | G23: CAR-01 | H23: Rough carpentry / blocking / backing | I23: SF | J23: Actual Area | K23: 450 | L23: =IFERROR(VLOOKUP(G23,'UNIT PRICE LIBRARY'!$C$3:$K$60,9,0),0) | M23: =IF(OR(N23="No",N23="TBD"),0,K23*L23) | N23: Yes | O23: Partitions and equipment backing
B24: 3F | C24: Boxing Gym | D24: 09 | E24: 09 65 66 | G24: FIN-04 | H24: Rubber athletic flooring – boxing | I24: SF | J24: Actual Area | K24: 2500 | L24: =IFERROR(VLOOKUP(G24,'UNIT PRICE LIBRARY'!$C$3:$K$60,9,0),0) | M24: =IF(OR(N24="No",N24="TBD"),0,K24*L24) | N24: Allowance | O24: Thickness TBD by owner
B25: 3F | C25: Boxing Gym | D25: 10 | E25: 10 28 13 | G25: ACC-01 | H25: Mirrors, wall-mounted | I25: SF | J25: Actual Area | K25: 240 | L25: =IFERROR(VLOOKUP(G25,'UNIT PRICE LIBRARY'!$C$3:$K$60,9,0),0) | M25: =IF(OR(N25="No",N25="TBD"),0,K25*L25) | N25: Yes | O25: 8 × 6x5 mirrors
B26: 3F | C26: Boxing Gym | D26: 11 | E26: 11 66 43 | G26: ATH-06 | H26: Boxing ring, 14x14 training ring | I26: EA | J26: Count | K26: 1 | L26: =IFERROR(VLOOKUP(G26,'UNIT PRICE LIBRARY'!$C$3:$K$60,9,0),0) | M26: =IF(OR(N26="No",N26="TBD"),0,K26*L26) | N26: Allowance | O26: Model and accessories TBD
B27: 3F | C27: Boxing Gym | D27: 11 | E27: 11 66 43 | G27: ATH-07 | H27: Bag systems / speed bag station | I27: LS | J27: LS | K27: 1 | L27: =IFERROR(VLOOKUP(G27,'UNIT PRICE LIBRARY'!$C$3:$K$60,9,0),0) | M27: =IF(OR(N27="No",N27="TBD"),0,K27*L27) | N27: Allowance | O27: Count and mounting TBD
B29: TAKEOFF SUBTOTAL (before markups) | M29: =SUM(M3:M27)
B30: → ADD NEW TAKEOFF ROWS ABOVE THE SUBTOTAL. Enter Floor, Zone, and Cost Code. Adj. Unit Cost auto-populates from UNIT PRICE LIBRARY via VLOOKUP on Cost Code.

Sheet FLOOR SUMMARY
B1: FLOOR-BY-FLOOR COST SUMMARY
B2: Floor | C2: Base Building Subtotal | D2: Equipment Allowances | E2: Subtotal | F2: General Conditions | G2: OH&P | H2: Contingencies | I2: Bid/Permit/Bonds | J2: Est. Floor Total
B3: LL | C3: =SUMIF(TAKEOFF!$B$3:$B$100,B3,TAKEOFF!$M$3:$M$100) | D3: =SUMPRODUCT((TAKEOFF!$B$3:$B$100=B3)*(TAKEOFF!$N$3:$N$100="Allowance")*TAKEOFF!$M$3:$M$100) | E3: =C3+D3 | F3: =E3*ASSUMPTIONS!$C$19 | G3: =(E3+F3)*ASSUMPTIONS!$C$20 | H3: =(E3+F3+G3)*(ASSUMPTIONS!$C$21+ASSUMPTIONS!$C$22+ASSUMPTIONS!$C$23) | I3: =(E3+F3+G3+H3)*ASSUMPTIONS!$C$24 | J3: =SUM(E3:I3)
B4: 1F | C4: =SUMIF(TAKEOFF!$B$3:$B$100,B4,TAKEOFF!$M$3:$M$100) | D4: =SUMPRODUCT((TAKEOFF!$B$3:$B$100=B4)*(TAKEOFF!$N$3:$N$100="Allowance")*TAKEOFF!$M$3:$M$100) | E4: =C4+D4 | F4: =E4*ASSUMPTIONS!$C$19 | G4: =(E4+F4)*ASSUMPTIONS!$C$20 | H4: =(E4+F4+G4)*(ASSUMPTIONS!$C$21+ASSUMPTIONS!$C$22+ASSUMPTIONS!$C$23) | I4: =(E4+F4+G4+H4)*ASSUMPTIONS!$C$24 | J4: =SUM(E4:I4)
B5: 2F | C5: =SUMIF(TAKEOFF!$B$3:$B$100,B5,TAKEOFF!$M$3:$M$100) | D5: =SUMPRODUCT((TAKEOFF!$B$3:$B$100=B5)*(TAKEOFF!$N$3:$N$100="Allowance")*TAKEOFF!$M$3:$M$100) | E5: =C5+D5 | F5: =E5*ASSUMPTIONS!$C$19 | G5: =(E5+F5)*ASSUMPTIONS!$C$20 | H5: =(E5+F5+G5)*(ASSUMPTIONS!$C$21+ASSUMPTIONS!$C$22+ASSUMPTIONS!$C$23) | I5: =(E5+F5+G5+H5)*ASSUMPTIONS!$C$24 | J5: =SUM(E5:I5)
B6: 3F | C6: =SUMIF(TAKEOFF!$B$3:$B$100,B6,TAKEOFF!$M$3:$M$100) | D6: =SUMPRODUCT((TAKEOFF!$B$3:$B$100=B6)*(TAKEOFF!$N$3:$N$100="Allowance")*TAKEOFF!$M$3:$M$100) | E6: =C6+D6 | F6: =E6*ASSUMPTIONS!$C$19 | G6: =(E6+F6)*ASSUMPTIONS!$C$20 | H6: =(E6+F6+G6)*(ASSUMPTIONS!$C$21+ASSUMPTIONS!$C$22+ASSUMPTIONS!$C$23) | I6: =(E6+F6+G6+H6)*ASSUMPTIONS!$C$24 | J6: =SUM(E6:I6)
B8: TOTAL | C8: =SUM(C3:C6) | D8: =SUM(D3:D6) | E8: =SUM(E3:E6) | F8: =SUM(F3:F6) | G8: =SUM(G3:G6) | H8: =SUM(H3:H6) | I8: =SUM(I3:I6) | J8: =SUM(J3:J6)
B10: ↑ Total Project ROM feeds BID SUMMARY and SF BENCHMARK sheets.

Sheet SCENARIO COMP
B1: YIELD & ROM SCENARIO COMPARISON | 1212 Lobdel Ave | City of Wilmington R-3
B2: April 9, 2026 | M2_2026_004 | Merge 4 Design LLC (M4D) | 30-unit WHA target exceeded in Scen. I and II
B4: METRIC | C4: SCN I - 36 UNITS / 18 ft | D4: SCN II - 40 UNITS / 16 ft | E4: SCN III - 24 UNITS / 20 ft
B5: YIELD
B6: Unit Configuration | C6: 4 rows x 9 units | D6: 4 rows x 10 units | E6: 3 rows x 8 units
B7: Unit Width (ft) | C7: 18 | D7: 16 | E7: 20
B8: Unit Size (SF) | C8: 1,260 | D8: 1,120 | E8: 1,520
B9: Total Units | C9: 36 | D9: 40 | E9: 24
B10: Density (du/ac) | C10: 25.9 | D10: 28.8 | E10: 17.3
B11: Site Depth Used | C11: 240 ft | D11: 240 ft | E11: 194 ft
B12: Surplus Depth | C12: 112.6 ft | D12: 112.6 ft | E12: 158.6 ft
B13: vs WHA 30-unit target | C13: +6 units (+20%) | D13: +10 units (+33%) | E13: Below target
B14: CONSTRUCTION TYPE B - MODULAR ROM
B15: Total ROM | C15: $9,200,026 | D15: $9,918,373 | E15: $6,509,701
B16: Cost Per Unit | C16: $255,556 | D16: $247,959 | E16: $271,238
B17: Gap vs $215K Target | C17: ~$40,556/unit | D17: ~$32,959/unit | E17: ~$56,238/unit
B18: Total Subsidy Gap | C18: ~$1,460,016 | D18: ~$1,318,360 | E18: ~$1,349,712
B19: Catalyst Fund ($35K/unit) | C19: $1,260,000 | D19: $1,400,000 | E19: $840,000
B20: Remaining Gap after Catalyst | C20: ~$200,016 | D20: ~$(81,640) | E20: ~$509,712
B21: CONSTRUCTION TYPE A - CLT/SIP ROM
B22: Total ROM (A) | C22: $14,875,352 | D22: $15,005,993 | E22: $11,635,084
B23: Gap vs $215K (A) | C23: ~$198K/unit | D23: ~$160K/unit | E23: ~$270K/unit
B24: CONSTRUCTION TYPE C - STICK ROM
B25: Total ROM (C) | C25: $14,731,123 | D25: $14,797,583 | E25: $11,553,115
B26: Gap vs $215K (C) | C26: ~$194K/unit | D26: ~$155K/unit | E26: ~$266K/unit
B27: M4D RECOMMENDATION
B28: M4D Recommendation | C28: PRIMARY PATH | D28: MAX DENSITY OPTION | E28: QUALITY BENCHMARK

Sheet BID SUMMARY
B1: ROM COST ESTIMATE — EXECUTIVE SUMMARY
B2: ="Project: " & ASSUMPTIONS!C3
B3: ="Estimate Date: " & TEXT(ASSUMPTIONS!C4,"mm/dd/yyyy") & " | Type: " & ASSUMPTIONS!C5
B4: Summary Item | C4: Amount | E4: Pricing Basis / Notes
B5: Base Building Subtotal | C5: =IFERROR(SUMIF('FLOOR SUMMARY'!B3:B8,"<>TOTAL",'FLOOR SUMMARY'!C3:C8),0) | E5: Architectural / interior renovation ROM with quantity-based takeoff. Excludes allowances.
B6: Equipment Allowances | C6: =IFERROR(SUM('FLOOR SUMMARY'!D3:D6),0) | E6: Owner-selection-dependent athletic and specialty equipment. Pending confirmation.
B7: Subtotal Before Markups | C7: =C5+C6
B8: General Conditions | C8: =C7*ASSUMPTIONS!$C$19 | E8: Rate: per ASSUMPTIONS!C19
B9: Overhead & Profit (OH&P) | C9: =(C7+C8)*ASSUMPTIONS!$C$20 | E9: Rate: per ASSUMPTIONS!C20
B10: Total Contingencies | C10: =(C7+C8+C9)*(ASSUMPTIONS!C21+ASSUMPTIONS!C22+ASSUMPTIONS!C23) | E10: Design + existing conditions + equipment/owner selection contingencies.
B11: Bid / Permit / Bonds | C11: =(C7+C8+C9+C10)*ASSUMPTIONS!$C$24 | E11: Rate: per ASSUMPTIONS!C24
B12: TOTAL PROJECT ROM | C12: =C5+C8+C9+C10+C11
B14: Project Cost per SF | C14: =IFERROR(C12/ASSUMPTIONS!$C$9,0) | E14: Reference only. Compare to SF BENCHMARK sheet for sanity check.
B16: CONTINGENCY BREAKDOWN (for reference)
B17: Design Contingency | C17: =(C7+C8+C9)*ASSUMPTIONS!C21
B18: Existing Conditions Contingency | C18: =(C7+C8+C9)*ASSUMPTIONS!C22
B19: Equipment/Owner Selection Contingency | C19: =(C7+C8+C9)*ASSUMPTIONS!C23
B21: SOFT COSTS & TOTAL PROJECT INVESTMENT (see SOFT COSTS and TOTAL PROJECT BUDGET sheets)
B22: Architecture Fee (from SOFT COSTS) | C22: ='SOFT COSTS'!F54 | E22: Base fee + renovation premium per M4Di fee schedule.
B23: Total Engineering Fees | C23: ='SOFT COSTS'!F84 | E23: Structural, MEP, FP, Civil, Geotech.
B24: Other Consultant & Owner Costs | C24: ='SOFT COSTS'!F85 | E24: Technology, legal, permits, insurance, testing, environmental.
B25: TOTAL SOFT COSTS | C25: ='SOFT COSTS'!F86 | E25: See SOFT COSTS sheet for detail and overrides.
B26: Owner Contingency | C26: ='TOTAL PROJECT BUDGET'!C34 | E26: Post-GMP owner contingency and program reserves.
B27: TOTAL PROJECT INVESTMENT | C27: ='TOTAL PROJECT BUDGET'!C36 | E27: Full project cost: hard + soft + owner costs.

Sheet BUDGET TRACKER
B1: M4Di | ALDi Budget Tracker | 1212 Lobdel Avenue — Multi-Unit Affordable Infill | M2_2026_004
B3: LINE ITEM | C3: COL D - ROM (LOCKED G0) | D3: COL E - 75% DD (Gate 2) | E3: COL F - GMP/SOV (Gate 3) | F3: COL G - ACTUAL (Gate 4) | G3: ROM vs DD Var % | H3: ROM vs GMP Var %
B4: Col D = locked ROM from COVER tab. Col D never changes after Gate 0. Enter E, F, G at respective gates. Variance >5% triggers Variance Log entry.
B5: HARD COSTS
B6: Sitework / Civil (drives, walks) | C6: =COVER!C39 | G6: =IF(D6=0,"-",IF(C6=0,"-",(D6-C6)/C6)) | H6: =IF(E6=0,"-",IF(C6=0,"-",(E6-C6)/C6))
B7: Foundations (modular-spec slab) | C7: =COVER!C40 | G7: =IF(D7=0,"-",IF(C7=0,"-",(D7-C7)/C7)) | H7: =IF(E7=0,"-",IF(C7=0,"-",(E7-C7)/C7))
B8: Modular Factory Units (36 units) | C8: =COVER!C41 | G8: =IF(D8=0,"-",IF(C8=0,"-",(D8-C8)/C8)) | H8: =IF(E8=0,"-",IF(C8=0,"-",(E8-C8)/C8))
B9: Freight + Set (crane, ~200 mi) | C9: =COVER!C42 | G9: =IF(D9=0,"-",IF(C9=0,"-",(D9-C9)/C9)) | H9: =IF(E9=0,"-",IF(C9=0,"-",(E9-C9)/C9))
B10: Site MEP Tie-Ins + Utilities | C10: =COVER!C43 | G10: =IF(D10=0,"-",IF(C10=0,"-",(D10-C10)/C10)) | H10: =IF(E10=0,"-",IF(C10=0,"-",(E10-C10)/C10))
B11: Exterior Finish Completion | C11: =COVER!C44 | G11: =IF(D11=0,"-",IF(C11=0,"-",(D11-C11)/C11)) | H11: =IF(E11=0,"-",IF(C11=0,"-",(E11-C11)/C11))
B12: Interior Finish Completion | C12: =COVER!C45 | G12: =IF(D12=0,"-",IF(C12=0,"-",(D12-C12)/C12)) | H12: =IF(E12=0,"-",IF(C12=0,"-",(E12-C12)/C12))
B13: Shared Open Space / Parking Court | C13: =COVER!C46 | G13: =IF(D13=0,"-",IF(C13=0,"-",(D13-C13)/C13)) | H13: =IF(E13=0,"-",IF(C13=0,"-",(E13-C13)/C13))
B14: Landscaping / Fencing / Walks | C14: =COVER!C47 | G14: =IF(D14=0,"-",IF(C14=0,"-",(D14-C14)/C14)) | H14: =IF(E14=0,"-",IF(C14=0,"-",(E14-C14)/C14))
B15: HARD COST SUBTOTAL | C15: =SUM(C6:C14)
B16: General Conditions (8%) | C16: =0.08*C15 | G16: =IF(D16=0,"-",IF(C16=0,"-",(D16-C16)/C16)) | H16: =IF(E16=0,"-",IF(C16=0,"-",(E16-C16)/C16))
B17: OH&P / GC Fee (6%) | C17: =0.06*(C15+C16) | G17: =IF(D17=0,"-",IF(C17=0,"-",(D17-C17)/C17)) | H17: =IF(E17=0,"-",IF(C17=0,"-",(E17-C17)/C17))
B18: Design Contingency (6%) | C18: =0.06*(C15+C16+C17) | G18: =IF(D18=0,"-",IF(C18=0,"-",(D18-C18)/C18)) | H18: =IF(E18=0,"-",IF(C18=0,"-",(E18-C18)/C18))
B19: SOFT COSTS & CONTINGENCY
B20: Soft Costs (12% of hard+markups) | C20: =0.12*(C15+C16+C17+C18) | G20: =IF(D20=0,"-",IF(C20=0,"-",(D20-C20)/C20)) | H20: =IF(E20=0,"-",IF(C20=0,"-",(E20-C20)/C20))
B21: Owner Contingency (5%) | C21: =0.05*(C15+C16+C17+C18+C20) | G21: =IF(D21=0,"-",IF(C21=0,"-",(D21-C21)/C21)) | H21: =IF(E21=0,"-",IF(C21=0,"-",(E21-C21)/C21))
B22: TOTAL PROJECT ROM - COLUMN D | C22: =SUM(C15,C16,C17,C18,C20,C21) | G22: =IF(D22=0,"-",IF(C22=0,"-",(D22-C22)/C22)) | H22: =IF(E22=0,"-",IF(C22=0,"-",(E22-C22)/C22))
B23: UNIT ECONOMICS
B24: Total Units (36 - Scenario I) | C24: =COVER!C24 | G24: =IF(D24=0,"-",IF(C24=0,"-",(D24-C24)/C24)) | H24: =IF(E24=0,"-",IF(C24=0,"-",(E24-C24)/C24))
B25: Cost Per Unit (ROM) | C25: =C22/C24 | G25: =IF(D25=0,"-",IF(C25=0,"-",(D25-C25)/C25)) | H25: =IF(E25=0,"-",IF(C25=0,"-",(E25-C25)/C25))
B26: Target Sales Price (WHA) | C26: 215000 | G26: =IF(D26=0,"-",IF(C26=0,"-",(D26-C26)/C26)) | H26: =IF(E26=0,"-",IF(C26=0,"-",(E26-C26)/C26))
B27: Subsidy Gap Per Unit | C27: =C25-C26 | G27: =IF(D27=0,"-",IF(C27=0,"-",(D27-C27)/C27)) | H27: =IF(E27=0,"-",IF(C27=0,"-",(E27-C27)/C27))
B28: Total Subsidy Gap | C28: =C27*C24 | G28: =IF(D28=0,"-",IF(C28=0,"-",(D28-C28)/C28)) | H28: =IF(E28=0,"-",IF(C28=0,"-",(E28-C28)/C28))

Sheet VARIANCE LOG
B1: VARIANCE LOG — Cost Changes Requiring Documentation
B2: Any variance >5% between estimate columns must be documented here before the next ALDi gate is cleared.
B4: Line Item / Budget Category | C4: Gate | D4: ROM Amt ($) | E4: New Est. Amt ($) | F4: Var ($) | G4: Var (%) | H4: Status | I4: Root Cause & Resolution | J4: Approved By
B5: Existing Conditions Contingency — higher than ROM | C5: Gate 2 | D5: 347000 | E5: 420000 | F5: 73,000 | G5: 21.0% | H5: Approved | I5: Hazmat survey confirmed asbestos in 3 locations. Abatement scope added. Owner approved $73K increase. | J5: T. Maxwell / M4Di
B6: HVAC — Phase 1A scope expanded per DDDS requirements | C6: Gate 2 | D6: 310000 | E6: 365000 | F6: 55,000 | G6: 17.7% | H6: Watch | I6: DDDS licensing pre-app required supplemental ventilation for clinical areas. Engineering confirmed scope. | J6: Pending owner
B7: [Next Variance Item — enter as identified] | H7: On Track

Sheet CHANGE ORDER LOG
B1: CHANGE ORDER LOG — ALDi Gate 3–4
B2: All changes to the contracted GMP/SOV (Column F) must be logged here. Actual Cost (Column G) = Column F + approved COs below.
B4: CO # | C4: Description | D4: Date | E4: GC Amount ($) | F4: Owner Cost ($) | G4: Cumulative COs ($) | H4: CO Running % of GMP | I4: Status | J4: Category | K4: Notes / Justification
B5: CO-001 | C5: Hazardous Materials Abatement — Phase 1 (asbestos, 3 locations) | D5: 04/15/2026 | E5: 73000 | F5: 0 | G5: 73000 | H5: 2.1% | I5: Approved | J5: Existing Conditions | K5: Required; covered by existing conditions contingency draw
B6: CO-002 | C6: Additional HVAC ductwork — DDDS ventilation compliance | D6: 05/01/2026 | E6: 55000 | F6: 0 | G6: 128000 | H6: 3.7% | I6: Pending | J6: Regulatory | K6: DDDS licensing requirement; pending owner authorization
B7: [Future CO — enter as issued] | I7: Pending
B9: TOTAL APPROVED COs | E9: =SUM(F5:F7)

Sheet DRAW SCHEDULE
B1: FUNDING DRAW SCHEDULE — Budget vs. Actual Spend
B2: Track each funding source draw against actual project expenditures. Updated monthly with each pay application.
B4: Funding Source | C4: Total Committed ($) | D4: Draw 1 ($) | E4: Draw 2 ($) | F4: Draw 3 ($) | G4: Draw 4 ($) | H4: Draw 5 ($) | I4: Total Drawn ($) | J4: Remaining ($) | K4: % Drawn
B5: Owner / Developer Equity (Dr. Maxwell) | C5: 2500000 | I5: =SUM(D5:H5) | J5: =C5-I5 | K5: =IFERROR(I5/C5,0)
B6: CDFI Construction Loan (NCALL) | C6: 3500000 | I6: =SUM(D6:H6) | J6: =C6-I6 | K6: =IFERROR(I6/C6,0)
B7: HUD CDBG Grant | C7: 750000 | I7: =SUM(D7:H7) | J7: =C7-I7 | K7: =IFERROR(I7/C7,0)
B8: Delaware DDDS Capital Support | C8: 500000 | I8: =SUM(D8:H8) | J8: =C8-I8 | K8: =IFERROR(I8/C8,0)
B9: Philanthropic Grants (Longwood / Welfare Fdn) | C9: 750000 | I9: =SUM(D9:H9) | J9: =C9-I9 | K9: =IFERROR(I9/C9,0)
B10: Owner Contingency Reserve (escrowed) | C10: 300000 | I10: =SUM(D10:H10) | J10: =C10-I10 | K10: =IFERROR(I10/C10,0)
B11: TOTAL FUNDING | C11: =SUM(C5:C10) | D11: =SUM(D5:D10) | E11: =SUM(E5:E10) | F11: =SUM(F5:F10) | G11: =SUM(G5:G10) | H11: =SUM(H5:H10) | I11: =SUM(I5:I10) | J11: =SUM(J5:J10) | K11: =SUM(K5:K10)

Sheet GATE DASHBOARD
B1: ALDi GATE DASHBOARD — Project Status Summary
B2: One-page project status for owner, AE, and lender reporting. Update at each gate.
B4: Project | C4: =COVER!C4
B5: Owner | C5: =COVER!C6
B6: AE | C6: =COVER!C7
B7: M4Di Lead | C7: =COVER!C8
B8: Building SF | C8: =COVER!C9
B9: ALDi Start | C9: =COVER!C10
B10: M4Di ROM (Locked Baseline) | C10: ='BUDGET TRACKER'!D80
B11: 75% DD Estimate | C11: ='BUDGET TRACKER'!E80
B12: 100% CD / GMP (Contracted) | C12: ='BUDGET TRACKER'!F80
B13: Actual Cost to Date | C13: ='BUDGET TRACKER'!G80
B14: ROM vs. Current Estimate Variance | C14: =IFERROR('BUDGET TRACKER'!E80-'BUDGET TRACKER'!D80,IFERROR('BUDGET TRACKER'!F80-'BUDGET TRACKER'!D80,"-"))
B15: ROM vs. Current Estimate Variance % | C15: =IFERROR(('BUDGET TRACKER'!E80-'BUDGET TRACKER'!D80)/'BUDGET TRACKER'!D80,"-")
B17: ALDi GATE STATUS
B18: Gate | C18: Name | D18: Target Date | E18: Actual Date | F18: Status | G18: Budget Check | H18: Key Conditions / Notes
B19: Gate 0 | C19: Controls Setup + Budget Baseline Lock | F19: In Progress | G19: ROM Locked | H19: Project charter issued. Budget baseline = Column D. Procurement calendar set.
B20: Gate 1 | C20: Schematic Design Review | F20: Pending | G20: Target ±15% | H20: SD documents reviewed. Constructability input provided. DDDS pre-app status confirmed.
B21: Gate 2 | C21: Design Development + 75% DD Estimate | F21: Pending | G21: Column E entered | H21: DD estimate entered in Column E. Variance log updated. Owner contingency reviewed.
B22: Gate 3 | C22: GMP Execution + SOV Entry | F22: Pending | G22: Column F = GMP | H22: Contractor SOV entered in Column F. GMP executed. Financing closed.
B23: Gate 4 | C23: Construction Controls + Closeout | F23: Pending | G23: Column G current | H23: Monthly actual cost updates. CO log maintained. HISTORICAL DB row completed.

Sheet SF BENCHMARK
B1: COST PER SF — BENCHMARK DASHBOARD
B2: Compares current ROM estimate to M4Di historical database and facility type benchmarks.
B3: Metric | C3: Value | E3: Historical Comparison | F3: Value
B4: Project Area (SF) | C4: =ASSUMPTIONS!C9 | E4: Project $/SF vs. Hist. Avg | F4: =IFERROR(C6/C7,"N/A - no data")
B5: ROM Construction Cost | C5: ='BID SUMMARY'!C12 | E5: Project $/SF vs. Hist. Median | F5: =IFERROR(C6/C8,"N/A - no data")
B6: Calculated Project Cost/SF | C6: ='BID SUMMARY'!C14 | E6: Sanity Check | F6: =IF(C6>C10,"Above historical max",IF(C6>C7,"Above historical average",IF(C6<C9,"Below historical min","Within historical range")))
B7: Historical Average $/SF | C7: =IFERROR(AVERAGE('HISTORICAL DB'!G4:G103),0)
B8: Historical Median $/SF | C8: =IFERROR(MEDIAN('HISTORICAL DB'!G4:G103),0)
B9: Historical Min $/SF | C9: =IFERROR(MIN(IF('HISTORICAL DB'!G4:G103>0,'HISTORICAL DB'!G4:G103)),0)
B10: Historical Max $/SF | C10: =IFERROR(MAX('HISTORICAL DB'!G4:G103),0)
B11: Historical Data Count | C11: =COUNTA('HISTORICAL DB'!A4:A103)
B13: FACILITY TYPE BENCHMARK RANGES ($/SF)
B14: Facility Type | C14: Low $/SF | D14: High $/SF | F14: Check vs. Project
B15: Community Facility Renovation | C15: 120 | D15: 250 | F15: =IF('BID SUMMARY'!C14=0,"Enter data",IF('BID SUMMARY'!C14<C15,"Below range",IF('BID SUMMARY'!C14>D15,"Above range","Within range")))
B16: Church / Faith-Based Renovation | C16: 110 | D16: 230 | F16: =IF('BID SUMMARY'!C14=0,"Enter data",IF('BID SUMMARY'!C14<C16,"Below range",IF('BID SUMMARY'!C14>D16,"Above range","Within range")))
B17: Athletic Facility Upgrade | C17: 150 | D17: 320 | F17: =IF('BID SUMMARY'!C14=0,"Enter data",IF('BID SUMMARY'!C14<C17,"Below range",IF('BID SUMMARY'!C14>D17,"Above range","Within range")))
B18: Athletic Flooring Replacement | C18: 80 | D18: 165 | F18: =IF('BID SUMMARY'!C14=0,"Enter data",IF('BID SUMMARY'!C14<C18,"Below range",IF('BID SUMMARY'!C14>D18,"Above range","Within range")))
B19: Adaptive Reuse — Community Use | C19: 140 | D19: 290 | F19: =IF('BID SUMMARY'!C14=0,"Enter data",IF('BID SUMMARY'!C14<C19,"Below range",IF('BID SUMMARY'!C14>D19,"Above range","Within range")))
B20: New Construction — Community Fac. | C20: 220 | D20: 420 | F20: =IF('BID SUMMARY'!C14=0,"Enter data",IF('BID SUMMARY'!C14<C20,"Below range",IF('BID SUMMARY'!C14>D20,"Above range","Within range")))
B21: Mixed-Use (residential + community) | C21: 260 | D21: 480 | F21: =IF('BID SUMMARY'!C14=0,"Enter data",IF('BID SUMMARY'!C14<C21,"Below range",IF('BID SUMMARY'!C14>D21,"Above range","Within range")))
B24: HOW TO READ THIS DASHBOARD
B25: If project $/SF is BELOW all ranges: | C25: Scope may be missing items, quantities may be understated, or allowances are not yet included.
B26: If project $/SF is ABOVE all ranges: | C26: Owner selections, specialty equipment, corrosion remediation, or code upgrades may be driving cost.
B27: If project aligns with historical average: | C27: ROM is behaving like a plausible early estimate. Continue to P3 for detailed scope confirmation.
B28: Historical database: | C28: Replace example rows in HISTORICAL DB with M4Di's own completed projects over time. This is the proprietary asset.

Sheet HISTORICAL DB
B1: M4Di HISTORICAL PROJECT COST DATABASE — PROPRIETARY ASSET
B2: CRITICAL: Enter every completed M4Di engagement in this database. This is M4Di's proprietary competitive advantage. Do not distribute externally. Source for SF BENCHMARK dashboard and annual cost reports.
B3: Project Name / Code | C3: Project Type | D3: Location / Region | E3: Year Completed | F3: Building Area (SF) | G3: Final Const. Cost | H3: Cost / SF | I3: Scope Description | J3: Data Source / Notes
B4: YMCA Gymnasium Renovation | C4: Athletic Facility Upgrade | D4: Pennsylvania | E4: 2023 | F4: 18000 | G4: 3200000 | H4: =IFERROR(G4/F4,0) | I4: Gym upgrades, flooring, bleachers, scoring equipment, wall padding. | J4: Example benchmark — replace with M4Di project data
B5: High School Gymnasium Upgrade | C5: Athletic Facility Upgrade | D5: Delaware | E5: 2022 | F5: 12000 | G5: 2100000 | H5: =IFERROR(G5/F5,0) | I5: Bleacher replacement, floor refinish, scoreboard, accessible path of travel. | J5: Example benchmark — replace with M4Di project data
B6: Community Rec Center Interior | C6: Community Facility Renovation | D6: Maryland | E6: 2021 | F6: 8000 | G6: 950000 | H6: =IFERROR(G6/F6,0) | I6: Interior renovation, athletic flooring, community room upgrades. | J6: Example benchmark — replace with M4Di project data
B7: Church Fellowship Hall Adaptive Reuse | C7: Adaptive Reuse — Community Use | D7: Delaware | E7: 2023 | F7: 6500 | G7: 1450000 | H7: =IFERROR(G7/F7,0) | I7: Fellowship hall converted to community clinic and gathering space. ADA upgrades. | J7: Example benchmark — replace with M4Di project data
B8: Faith-Based Youth Center Renovation | C8: Community Facility Renovation | D8: New Jersey | E8: 2024 | F8: 9200 | G8: 2280000 | H8: =IFERROR(G8/F8,0) | I8: Full interior renovation, new MEP, gymnasium floor, community kitchen. | J8: Example benchmark — replace with M4Di project data
B10: → ADD NEW COMPLETED PROJECTS ABOVE THIS LINE. Copy Cost/SF formula from column H. Fill all fields at project closeout.
B12: DATABASE STATISTICS (auto-calculated — used by SF BENCHMARK)
B13: Total Projects in Database | C13: =COUNTA(B4:B9)
B14: Average Cost / SF | C14: =IFERROR(AVERAGE(H4:H9),0)
B15: Median Cost / SF | C15: =IFERROR(MEDIAN(H4:H9),0)
B16: Minimum Cost / SF | C16: =IFERROR(MIN(IF(H4:H9>0,H4:H9)),0)
B17: Maximum Cost / SF | C17: =IFERROR(MAX(H4:H9),0)

Sheet SOFT COSTS
B1: SOFT COSTS — Professional Fees & Pre-Construction Budget
B2: Soft costs are calculated as a percentage of the Total Hard Cost ROM (from BID SUMMARY). Architecture fee uses the M4Di Base Fee Schedule (AIA-aligned). Engineering and specialty fees use benchmark percentages adjustable per project. All rates are user-overridable.
B4: A — PROJECT BASIS (from ASSUMPTIONS & BID SUMMARY)
B5: Total Hard Cost ROM | C5: ='BID SUMMARY'!C12 | D5: Pulled from BID SUMMARY. This is the construction cost base for all fee calculations.
B6: Project Type (for fee schedule) | C6: =ASSUMPTIONS!C6 | D6: Auto-pulled from ASSUMPTIONS. Drives fee type classification below.
B7: Estimate Phase | C7: =ASSUMPTIONS!C5 | D7: ROM / Conceptual | Schematic | Design Development | GMP
B8: Gross Area (SF) | C8: =ASSUMPTIONS!C9 | D8: From ASSUMPTIONS. Used for cost/SF benchmarking.
B10: B — ARCHITECTURE FEE (M4Di Base Fee Schedule)
B11: Fee lookup uses the M4Di Base Fee Schedule. Select the Project Type Code (A–E) based on complexity. For renovation/adaptive reuse, apply the renovation premium. New Construction = base rate only. Renovation = base + premium.
B13: FEE SCHEDULE REFERENCE TABLE — Base % of Construction Cost
B14: Construction Budget Range | D14: Type A | E14: Type B | F14: Type C | G14: Type D | H14: Type E
B15: Up to – $49,999 | D15: 0.089 | E15: 0.099 | F15: 0.109 | G15: 0.117 | H15: 0.12
B16: $50,000 – $99,999 | D16: 0.084 | E16: 0.094 | F16: 0.107 | G16: 0.111 | H16: 0.119
B17: $100,000 – $149,999 | D17: 0.081 | E17: 0.091 | F17: 0.104 | G17: 0.109 | H17: 0.115
B18: $150,000 – $199,999 | D18: 0.079 | E18: 0.089 | F18: 0.101 | G18: 0.105 | H18: 0.112
B19: $200,000 – $299,999 | D19: 0.074 | E19: 0.084 | F19: 0.099 | G19: 0.103 | H19: 0.11
B20: $300,000 – $499,999 | D20: 0.072 | E20: 0.082 | F20: 0.094 | G20: 0.1 | H20: 0.107
B21: $500,000 – $749,999 | D21: 0.069 | E21: 0.079 | F21: 0.091 | G21: 0.097 | H21: 0.104
B22: $750,000 – $999,999 | D22: 0.067 | E22: 0.077 | F22: 0.089 | G22: 0.094 | H22: 0.101
B23: $1,000,000 – $1,499,999 | D23: 0.064 | E23: 0.074 | F23: 0.084 | G23: 0.091 | H23: 0.098
B24: $1,500,000 – $1,999,999 | D24: 0.062 | E24: 0.072 | F24: 0.082 | G24: 0.088 | H24: 0.095
B25: $2,000,000 – $2,999,999 | D25: 0.059 | E25: 0.069 | F25: 0.079 | G25: 0.085 | H25: 0.092
B26: $3,000,000 – $3,999,999 | D26: 0.057 | E26: 0.067 | F26: 0.077 | G26: 0.083 | H26: 0.09
... B33: Renovation premium (add to above) | D33: 0.005 | E33: 0.0065 | F33: 0.0075 | G33: 0.0085 | H33: 0.01
B35: PROJECT TYPE CLASSIFICATION — Select the code that matches your facility
B36: Type A | C36: Warehouse, Public Garage, Residential (standard)
B37: Type B | C37: Office, Parking Facility, Retail, Visitor Center, Maintenance Garage, Tenant Fit-out
B38: Type C | C38: School, Training Facility, Day Care, Fitness Center, Mixed-Use, Adult Care, Laundry
B39: Type D | C39: Library, Restaurant, Theater (no stage), Outpatient Clinic, Detention, Courthouse, Data Center
B40: Type E | C40: Hospital, Research, Museum, Stadium, Prison, Emergency Ops, Theater/Auditorium with stage
B41: M4Di Default — Community Facility Renovation | C41: Use Type C (Fitness Center / Mixed-Use) for church/community renovation. Use Type D for clinic or complex adaptive reuse.
B44: C — FEE INPUTS & CALCULATIONS (enter yellow cells; formulas auto-populate)
B45: Discipline / Fee Item | C45: % of Hard Cost (enter or auto) | D45: Calculated Fee ($) | E45: User Override ($ if fixed) | F45: Fee Used (calc or override) | G45: Included in Budget? | H45: Notes / Assumptions
B46: PROJECT TYPE CODE & RENOVATION SELECTION (user inputs)
B47: AIA Project Type Code (A / B / C / D / E) | C47: C | D47: Type A=warehouse/parking, B=office/retail, C=school/fitness/mixed-use (M4Di default), D=clinic/library/theater, E=hospital/research. See guide above.
B48: Renovation / Adaptive Reuse? (Yes / No) | C48: Yes | D48: Yes: adds renovation premium to base Arch fee per fee schedule. WHACC = Yes (interior improvement + adaptive reuse elements).
B50: ARCHITECTURE & ENGINEERING FEES
B51: Discipline / Fee Item | C51: % of Hard Cost | D51: Calculated Fee ($) | E51: User Override ($) leave blank = use calc | F51: Fee Used | G51: Include? | H51: Notes / Source
B52: Architecture — Base Fee (fee schedule) | C52: =IFERROR(IF(C47="A",IF(C5<50000,D15,IF(C5<100000,D16,IF(C5<150000,D17,IF(C5<200000,D18,IF(C5<300000,D19,IF(C5<500000,D20,IF(C5<750000,D21,IF(C5<1000000,D22,IF(C5<1500000,D23,IF(C5<2000000,D24,IF(C5<3000000,D25,IF(C5<4000000,D26,IF(C5<5000000,D27,IF(C5<8000000,D28,IF(C5<12000000,D29,IF(C5<15000000,D30,IF(C5<20000000,D31,D32))))))))))))))))),IF(C47="B",IF(C5<50000,E15,IF(C5<100000,E16,IF(C5<150000,E17,IF(C5<200000,E18,IF(C5<300000,E19,IF(C5<500000,E20,IF(C5<750000,E21,IF(C5<1000000,E22,IF(C5<1500000,E23,IF(C5<2000000,E24,IF(C5<3000000,E25,IF(C5<4000000,E26,IF(C5<5000000,E27,IF(C5<8000000,E28,IF(C5<12000000,E29,IF(C5<15000000,E30,IF(C5<20000000,E31,E32))))))))))))))))),IF(C47="C",IF(C5<50000,F15,IF(C5<100000,F16,IF(C5<150000,F17,IF(C5<200000,F18,IF(C5<300000,F19,IF(C5<500000,F20,IF(C5<750000,F21,IF(C5<1000000,F22,IF(C5<1500000,F23,IF(C5<2000000,F24,IF(C5<3000000,F25,IF(C5<4000000,F26,IF(C5<5000000,F27,IF(C5<8000000,F28,IF(C5<12000000,F29,IF(C5<15000000,F30,IF(C5<20000000,F31,F32))))))))))))))))),IF(C47="D",IF(C5<50000,G15,IF(C5<100000,G16,IF(C5<150000,G17,IF(C5<200000,G18,IF(C5<300000,G19,IF(C5<500000,G20,IF(C5<750000,G21,IF(C5<1000000,G22,IF(C5<1500000,G23,IF(C5<2000000,G24,IF(C5<3000000,G25,IF(C5<4000000,G26,IF(C5<5000000,G27,IF(C5<8000000,G28,IF(C5<12000000,G29,IF(C5<15000000,G30,IF(C5<20000000,G31,G32))))))))))))))))),IF(C47="E",IF(C5<50000,H15,IF(C5<100000,H16,IF(C5<150000,H17,IF(C5<200000,H18,IF(C5<300000,H19,IF(C5<500000,H20,IF(C5<750000,H21,IF(C5<1000000,H22,IF(C5<1500000,H23,IF(C5<2000000,H24,IF(C5<3000000,H25,IF(C5<4000000,H26,IF(C5<5000000,H27,IF(C5<8000000,H28,IF(C5<12000000,H29,IF(C5<15000000,H30,IF(C5<20000000,H31,H32))))))))))))))))),0))))),0) | D52: =C5*C52 | F52: =IF(AND(E52<>"",E52<>0),E52,D52) | G52: Yes | H52: Auto-calculated from M4Di Base Fee Schedule. Based on construction cost tier and Type Code.
B53: + Renovation Premium (if applicable) | C53: =IF(C48="Yes",IF(C47="A",D33,IF(C47="B",E33,IF(C47="C",F33,IF(C47="D",G33,IF(C47="E",H33,0))))),0) | D53: =C5*C53 | F53: =IF(AND(E53<>"",E53<>0),E53,D53) | G53: Yes | H53: Add-on for renovation/adaptive reuse per fee schedule. Set to 0 if new construction.
...

Sheet CLARIFICATIONS
B1: CLARIFICATIONS / EXCLUSIONS / RISK LOG
B2: Include this sheet in all client deliverables. It defines the boundaries of the estimate and protects M4Di from scope disputes. Update at every estimate revision.
B3: Category | C3: Item | D3: Included / Excluded / Allowance | E3: Risk Level | F3: Comment / Mitigation
B4: General | C4: All quantities are conceptual and require field verification before GMP | D4: Included | E4: High | F4: Use as ROM only. Not a GMP or guaranteed maximum price.
B5: General | C5: Estimate based on scope narrative and program only — no drawings | D5: Included | E5: High | F5: Unit quantities are estimator's judgment. Field verify before DD.
B6: Equipment | C6: Athletic equipment model numbers and manufacturers | D6: Allowance | E6: High | F6: Owner selections pending. Allowances will be updated as selections are confirmed.
B7: Equipment | C7: Boxing equipment package | D7: Allowance | E7: High | F7: Basis of design still open. Owner to confirm model and accessory scope.
B8: MEP | C8: Power and data modifications for scoreboards and specialty equipment | D8: Allowance | E8: Medium | F8: Allowance included. Requires MEP engineer coordination and load calculations.
B9: MEP | C9: HVAC modifications or upgrades | D9: Excluded | E9: Medium | F9: Not in scope unless noted. Carry separate MEP budget if HVAC work is anticipated.
B10: MEP | C10: Plumbing — new fixtures or drainage | D10: Excluded | E10: Medium | F10: Minor modifications covered by allowance. Major new plumbing excluded.
B11: Existing Conditions | C11: Concealed corrosion or substrate damage beyond scope assumptions | D11: Excluded | E11: High | F11: Carry contingency or unit rates for concealed conditions. Field verification recommended.
B12: Existing Conditions | C12: Hazardous material abatement (asbestos, lead paint) | D12: Excluded | E12: High | F12: Requires testing and licensed abatement contractor. Separate budget required.
B13: Existing Conditions | C13: Structural deficiencies identified during construction | D13: Excluded | E13: High | F13: Not in scope. Structural engineer review recommended before estimate finalization.
B14: Schedule | C14: Cost escalation beyond current estimate date | D14: Excluded | E14: Medium | F14: Adjust ENR escalation factor in ASSUMPTIONS for revised bid dates.
... B21: Accessibility | C21: ADA path of travel upgrades beyond specified scope | D21: Excluded | E21: Medium | F21: ADA items within designated scope are included. Full-building accessibility audit not in scope.
B23: → ADD PROJECT-SPECIFIC CLARIFICATIONS ABOVE. Always include this sheet in client deliverable packages.

Sheet TOTAL PROJECT BUDGET
B1: TOTAL PROJECT BUDGET — Hard Costs + Soft Costs + Owner Costs
B2: This sheet aggregates the full project investment: construction hard costs (from BID SUMMARY), professional fees and soft costs (from SOFT COSTS), and owner contingency. Use this for board presentations, CDFI loan packages, and grant applications.
B3: ="Project: " & ASSUMPTIONS!C3 & " | " & TEXT(ASSUMPTIONS!C4,"mm/dd/yyyy") & " | Phase: " & ASSUMPTIONS!C5
B5: Budget Item | C5: Amount ($) | D5: % of Hard Cost | E5: % of Total | F5: Notes
B6: SECTION 1 — HARD COSTS (Construction)
B7: Base Building Subtotal (labor + materials) | C7: ='BID SUMMARY'!C5 | D7: =IFERROR(C7/C13,0) | E7: =IFERROR(C7/C36,0) | F7: Quantity-based takeoff from TAKEOFF sheet, adjusted for region and escalation.
B8: Equipment Allowances (owner selections) | C8: ='BID SUMMARY'!C6 | D8: =IFERROR(C8/C13,0) | E8: =IFERROR(C8/C36,0) | F8: Athletic and specialty equipment. Pending owner selections. See EQUIPMENT ALLOWANCES.
B9: General Conditions | C9: ='BID SUMMARY'!C8 | D9: =IFERROR(C9/C13,0) | E9: =IFERROR(C9/C36,0) | F9: On-site supervision, temp facilities, insurance. Rate per ASSUMPTIONS.
B10: Overhead & Profit (OH&P) | C10: ='BID SUMMARY'!C9 | D10: =IFERROR(C10/C13,0) | E10: =IFERROR(C10/C36,0) | F10: Contractor OH&P. Rate per ASSUMPTIONS.
B11: Total Contingencies | C11: ='BID SUMMARY'!C10 | D11: =IFERROR(C11/C13,0) | E11: =IFERROR(C11/C36,0) | F11: Design + existing conditions + owner selection contingency. Will reduce at each gate.
B12: Bid / Permit / Bonds | C12: ='BID SUMMARY'!C11 | D12: =IFERROR(C12/C13,0) | E12: =IFERROR(C12/C36,0) | F12: Permitting fees, bid bonds, performance bonds.
B13: TOTAL HARD COST (Construction ROM) | C13: ='BID SUMMARY'!C12 | D13: 1 | E13: =IFERROR(C13/C36,0)
B15: SECTION 2 — SOFT COSTS (Professional Fees & Owner Costs)
B16: Architecture — Total Fee (base + renovation premium) | C16: ='SOFT COSTS'!F54 | D16: =IFERROR(C16/C13,0) | E16: =IFERROR(C16/C36,0) | F16: Base fee per M4Di fee schedule + renovation premium. See SOFT COSTS sheet.
B17: Structural Engineering | C17: ='SOFT COSTS'!F57 | D17: =IFERROR(C17/C13,0) | E17: =IFERROR(C17/C36,0) | F17: See SOFT COSTS sheet for rate and override.
B18: Mechanical Engineering (HVAC) | C18: ='SOFT COSTS'!F58 | D18: =IFERROR(C18/C13,0) | E18: =IFERROR(C18/C36,0) | F18: See SOFT COSTS sheet for rate and override.
B19: Electrical Engineering | C19: ='SOFT COSTS'!F59 | D19: =IFERROR(C19/C13,0) | E19: =IFERROR(C19/C36,0) | F19: See SOFT COSTS sheet for rate and override.
B20: Plumbing Engineering | C20: ='SOFT COSTS'!F60 | D20: =IFERROR(C20/C13,0) | E20: =IFERROR(C20/C36,0) | F20: See SOFT COSTS sheet for rate and override.
B21: Fire Protection Engineering | C21: ='SOFT COSTS'!F61 | D21: =IFERROR(C21/C13,0) | E21: =IFERROR(C21/C36,0) | F21: See SOFT COSTS sheet for rate and override.
B22: Civil Engineering | C22: ='SOFT COSTS'!F62 | D22: =IFERROR(C22/C13,0) | E22: =IFERROR(C22/C36,0) | F22: See SOFT COSTS sheet. Minimal for interior-only scope.
B23: Geotechnical / Soils Report | C23: ='SOFT COSTS'!F63 | D23: =IFERROR(C23/C13,0) | E23: =IFERROR(C23/C36,0) | F23: Fixed fee item for new foundations or unknown conditions.
B24: Other Consultants & Owner Costs | C24: ='SOFT COSTS'!F85 | D24: =IFERROR(C24/C13,0) | E24: =IFERROR(C24/C36,0) | F24: Technology, legal, permits, insurance, testing, environmental. See SOFT COSTS.
B25: TOTAL SOFT COSTS | C25: ='SOFT COSTS'!F86 | D25: =IFERROR(C25/C13,0) | E25: =IFERROR(C25/C36,0)
B27: SECTION 3 — OWNER CONTINGENCY & PREDEVELOPMENT
B28: Owner Project Contingency (post-GMP) | C28: =IFERROR(D28*C13,0) | D28: 0.05 | E28: =IFERROR(C28/C36,0) | F28: Owner-held contingency for scope changes, unforeseen conditions, and owner decisions after GMP. Recommend 5%–10%.
B29: Predevelopment Costs (M4Di P1–P3 fees) | C29: =IFERROR(D29*C13,0) | D29: 0 | E29: =IFERROR(C29/C36,0) | F29: M4Di feasibility ops fees already incurred or contracted. Enter fixed dollar amount in override on SOFT COSTS.
B30: FF&E — Furniture, Fixtures & Equipment | C30: =IFERROR(D30*C13,0) | D30: 0 | E30: =IFERROR(C30/C36,0) | F30: Non-construction FF&E not in the construction contract. Enter lump sum estimate.
B31: Technology / AV / Security Systems | C31: =IFERROR(D31*C13,0) | D31: 0 | E31: =IFERROR(C31/C36,0) | F31: Owner-procured tech systems outside of construction contract. Enter estimate.
B32: Moving / Relocation / Swing Space | C32: =IFERROR(D32*C13,0) | D32: 0 | E32: =IFERROR(C32/C36,0) | F32: If applicable. Enter fixed estimate.
B33: Program Reserve (funding gap buffer) | C33: =IFERROR(D33*C13,0) | D33: 0 | E33: =IFERROR(C33/C36,0) | F33: Discretionary reserve for funding shortfalls. Typically 3%–8% of total project cost for nonprofit owners.
B34: TOTAL OWNER CONTINGENCY & OTHER | C34: =C28+C29+C30+C31+C32+C33 | D34: =IFERROR(C34/C13,0) | E34: =IFERROR(C34/C36,0)
B36: TOTAL PROJECT INVESTMENT | C36: =C13+C25+C34 | D36: 1
B38: SUMMARY METRICS
B39: Total Project Investment | C39: =C36
B40: Hard Cost ROM | C40: ='BID SUMMARY'!C12
B41: Soft Costs (professional fees + other) | C41: ='SOFT COSTS'!F86
B42: Soft Costs as % of Hard Costs | C42: =IFERROR('SOFT COSTS'!F86/'BID SUMMARY'!C12,0) | D42: Benchmark: 18%–25% typical community facility; 25%–35% complex renovation/new construction.
B43: Total Project Cost / SF | C43: =IFERROR(C36/ASSUMPTIONS!C9,0) | D43: Total investment including all soft costs. Compare to $/SF benchmarks in SF BENCHMARK sheet.
B44: Hard Cost / SF | C44: ='BID SUMMARY'!C14 | D44: Construction cost only. Use for benchmarking against comparable projects.

Sheet ALDDB EXPORT
B1: ALDDB EXPORT - Closeout Data Row | M4Di Historical Cost Database
B2: Complete at Gate 4 closeout. Copy Col C as VALUES into ALDDB Master next empty row. This is the moat. Never skip.
B4: FIELD | C4: VALUE / FORMULA
B5: Project Code | C5: =COVER!C6
B6: Project Name | C6: =COVER!C7
B7: Address | C7: =COVER!C8
B8: Client | C8: =COVER!C9
B9: Lead Firm | C9: =COVER!C10
B10: ALDi Gate at Export | C10: G4 Closeout (enter manually)
B11: Governing Code | C11: =COVER!C15
B12: Construction Type | C12: =COVER!C24
B13: Total Units | C13: =COVER!C24
B14: Unit SF | C14: =COVER!C29
B15: Total GFA (SF) | C15: =COVER!C30
B16: Site SF | C16: =COVER!C18
B17: Site Acres | C17: =COVER!C19
B18: Year Completed | C18: Enter at closeout
B19: Column D ROM Total | C19: =COVER!C54
B20: Column E 75% DD | C20: Enter from BUDGET TRACKER at closeout
B21: Column F GMP/SOV | C21: Enter from BUDGET TRACKER at closeout
B22: Column G Actual Cost | C22: Enter from BUDGET TRACKER at closeout
B23: Column D vs G Variance ($) | C23: =IF(C15>0,C17-C15,"-")
B24: Column D vs G Variance (%) | C24: =IF(C15>0,(C17-C15)/C15,"-")
B25: Hard Cost / SF | C25: =COVER!C64
B26: Total Cost / SF | C26: =COVER!C65
B27: Subsidy Gap / Unit | C27: Enter from BUDGET TRACKER at closeout
B28: ENR Index | C28: =COVER!C66
B29: Bid Date | C29: =COVER!C67
B30: Key Variance Notes | C30: Enter from VARIANCE LOG at closeout
B31: Data Entry Date | C31: Enter at closeout
B34: PROTOCOL: At Gate 4 closeout, complete all blue "Enter" cells. Copy Col C as Paste Special > Values into next ALDDB Master row. One row per closed project. This feeds the moat.

Sheet TAB QA
B1: TAB QA — CRITICAL FORMULA CHECKS & WORKBOOK VALIDATION
B2: Use this sheet after any revision to confirm critical formulas are working correctly. Open in Excel, press Ctrl+Alt+F9 to force full recalculation, then review each check.
B3: Check ID | C3: Sheet | D3: Cell | E3: Description | F3: Expected Behavior | G3: Live Value | H3: Manual QA Result | I3: Reviewer Notes
B4: QA-01 | C4: ASSUMPTIONS | D4: C12 | E4: Weighted trade labor factor | F4: Returns 1.000x for Delaware and ~1.145x for Philadelphia Metro | G4: =ASSUMPTIONS!C12 | H4: Not Checked
B5: QA-02 | C5: REGIONAL FACTORS | D5: I3 | E5: Delaware weighted labor basket | F5: Returns a numeric weighted basket (should be ~26.17) | G5: ='REGIONAL FACTORS'!I3 | H5: Not Checked
B6: QA-03 | C6: REGIONAL FACTORS | D6: I4 | E6: Philadelphia region factor | F6: Returns factor >1.000x (should be ~1.145) | G6: ='REGIONAL FACTORS'!I4 | H6: Not Checked
B7: QA-04 | C7: UNIT PRICE LIBRARY | D7: K3 | E7: Adjusted unit price row 3 | F7: Returns numeric adjusted unit price (Base Price × Region Factor × Escalation) | G7: ='UNIT PRICE LIBRARY'!K3 | H7: Not Checked
B8: QA-05 | C8: TAKEOFF | D8: L3 | E8: Adj. unit cost VLOOKUP row 3 | F8: Returns matching adjusted unit cost from UNIT PRICE LIBRARY via Cost Code VLOOKUP | G8: =TAKEOFF!L3 | H8: Not Checked
B9: QA-06 | C9: TAKEOFF | D9: M3 | E9: Takeoff line total row 3 | F9: Returns quantity × adjusted unit cost (or 0 if Included = No) | G9: =TAKEOFF!M3 | H9: Not Checked
B10: QA-07 | C10: FLOOR SUMMARY | D10: C3 | E10: LL base building total | F10: Sums all LL rows from TAKEOFF where Included = Yes or Allowance | G10: ='FLOOR SUMMARY'!C3 | H10: Not Checked
B11: QA-08 | C11: FLOOR SUMMARY | D11: I8 | E11: Total Project ROM | F11: Should equal sum of all floor totals in column J | G11: ='FLOOR SUMMARY'!I8 | H11: Not Checked
