Workbook

Sheet README
B2: M4Di Operational Intelligence (OI) Tool — Phase 0
B3: ROM Estimating & Predevelopment Cost Intelligence Platform
B4: Version 1.0 | March 2026 | © M4Di, Inc. | CONFIDENTIAL
B6: RECOMMENDED WORKFLOW
B7: 1 | C7: ASSUMPTIONS | D7: Enter yellow input cells: project name, date, region, and all markup percentages.
B8: 2 | C8: REGIONAL FACTORS | D8: Review or update the regional labor basket and select your pricing region.
B9: 3 | C9: UNIT PRICE LIBRARY | D9: Verify or add unit prices for your project scope. Craig populates the Baseline Region.
B10: 4 | C10: TAKEOFF | D10: Enter quantities by floor/zone. The tool auto-applies adjusted unit costs.
B11: 5 | C11: EQUIPMENT ALLOWANCES | D11: Document owner-selection-dependent equipment allowances with basis of design.
B12: 6 | C12: FLOOR SUMMARY | D12: Review auto-calculated floor totals with markups. No data entry required.
B13: 7 | C13: BID SUMMARY | D13: Executive ROM with full cost stack. Use for board presentations and funder packages.
B14: 8 | C14: SF BENCHMARK | D14: Compare project $/SF against M4Di historical database and facility type ranges.
B15: 9 | C15: HISTORICAL DB | D15: CRITICAL: Enter every completed project. This is M4Di's proprietary data asset.
B16: 10 | C16: OWNER SELECTIONS | D16: Track owner decisions affecting allowance-sensitive items.
B17: 11 | C17: ALLOWANCE LOG | D17: Living log of all open allowances. Export monthly for ALDi gate reporting.
B18: 12 | C18: CLARIFICATIONS | D18: Document scope inclusions, exclusions, and risk flags for client delivery.
B21: COLOR CODING LEGEND (Industry Standard)
B22: SAMPLE | C22: Blue text / yellow background | D22: Hardcoded user inputs — values you enter or change
B23: SAMPLE | C23: Black text / white background | D23: Calculated formulas — do not overwrite
B24: SAMPLE | C24: Green text / light green background | D24: Cross-sheet links — pulling from another tab
B25: SAMPLE | C25: Red text | D25: External links to other files
B26: SAMPLE | C26: Yellow background | D26: Cells requiring attention or decision
B28: PROPRIETARY NOTICE: This workbook and its methodology, unit price library, regional factor weights, and historical database are proprietary to M4Di, Inc. Unauthorized distribution or reproduction is prohibited. © 2026 M4Di, Inc. All rights reserved.

Sheet ASSUMPTIONS
B1: PROJECT ASSUMPTIONS & CONTROLS
B2: Input | C2: Value | E2: Notes
B3: Project Name | C3: M-Well Community Health Campus | E3: Use a short, consistent project code (e.g., WHACC-2026).
B4: Estimate Date | E4: Enter as MM/DD/YYYY. Update with each revision.
B5: Estimate Type | C5: ROM / Conceptual | E5: ROM / Conceptual | Schematic | Design Development | GMP
B6: Project Type | C6: Adaptive Reuse | E6: Interior Improvement | Adaptive Reuse | New Construction | Mixed-Use
B7: Client / Owner | C7: M-Well Medical Group | E7: Legal entity name of the owner organization.
B8: Site Address | C8: 3110 Philadelphia Pike, Claymont, DE 19703 | E8: Full property address for zoning lookup reference.
B9: Total Gross Area (SF) | C9: 27452 | E9: Total gross building SF affected by the scope.
B10: Base Region | C10: Delaware | E10: Delaware = M4Di baseline. All unit prices sourced from Delaware competitive bid market.
B11: Selected Pricing Region | C11: New Castle/Wilmington | E11: Must match a region defined in REGIONAL FACTORS sheet.
B12: Weighted Trade Labor Factor | C12: =IFERROR(INDEX('REGIONAL FACTORS'!H$4:H$20,MATCH(C11,'REGIONAL FACTORS'!A$4:A$20,0)),1) -> 1 | E12: Auto-pulled from REGIONAL FACTORS. 1.000x = Delaware baseline. Philadelphia Metro ≈ 1.145x.
B13: COST ESCALATION
B14: ENR Construction Cost Index (CCI) Escalation % | C14: 0.027 | E14: Source: ENR CCI Q1 2026. Update quarterly. Applies to all labor-heavy items.
B15: ENR Building Cost Index (BCI) Escalation % | C15: 0.043 | E15: Source: ENR BCI Q1 2026. Update quarterly. Applies to material-heavy items.
B16: Blended Escalation Rate | C16: =AVERAGE(C14,C15) -> 0.035 | E16: Formula: average of CCI and BCI. Used in unit price adjusted cost calculation.
B17: Material / Market Factor | C17: 1 | E17: Adjust for procurement pressure, bid climate volatility, or material shortages. 1.000x = neutral.
B18: MARKUPS & CONTINGENCIES
B19: General Conditions % | C19: 0.08 | E19: Typical range: 6%–10%. Covers on-site supervision, temporary facilities, insurance.
B20: Overhead & Profit (OH&P) % | C20: 0.1 | E20: Typical range: 8%–12%. Applied to subtotal after GC.
B21: Design Contingency % | C21: 0.12 | E21: Reduce to 8% at SD; 5% at DD; 0% at GMP. Reflects design development risk.
B22: Existing Conditions Contingency % | C22: 0.1 | E22: Higher for gut renovations (12%–15%). Covers concealed conditions and substrate damage.
B23: Equipment / Owner Selection Contingency % | C23: 0.08 | E23: Reduce as owner selections are confirmed. Set to 0% when all allowances are locked.
B24: Bid / Permit / Bonds % | C24: 0.02 | E24: Covers permitting fees, bid bonds, performance bonds. Adjust for municipality.
B25: Sales Tax % | C25: 0 | E25: Delaware: 0%. Adjust for other jurisdictions. Apply only to taxable material costs if split.
B26: Total Contingency % | C26: =C21+C22+C23 -> 0.3 | E26: Sum of all contingency lines. For reference only.
B28: QUICK REFERENCE TOTALS (auto-calculated from BID SUMMARY)
B29: Base Building Subtotal | C29: ='BID SUMMARY'!C3 -> 0
B30: Equipment Allowances | C30: ='BID SUMMARY'!C4 -> Amount
B31: Subtotal Before Markups | C31: ='BID SUMMARY'!C5 -> 5411956.7
B32: General Conditions | C32: ='BID SUMMARY'!C6 -> 473719.5
B33: OH&P | C33: ='BID SUMMARY'!C7 -> 5885676.2
B34: Total Contingencies | C34: ='BID SUMMARY'!C8 -> 470854.1
B35: Bid / Permit / Bonds | C35: ='BID SUMMARY'!C9 -> 635653.03
B36: TOTAL PROJECT ROM | C36: ='BID SUMMARY'!C10 -> 2097655
B37: FEE SCHEDULE CONTROLS (feeds SOFT COSTS sheet)
B38: AIA Project Type Code | C38: C | E38: A=warehouse, B=office, C=school/fitness (M4Di default), D=clinic/theater, E=hospital/research.
B39: Renovation Project? | C39: Yes | E39: Yes adds renovation premium to base architecture fee. WHACC = Yes.

Sheet REGIONAL FACTORS
B1: REGIONAL MARKET FACTORS — Public Data-Based Labor Basket
B2: Region | C2: Carpenters $/hr | D2: Laborers $/hr | E2: Electricians $/hr | F2: Painters $/hr | G2: Concrete Finishers $/hr | H2: Drywall/Ceiling $/hr | I2: Weighted Labor Basket | J2: Region Factor vs. Delaware | K2: Trade | L2: Weight
B3: Delaware | C3: 29.3 | D3: 22.57 | E3: 30.93 | F3: 23.48 | G3: 25.47 | H3: 25.32 | I3: =C3*$L$3+D3*$L$4+E3*$L$5+F3*$L$6+G3*$L$7+H3*$L$8 -> 26.172 | J3: =1 -> 1 | K3: Carpenters | L3: 0.3 | M3: Baseline — Delaware statewide OEWS wages. Source: BLS OEWS 2024, State=DE.
B4: New Castle/Wilmington | C4: 29.5 | D4: 22.5 | E4: 30.5 | F4: 22.9 | G4: 25.3 | H4: 25.2 | I4: =C4*$L$3+D4*$L$4+E4*$L$5+F4*$L$6+G4*$L$7+H4*$L$8 -> 26.03 | J4: =I4/I$3 -> 0.99457435 | K4: Laborers | L4: 0.2 | M4: New Castle County sub-market proxy. Slightly above state average for urban premium.
B5: Philadelphia Metro | C5: 31.47 | D5: 27.82 | E5: 37.24 | F5: 26.36 | G5: 30.83 | H5: 28.7 | I5: =C5*$L$3+D5*$L$4+E5*$L$5+F5*$L$6+G5*$L$7+H5*$L$8 -> 29.954 | J5: =I5/I$3 -> 1.1445056 | K5: Electricians | L5: 0.1 | M5: Philadelphia-Camden-Wilmington MSA. Source: BLS OEWS 2024, MSA=37980.
B6: New Jersey | C6: 35.16 | D6: 34.27 | E6: 38.51 | F6: 31.16 | G6: 34.78 | H6: 29.5 | I6: =C6*$L$3+D6*$L$4+E6*$L$5+F6*$L$6+G6*$L$7+H6*$L$8 -> 33.913 | J6: =I6/I$3 -> 1.2957741 | K6: Painters | L6: 0.2 | M6: NJ statewide OEWS 2024, all industries. Higher union density drives premium.
B7: Baltimore Area | C7: 28.74 | D7: 22.99 | E7: 33.83 | F7: 27.86 | G7: 26.34 | H7: 24.13 | I7: =C7*$L$3+D7*$L$4+E7*$L$5+F7*$L$6+G7*$L$7+H7*$L$8 -> 27.222 | J7: =I7/I$3 -> 1.0401192 | K7: Concrete Finishers | L7: 0.1 | M7: Baltimore-Columbia-Towson MSA proxy. Source: BLS OEWS 2024, MSA=12580.
B8: Washington DC Metro | C8: 34.5 | D8: 27.1 | E8: 40.2 | F8: 29.5 | G8: 31.2 | H8: 30.4 | I8: =C8*$L$3+D8*$L$4+E8*$L$5+F8*$L$6+G8*$L$7+H8*$L$8 -> 31.85 | J8: =I8/I$3 -> 1.2169494 | K8: Drywall/Ceiling | L8: 0.1 | M8: DC-VA-MD-WV MSA. Source: BLS OEWS 2024, MSA=47900. High labor market tightness.
B9: Custom | C9: 0 | D9: 0 | E9: 0 | F9: 0 | G9: 0 | H9: 0 | I9: =C9*$L$3+D9*$L$4+E9*$L$5+F9*$L$6+G9*$L$7+H9*$L$8 -> 0 | J9: =I9/I$3 -> 0 | K9: TOTAL | L9: =SUM(L3:L8) -> 1 | M9: Enter custom wage rates. Factor auto-calculates vs. Delaware baseline.
B11: NOTE: Weighted Labor Basket is an internal blended labor-only ROM index using BLS OEWS wage data and the trade weightings shown at right. It is not a full construction location factor. ENR City Cost Indexes should be used for full project-level location adjustment when available.

Sheet UNIT PRICE LIBRARY
B2: M4Di™ UNIT PRICE LIBRARY — IDD Residential + Community Health Facility · M-Well Community Health Campus · Phase 1: School Renovation · New Castle County / Wilmington, Delaware · 2026 Pricing
B3: All base unit prices reflect New Castle County / Wilmington Delaware competitive bid market. Regional Factor and Escalation Factor apply automatically. Adjusted Unit Price feeds TAKEOFF via VLOOKUP on Cost Code. Blue/yellow input cells = overrideable. Do not modify columns I–K (formulas). Scope items aligned to M-Well Phase 1: 27,452 SF 2-story school → IDD R-4 residential + IDD licensing standards.
B4: B | C4: Div | D4: Cost Code | E4: Spec Section | F4: Bid Package | G4: Scope Item | H4: Unit | I4: Base Unit Price (Baseline Region) | J4: Region Factor | K4: Escalation Factor | L4: Adjusted Unit Price | M4: Owner Selection Sensitive? | N4: Source / Basis
B5: DIV 02 — DEMOLITION & SITE PREPARATION
C6: 02 | D6: DEM-01 | E6: 02 41 19 | G6: Selective demolition – interior non-structural partitions | H6: SF | I6: 4.5 | J6: =ASSUMPTIONS!C12 -> 1 | K6: =1+ASSUMPTIONS!C16 -> 1.035 | L6: =I6*J6*K6 -> 4.6575 | M6: No | N6: Per SF GFA. Includes debris removal and haul-off. Range $3–7/SF for school renovation.
C7: 02 | D7: DEM-02 | E7: 02 41 19 | G7: Selective demolition – existing ceilings and soffits | H7: SF | I7: 3.25 | J7: =ASSUMPTIONS!C12 -> 1 | K7: =1+ASSUMPTIONS!C16 -> 1.035 | L7: =I7*J7*K7 -> 3.36375 | M7: No | N7: ACT grid + tile or drywall ceiling removal. Includes sorting for recycling.
C8: 02 | D8: DEM-03 | E8: 02 41 13 | G8: Selective demolition – existing doors, frames, hardware | H8: EA | I8: 285 | J8: =ASSUMPTIONS!C12 -> 1 | K8: =1+ASSUMPTIONS!C16 -> 1.035 | L8: =I8*J8*K8 -> 294.975 | M8: No | N8: Per opening. Includes careful removal to protect openings for reuse or patching.
C9: 02 | D9: DEM-04 | E9: 02 41 19 | G9: Selective demolition – existing flooring (VCT/tile/carpet) | H9: SF | I9: 2.75 | J9: =ASSUMPTIONS!C12 -> 1 | K9: =1+ASSUMPTIONS!C16 -> 1.035 | L9: =I9*J9*K9 -> 2.84625 | M9: No | N9: Includes adhesive scraping and surface prep for new flooring. Hazmat survey assumed complete.
C10: 02 | D10: HAZ-01 | E10: 02 82 13 | G10: Asbestos abatement – floor tile and mastic (pre-1980 school) | H10: SF | I10: 18 | J10: =ASSUMPTIONS!C12 -> 1 | K10: =1+ASSUMPTIONS!C16 -> 1.035 | L10: =I10*J10*K10 -> 18.63 | M10: No | N10: Per SF affected area. Includes air monitoring, NESHAP notification, disposal. NCC licensed contractor.
C11: 02 | D11: HAZ-02 | E11: 02 83 13 | G11: Lead paint abatement – encapsulation or removal | H11: SF | I11: 6.5 | J11: =ASSUMPTIONS!C12 -> 1 | K11: =1+ASSUMPTIONS!C16 -> 1.035 | L11: =I11*J11*K11 -> 6.7275 | M11: No | N11: Per SF surface area. Method TBD by industrial hygienist report. Allowance pending Phase I ESA.
B12: DIV 03 — CONCRETE
C13: 03 | D13: CON-01 | E13: 03 30 00 | G13: Concrete slab patch / repair (existing slab anomalies) | H13: SF | I13: 22 | J13: =ASSUMPTIONS!C12 -> 1 | K13: =1+ASSUMPTIONS!C16 -> 1.035 | L13: =I13*J13*K13 -> 22.77 | M13: No | N13: Assumes 15% of floor area requires patching. Full slab replacement priced separately if needed.
C14: 03 | D14: CON-02 | E14: 03 30 00 | G14: Concrete housekeeping pad – mechanical equipment | H14: CY | I14: 450 | J14: =ASSUMPTIONS!C12 -> 1 | K14: =1+ASSUMPTIONS!C16 -> 1.035 | L14: =I14*J14*K14 -> 465.75 | M14: No | N14: Formed, reinforced, poured, finished. Per CY. For mechanical and plumbing equipment bases.
C15: 03 | D15: CON-03 | E15: 03 30 00 | G15: Elevator pit – concrete liner and sump | H15: LS | I15: 18500 | J15: =ASSUMPTIONS!C12 -> 1 | K15: =1+ASSUMPTIONS!C16 -> 1.035 | L15: =I15*J15*K15 -> 19147.5 | M15: No | N15: Lump sum allowance. Excavation, forming, waterproofing, pit drain. Coordinate with elevator supplier.
B16: DIV 04 — MASONRY
C17: 04 | D17: MAS-01 | E17: 04 22 00 | G17: CMU infill – existing openings to be closed | H17: SF | I17: 32 | J17: =ASSUMPTIONS!C12 -> 1 | K17: =1+ASSUMPTIONS!C16 -> 1.035 | L17: =I17*J17*K17 -> 33.12 | M17: No | N17: New CMU to match existing, includes mortar, grout, reinforcing. Toothing and pinning.
C18: 04 | D18: MAS-02 | E18: 04 22 00 | G18: CMU repair – tuck-pointing and spall repair | H18: SF | I18: 14.5 | J18: =ASSUMPTIONS!C12 -> 1 | K18: =1+ASSUMPTIONS!C16 -> 1.035 | L18: =I18*J18*K18 -> 15.0075 | M18: No | N18: Per SF affected surface. Includes mortar removal, repointing, color-matching mortar.
B19: DIV 05 — METALS
C20: 05 | D20: MET-01 | E20: 05 52 13 | G20: Stainless steel handrail – IDD residential corridor (1.5" dia.) | H20: LF | I20: 185 | J20: =ASSUMPTIONS!C12 -> 1 | K20: =1+ASSUMPTIONS!C16 -> 1.035 | L20: =I20*J20*K20 -> 191.475 | M20: No | N20: Continuous handrail both sides of corridor per DDDS licensing. Stainless for durability/hygiene.
C21: 05 | D21: MET-02 | E21: 05 52 13 | G21: Aluminum guardrail – stair and open-to-below conditions | H21: LF | I21: 365 | J21: =ASSUMPTIONS!C12 -> 1 | K21: =1+ASSUMPTIONS!C16 -> 1.035 | L21: =I21*J21*K21 -> 377.775 | M21: No | N21: IBC 42" height minimum. Includes anchor system. Powder coat standard.
C22: 05 | D22: MET-03 | E22: 05 40 00 | G22: Light gauge steel framing – new non-structural partitions | H22: SF | I22: 8.5 | J22: =ASSUMPTIONS!C12 -> 1 | K22: =1+ASSUMPTIONS!C16 -> 1.035 | L22: =I22*J22*K22 -> 8.7975 | M22: No | N22: Per SF of partition (one face). 3-5/8" 20ga stud at 16" OC. Includes track and bridging.
C23: 05 | D23: MET-04 | E23: 05 51 13 | G23: Steel stair – new elevator shaft framing and support | H23: LS | I23: 28000 | J23: =ASSUMPTIONS!C12 -> 1 | K23: =1+ASSUMPTIONS!C16 -> 1.035 | L23: =I23*J23*K23 -> 28980 | M23: No | N23: Allowance for elevator shaft structural framing, pit angle, and cab guide rail embeds.
B24: DIV 06 — WOOD & PLASTICS
C25: 06 | D25: CAR-01 | E25: 06 10 00 | G25: Rough carpentry – blocking and backing for grab bars / equipment | H25: SF | I25: 22 | J25: =ASSUMPTIONS!C12 -> 1 | K25: =1+ASSUMPTIONS!C16 -> 1.035 | L25: =I25*J25*K25 -> 22.77 | M25: No | N25: Per SF wall area requiring backing. IDD residential: extensive blocking for grab bars throughout.
C26: 06 | D26: CAR-02 | E26: 06 20 00 | G26: Finish carpentry – base cabinets (medication room, staff stations) | H26: LF | I26: 425 | J26: =ASSUMPTIONS!C12 -> 1 | K26: =1+ASSUMPTIONS!C16 -> 1.035 | L26: =I26*J26*K26 -> 439.875 | M26: Yes | N26: Allowance. Per LF of base cabinet. Includes box, door, hardware. Countertop separate.
C27: 06 | D27: CAR-03 | E27: 06 20 00 | G27: Finish carpentry – countertop (HPL, med-grade, per LF) | H27: LF | I27: 95 | J27: =ASSUMPTIONS!C12 -> 1 | K27: =1+ASSUMPTIONS!C16 -> 1.035 | L27: =I27*J27*K27 -> 98.325 | M27: Yes | N27: High-pressure laminate. Solid surface upcharge = $55/LF additional. ADA heights required.
B28: DIV 07 — THERMAL & MOISTURE PROTECTION
C29: 07 | D29: INS-01 | E29: 07 21 00 | G29: Batt insulation – exterior wall cavities (R-13 or R-19) | H29: SF | I29: 2.85 | J29: =ASSUMPTIONS!C12 -> 1 | K29: =1+ASSUMPTIONS!C16 -> 1.035 | L29: =I29*J29*K29 -> 2.94975 | M29: No | N29: Per SF of exterior wall. Faced batt, energy code compliant. Verify existing cavity depth.
C30: 07 | D30: INS-02 | E30: 07 21 19 | G30: Rigid insulation board – below-slab or roof deck | H30: SF | I30: 3.4 | J30: =ASSUMPTIONS!C12 -> 1 | K30: =1+ASSUMPTIONS!C16 -> 1.035 | L30: =I30*J30*K30 -> 3.519 | M30: No | N30: 2" polyiso or XPS. Per SF. For roof and slab-on-grade conditions.
C31: 07 | D31: ROO-01 | E31: 07 52 16 | G31: Roof membrane replacement – EPDM 60-mil fully adhered | H31: SF | I31: 14.5 | J31: =ASSUMPTIONS!C12 -> 1 | K31: =1+ASSUMPTIONS!C16 -> 1.035 | L31: =I31*J31*K31 -> 15.0075 | M31: No | N31: Per SF of roof area. Includes new insulation, edge metal, drain modification. No structural deck.
N32: Per SF of below-grade wall. Crystalline or sheet membrane. Includes drainage board.
C33: 07 | D33: CLK-01 | E33: 07 92 00 | G33: Sealants and caulking – windows, penetrations, control joints | H33: LF | I33: 8.5 | J33: =ASSUMPTIONS!C12 -> 1 | K33: =1+ASSUMPTIONS!C16 -> 1.035 | L33: =I33*J33*K33 -> 8.7975 | M33: No | N33: Per LF of joint. Silicone at exterior; paintable latex at interior. Safety-compliant VOC.
B34: DIV 08 — OPENINGS
C35: 08 | D35: DOO-01 | E35: 08 11 13 | G35: Hollow metal door + frame + hardware set – standard interior | H35: EA | I35: 3950 | J35: =ASSUMPTIONS!C12 -> 1 | K35: =1+ASSUMPTIONS!C16 -> 1.035 | L35: =I35*J35*K35 -> 4088.25 | M35: No | N35: Complete unit. ADA lever handle, LCN closer, Von Duprin panic if required. 3'x8' standard.
C36: 08 | D36: DOO-02 | E36: 08 11 13 | G36: Hollow metal door + frame + hardware – IDD resident bedroom (ligature-resistant) | H36: EA | I36: 5200 | J36: =ASSUMPTIONS!C12 -> 1 | K36: =1+ASSUMPTIONS!C16 -> 1.035 | L36: =I36*J36*K36 -> 5382 | M36: Yes | N36: Allowance. Anti-ligature hardware required per DDDS licensing: recessed hinges, tamper-resistant.
C37: 08 | D37: DOO-03 | E37: 08 11 13 | G37: Hollow metal door + frame – medication room (keyed security) | H37: EA | I37: 4800 | J37: =ASSUMPTIONS!C12 -> 1 | K37: =1+ASSUMPTIONS!C16 -> 1.035 | L37: =I37*J37*K37 -> 4968 | M37: Yes | N37: Allowance. Controlled access hardware, security hinges, vision panel with film. DDDS required.
C38: 08 | D38: DOO-04 | E38: 08 11 16 | G38: Aluminum storefront entrance – main accessible entry | H38: EA | I38: 18500 | J38: =ASSUMPTIONS!C12 -> 1 | K38: =1+ASSUMPTIONS!C16 -> 1.035 | L38: =I38*J38*K38 -> 19147.5 | M38: Yes | N38: Allowance. Full-lite aluminum with ADA-compliant power door operator. Includes threshold and sill.
C39: 08 | D39: WIN-01 | E39: 08 51 13 | G39: Aluminum window replacement – existing school openings | H39: SF | I39: 72 | J39: =ASSUMPTIONS!C12 -> 1 | K39: =1+ASSUMPTIONS!C16 -> 1.035 | L39: =I39*J39*K39 -> 74.52 | M39: Yes | N39: Allowance. Per SF of rough opening. Thermally broken aluminum, Low-E glazing, Safety film interior.
B40: DIV 09 — FINISHES
C41: 09 | D41: GWB-01 | E41: 09 29 00 | G41: Gypsum wallboard partition – 3-5/8" metal stud, taped + primed (per face) | H41: SF | I41: 17.5 | J41: =ASSUMPTIONS!C12 -> 1 | K41: =1+ASSUMPTIONS!C16 -> 1.035 | L41: =I41*J41*K41 -> 18.1125 | M41: No | N41: Per face SF. Double for both faces. Type-X at corridor walls per NFPA 101.
...

Sheet TAKEOFF
B2: QUANTITY TAKEOFF — M-Well Community Health Campus · Phase 1: School Building Renovation (IDD Residential, 27,452 SF)
B3: Enter quantities in column L (Quantity). Column M (Adj. Unit Cost) pulls automatically from UNIT PRICE LIBRARY via VLOOKUP on Cost Code. Column N (Line Total) = L × M. Column O (Included?) controls BID SUMMARY: enter 'Yes', 'No', or 'Allowance'. Add rows above the SUBTOTAL row. Do not modify formulas in L or M.
B4: B | C4: Floor | D4: Area / Zone | E4: Div | F4: Spec Section | G4: Bid Package | H4: Cost Code | I4: Scope Item | J4: Unit | K4: Quantity Source | L4: Quantity | M4: Adj. Unit Cost (from Library) | N4: Line Total | O4: Included? | P4: Comments
B5: FLOOR 1 — PHASE 1A: Partial Fit-Out + Full Building Life-Safety Backbone
C6: 1F | D6: Entire Building | E6: 02 | F6: 02 41 19 | H6: DEM-01 | I6: Selective demolition – interior partitions and finishes | J6: SF | K6: 27,452 SF × 65% demo factor | L6: 17844 | M6: =IFERROR(VLOOKUP(H6,'UNIT PRICE LIBRARY'!D:L,9,FALSE()),0) -> 4.6575 | N6: =IF(O6="No",0,L6*M6) -> 83108.43 | O6: Yes | P6: 65% of GFA requires interior demolition. Excludes areas to remain.
C7: 1F | D7: Entire Building | E7: 02 | F7: 02 41 19 | H7: DEM-02 | I7: Selective demolition – existing ceilings (ACT + drywall) | J7: SF | K7: 27,452 SF GFA | L7: 27452 | M7: =IFERROR(VLOOKUP(H7,'UNIT PRICE LIBRARY'!D:L,9,FALSE()),0) -> 3.36375 | N7: =IF(O7="No",0,L7*M7) -> 92341.665 | O7: Yes | P7: Full ceiling demolition required to run new MEP backbone.
C8: 1F | D8: Entire Building | E8: 02 | F8: 02 41 19 | H8: DEM-03 | I8: Selective demolition – existing doors, frames (to be replaced) | J8: EA | K8: Count existing | L8: 65 | M8: =IFERROR(VLOOKUP(H8,'UNIT PRICE LIBRARY'!D:L,9,FALSE()),0) -> 294.975 | N8: =IF(O8="No",0,L8*M8) -> 19173.375 | O8: Yes | P8: Replace 65 of estimated 80 door openings. Retain serviceable openings.
C9: 1F | D9: Entire Building | E9: 02 | F9: 02 41 19 | H9: DEM-04 | I9: Selective demolition – existing flooring throughout | J9: SF | K9: 27,452 SF GFA | L9: 27452 | M9: =IFERROR(VLOOKUP(H9,'UNIT PRICE LIBRARY'!D:L,9,FALSE()),0) -> 2.84625 | N9: =IF(O9="No",0,L9*M9) -> 78135.255 | O9: Yes | P9: Full flooring removal for new finishes and substrate prep.
C10: 1F | D10: Entire Building | E10: 02 | F10: HAZ-01 | H10: HAZ-01 | I10: Asbestos abatement – floor tile and mastic (pre-1980 school) | J10: SF | K10: Estimated 40% of floor area | L10: 10981 | M10: =IFERROR(VLOOKUP(H10,'UNIT PRICE LIBRARY'!D:L,9,FALSE()),0) -> 18.63 | N10: =IF(O10="No",0,L10*M10) -> 204576.03 | O10: Yes | P10: Pre-1980 building: assume 40% of floor area affected. Phase I ESA to confirm.
C11: 1F | D11: Corridors + Stairs | E11: 03 | F11: 03 30 00 | H11: CON-01 | I11: Concrete slab patch / repair – corridors and damaged areas | J11: SF | K11: Estimated 15% of slab | L11: 4118 | M11: =IFERROR(VLOOKUP(H11,'UNIT PRICE LIBRARY'!D:L,9,FALSE()),0) -> 22.77 | N11: =IF(O11="No",0,L11*M11) -> 93766.86 | O11: Yes | P11: 15% of floor area patching assumed for pre-1980 slab.
C12: 1F | D12: Elevator Shaft | E12: 03 | F12: 03 30 00 | H12: CON-03 | I12: Elevator pit – concrete liner, waterproofing, sump | J12: LS | K12: 1 shaft | L12: 1 | M12: =IFERROR(VLOOKUP(H12,'UNIT PRICE LIBRARY'!D:L,9,FALSE()),0) -> 19147.5 | N12: =IF(O12="No",0,L12*M12) -> 19147.5 | O12: Yes | P12: Phase 1A: shaft shell + pit only. Cab installed in Phase 1B.
C13: 1F | D13: Entire Building | E13: 04 | F13: 04 22 00 | H13: MAS-01 | I13: CMU infill – new program openings to be closed | J13: SF | K13: Estimated 8 openings × 40 SF | L13: 320 | M13: =IFERROR(VLOOKUP(H13,'UNIT PRICE LIBRARY'!D:L,9,FALSE()),0) -> 33.12 | N13: =IF(O13="No",0,L13*M13) -> 10598.4 | O13: Yes | P13: New program partitions require closure of some existing openings.
C14: 1F | D14: Corridors + Stairs | E14: 05 | F14: 05 52 13 | H14: MET-01 | I14: Stainless steel handrail – IDD residential corridors (both sides) | J14: LF | K14: Corridor LF × 2 sides × 2 floors ÷ 2 | L14: 520 | M14: =IFERROR(VLOOKUP(H14,'UNIT PRICE LIBRARY'!D:L,9,FALSE()),0) -> 191.475 | N14: =IF(O14="No",0,L14*M14) -> 99567 | O14: Yes | P14: 520 LF of corridor on Floor 1. Both sides per DDDS. Stainless for hygiene.
C15: 1F | D15: Stairs A + B | E15: 05 | F15: 05 52 13 | H15: MET-02 | I15: Aluminum guardrail – stair A and B open-to-below | J15: LF | K15: 2 stairs × 28 LF each | L15: 56 | M15: =IFERROR(VLOOKUP(H15,'UNIT PRICE LIBRARY'!D:L,9,FALSE()),0) -> 377.775 | N15: =IF(O15="No",0,L15*M15) -> 21155.4 | O15: Yes | P15: IBC 42" guardrail at open stair conditions.
C16: 1F | D16: New Partitions | E16: 05 | F16: 05 40 00 | H16: MET-03 | I16: Light gauge steel framing – new IDD program partitions | J16: SF | K16: New partition area (both faces) 6,400 SF | L16: 6400 | M16: =IFERROR(VLOOKUP(H16,'UNIT PRICE LIBRARY'!D:L,9,FALSE()),0) -> 8.7975 | N16: =IF(O16="No",0,L16*M16) -> 56304 | O16: Yes | P16: New partitions for program rooms on Floor 1. Both faces included.
C17: 1F | D17: Elevator Shaft | E17: 05 | F17: 05 51 13 | H17: MET-04 | I17: Steel elevator shaft framing + structural support | J17: LS | K17: 1 shaft | L17: 1 | M17: =IFERROR(VLOOKUP(H17,'UNIT PRICE LIBRARY'!D:L,9,FALSE()),0) -> 28980 | N17: =IF(O17="No",0,L17*M17) -> 28980 | O17: Yes | P17: Shaft steel, pit angle, guide rail embeds. Cab by owner in Phase 1B.
... C28: 1F | D28: Corridors + Common | E28: 09 | F28: GWB-01 | H28: GWB-01 | I28: GWB partition – new IDD program partitions (per face) | J28: SF | K28: New partition area (both faces) | L28: 6400 | M28: =IFERROR(VLOOKUP(H28,'UNIT PRICE LIBRARY'!D:L,9,FALSE()),0) -> 18.1125 | N28: =IF(O28="No",0,L28*M28) -> 115920 | O28: Yes | P28: Type-X GWB at corridor walls per NFPA 101 § 18/19.
M29: =IFERROR(VLOOKUP(H29,'UNIT PRICE LIBRARY'!D:L,9,FALSE()),0) -> 0 | N29: =IF(O29="No",0,L29*M29) -> 0 | O29: Yes | P29: Cement board at tile areas; moisture-resistant GWB elsewhere in wet rooms.
P30: Excludes resident rooms (drywall) and bathrooms (MR tile).
C31: 1F | D31: Bathrooms | E31: 09 | F31: 09 51 23 | H31: ACT-02 | I31: ACT ceiling – moisture-resistant (all bathrooms + laundry) | J31: SF | K31: 42 bathrooms × 80 SF + laundry 100 SF | L31: 3460 | M31: =IFERROR(VLOOKUP(H31,'UNIT PRICE LIBRARY'!D:L,9,FALSE()),0) -> 11.9025 | N31: =IF(O31="No",0,L31*M31) -> 41182.65 | O31: Yes | P31: MR tile or MR ACT at all wet rooms per DDDS.
C32: 1F | D32: Resident Rooms + Stairs | E32: 09 | F32: 09 29 00 | H32: GWB-03 | I32: Drywall ceiling – resident bedrooms and sensory rooms | J32: SF | K32: 35 rooms × 180 SF avg ceiling | L32: 6300 | M32: =IFERROR(VLOOKUP(H32,'UNIT PRICE LIBRARY'!D:L,9,FALSE()),0) -> 13.19625 | N32: =IF(O32="No",0,L32*M32) -> 83136.375 | O32: Yes | P32: Smooth drywall ceiling at resident rooms. Sensory rooms: full smooth interior.
C33: 1F | D33: Common Areas | E33: 09 | F33: 09 91 00 | H33: PAI-01 | I33: Interior paint – standard 2-coat (walls + ceilings, all spaces) | J33: SF | K33: 27,452 SF × 2.8 surface factor | L33: 76866 | M33: =IFERROR(VLOOKUP(H33,'UNIT PRICE LIBRARY'!D:L,9,FALSE()),0) -> 4.08825 | N33: =IF(O33="No",0,L33*M33) -> 314247.42 | O33: Yes | P33: 2.8× surface factor for walls + ceiling. Low-VOC required throughout.
C34: 1F | D34: Bathrooms + Kitchens | E34: 09 | F34: 09 91 00 | H34: PAI-02 | I34: Interior paint – semi-gloss (all wet and clinical areas) | J34: SF | K34: Bathroom + kitchen wall SF | L34: 12400 | M34: =IFERROR(VLOOKUP(H34,'UNIT PRICE LIBRARY'!D:L,9,FALSE()),0) -> 4.6575 | N34: =IF(O34="No",0,L34*M34) -> 57753 | O34: Yes | P34: Semi-gloss for washability at all wet areas and medication rooms.
C35: 1F | D35: Mechanical + Utility | E35: 09 | F35: 09 96 00 | H35: PAI-03 | I35: High-performance epoxy coating – mechanical and utility rooms | J35: SF | K35: Mech 320 SF + utility 200 SF | L35: 520 | M35: =IFERROR(VLOOKUP(H35,'UNIT PRICE LIBRARY'!D:L,9,FALSE()),0) -> 10.8675 | N35: =IF(O35="No",0,L35*M35) -> 5651.1 | O35: Yes | P35: Epoxy floor and wall at all mechanical/electrical rooms.
C36: 1F | D36: Resident Rooms + Corridors | E36: 09 | F36: 09 65 13 | H36: FLR-01 | I36: LVT flooring – resident bedrooms and corridors (6mm commercial) | J36: SF | K36: Rooms 9,000 SF + corridors 4,200 SF | L36: 13200 | M36: =IFERROR(VLOOKUP(H36,'UNIT PRICE LIBRARY'!D:L,9,FALSE()),0) -> 11.9025 | N36: =IF(O36="No",0,L36*M36) -> 157113 | O36: Yes | P36: Commercial LVT throughout residential areas. Ease of cleaning key for IDD program.
C37: 1F | D37: Bathrooms | E37: 09 | F37: 09 66 13 | H37: FLR-02 | I37: Ceramic tile – bathroom floors (slip-resistant, DCOF ≥0.42) | J37: SF | K37: 42 bathrooms × 80 SF | L37: 3360 | M37: =IFERROR(VLOOKUP(H37,'UNIT PRICE LIBRARY'!D:L,9,FALSE()),0) -> 19.1475 | N37: =IF(O37="No",0,L37*M37) -> 64335.6 | O37: Yes | P37: Slip-resistant porcelain. ADA-compliant DCOF. Required at all IDD bathrooms.
C38: 1F | D38: Bathrooms | E38: 09 | F38: 09 66 13 | H38: FLR-03 | I38: Ceramic tile – bathroom walls (wainscot to 72") | J38: SF | K38: 42 bathrooms × 240 SF walls to 72" | L38: 10080 | M38: =IFERROR(VLOOKUP(H38,'UNIT PRICE LIBRARY'!D:L,9,FALSE()),0) -> 17.0775 | N38: =IF(O38="No",0,L38*M38) -> 172141.2 | O38: Yes | P38: Full tile wainscot at all resident bathrooms per DDDS hygiene standards.
C39: 1F | D39: Sensory Rooms | E39: 09 | F39: 09 65 16 | H39: FLR-04 | I39: Sheet vinyl – sensory rooms (seamless, cushioned, impact-absorbing) | J39: SF | K39: 2 sensory rooms × 280 SF | L39: 560 | M39: =IFERROR(VLOOKUP(H39,'UNIT PRICE LIBRARY'!D:L,9,FALSE()),0) -> 14.23125 | N39: =IF(O39="No",0,L39*M39) -> 7969.5 | O39: Allowance | P39: Forbo Marmoleum or equal. OT-specified. Color/pattern TBD by OT program.
C40: 1F | D40: Therapy Rooms | E40: 09 | F40: 09 68 13 | H40: FLR-05 | I40: Carpet tile – therapy and activity rooms (soft zone) | J40: SF | K40: 3 therapy rooms × 420 SF avg | L40: 1260 | M40: =IFERROR(VLOOKUP(H40,'UNIT PRICE LIBRARY'!D:L,9,FALSE()),0) -> 7.7625 | N40: =IF(O40="No",0,L40*M40) -> 9780.75 | O40: Allowance | P40: 24x24 carpet tile. IDD: pattern and color per OT recommendation. Avoid strong patterns.
C41: 1F | D41: IDD Corridors | E41: 09 | F41: 09 22 36 | H41: ACC-01 | I41: Corner guards – stainless steel IDD corridors (full height) | J41: LF | K41: Corridor LF × 4 corners per bay × est. factor | L41: 280 | M41: =IFERROR(VLOOKUP(H41,'UNIT PRICE LIBRARY'!D:L,9,FALSE()),0) -> 43.47 | N41: =IF(O41="No",0,L41*M41) -> 12171.6 | O41: Yes | P41: All IDD corridor corners. Full height stainless. DDDS standard requirement.
C42: 1F | D42: IDD Corridors | E42: 09 | F42: 09 22 36 | H42: ACC-02 | I42: Wall protection – chair rail and crash rail system | J42: LF | K42: Corridor LF × 2 sides | L42: 1040 | M42: =IFERROR(VLOOKUP(H42,'UNIT PRICE LIBRARY'!D:L,9,FALSE()),0) -> 29.4975 | N42: =IF(O42="No",0,L42*M42) -> 30677.4 | O42: Yes | P42: 32" and 42" rails at residential corridors. Protects walls and residents.
... C55: 1F | D55: Therapy Rooms | E55: 11 | F55: 11 72 00 | H55: EQP-05 | I55: Therapy room equipment package (OT/PT standard) | J55: LS | K55: 3 therapy rooms | L55: 3 | M55: =IFERROR(VLOOKUP(H55,'UNIT PRICE LIBRARY'!D:L,9,FALSE()),0) -> 18630 | N55: =IF(O55="No",0,L55*M55) -> 55890 | O55: Allowance | P55: Balance beams, therapy mats, balls, storage. Scope from OT program guide.
B56: FULL BUILDING — Life-Safety + MEP Backbone (Phase 1A — Non-Negotiable Scope)
C57: BLDG | D57: Entire Building | E57: 21 | F57: 21 13 13 | H57: FPS-01 | I57: NFPA 13 wet-pipe sprinkler system – full building (27,452 SF) | J57: SF | K57: Full building GFA | L57: 27452 | M57: =IFERROR(VLOOKUP(H57,'UNIT PRICE LIBRARY'!D:L,9,FALSE()),0) -> 8.7975 | N57: =IF(O57="No",0,L57*M57) -> 241508.97 | O57: Yes | P57: Full building NFPA 13 required for IBC R-4 IDD residential. Cannot phase. Install entire building in Phase 1A.
C58: BLDG | D58: Entire Building | E58: 22 | F58: 22 11 16 | H58: PLB-01 | I58: Plumbing rough-in + trim – new bathrooms (complete fixture group) | J58: EA | K58: 42 bathrooms | L58: 42 | M58: =IFERROR(VLOOKUP(H58,'UNIT PRICE LIBRARY'!D:L,9,FALSE()),0) -> 15007.5 | N58: =IF(O58="No",0,L58*M58) -> 630315 | O58: Yes | P58: Full plumbing at all bathrooms. WC, lavatory, shower where applicable. Full waste/vent runs.
C59: BLDG | D59: Resident Bathrooms | E59: 22 | F59: 22 11 16 | H59: PLB-02 | I59: ADA anti-ligature water closet (wall-hung, DDDS) | J59: EA | K59: 35 resident bathrooms | L59: 35 | M59: =IFERROR(VLOOKUP(H59,'UNIT PRICE LIBRARY'!D:L,9,FALSE()),0) -> 2277 | N59: =IF(O59="No",0,L59*M59) -> 79695 | O59: Yes | P59: Anti-ligature flush valve required per DDDS at all resident bathrooms.
C60: BLDG | D60: Resident Bathrooms | E60: 22 | F60: 22 11 16 | H60: PLB-03 | I60: ADA lavatory (wall-hung, insulated P-trap) | J60: EA | K60: 35 resident bathrooms | L60: 35 | M60: =IFERROR(VLOOKUP(H60,'UNIT PRICE LIBRARY'!D:L,9,FALSE()),0) -> 1500.75 | N60: =IF(O60="No",0,L60*M60) -> 52526.25 | O60: Yes | P60: Anti-scald protection, insulated P-trap, anti-ligature faucet.
C61: BLDG | D61: Mechanical Rooms | E61: 22 | F61: 22 35 00 | H61: PLB-04 | I61: Domestic hot water heaters – commercial (1 per 20-resident zone) | J61: EA | K61: 6 zones for 112 residents | L61: 6 | M61: =IFERROR(VLOOKUP(H61,'UNIT PRICE LIBRARY'!D:L,9,FALSE()),0) -> 8797.5 | N61: =IF(O61="No",0,L61*M61) -> 52785 | O61: Yes | P61: High-recovery commercial units with tempering valves for safety.
C62: BLDG | D62: Kitchen | E62: 22 | F62: 22 11 16 | H62: PLB-05 | I62: Kitchen plumbing rough-in – dining service equipment connections | J62: LS | K62: 1 kitchen | L62: 1 | M62: =IFERROR(VLOOKUP(H62,'UNIT PRICE LIBRARY'!D:L,9,FALSE()),0) -> 18630 | N62: =IF(O62="No",0,L62*M62) -> 18630 | O62: Yes | P62: All kitchen equipment rough plumbing. Gas (if applicable) priced separately.
C63: BLDG | D63: Resident Rooms | E63: 23 | F63: 23 05 00 | H63: HVA-01 | I63: HVAC – unit ventilators with individual zone control (per room) | J63: EA | K63: 35 resident rooms | L63: 35 | M63: =IFERROR(VLOOKUP(H63,'UNIT PRICE LIBRARY'!D:L,9,FALSE()),0) -> 4968 | N63: =IF(O63="No",0,L63*M63) -> 173880 | O63: Yes | P63: Individual zone control required per DDDS for resident comfort and infection control.
...

Sheet EQUIPMENT ALLOWANCES
B1: OWNER SELECTION / ATHLETIC EQUIPMENT ALLOWANCES
B2: Category | C2: Allowance Item | D2: Basis of Design | E2: Qty | F2: Allowance Each | G2: Allowance Total | H2: Owner Selection Status | I2: Comments / Open Items
B3: Gym | C3: Main/side basketball backstop systems | D3: Jaypro / Porter / Draper | E3: 4 | F3: 14500 | G3: =E3*F3 -> 58000 | H3: Pending | I3: Select model/series, extension length, mounting type. 1 main + 3 side courts.
B4: Gym | C4: Telescoping bleacher system | D4: Jaypro / Irwin / Hussey | E4: 1 | F4: 95000 | G4: =E4*F4 -> 95000 | H4: Pending | I4: Confirm row count, rail configuration, ADA seating layout, finish.
B5: Gym | C5: Scoreboard / control system | D5: Daktronics / Watchfire / Electro-Mech | E5: 1 | F5: 18000 | G5: =E5*F5 -> 18000 | H5: Pending | I5: Confirm display type, clock size, controller, optional shot clock.
B6: Gym | C6: Wall padding / graphics | D6: Jaypro / Safety Padding / Bison | E6: 1 | F6: 32000 | G6: =E6*F6 -> 32000 | H6: Pending | I6: Confirm padding extents, color, logos / graphics, stage pad scope.
B7: Gym | C7: Volleyball post/sleeve system | D7: Jaypro / Porter / Draper | E7: 1 | F7: 3500 | G7: =E7*F7 -> 3500 | H7: Pending | I7: Confirm 7000-series configuration or equivalent.
B8: Boxing | C8: Boxing ring and accessories | D8: Title / Ringside / Everlast | E8: 1 | F8: 18000 | G8: =E8*F8 -> 18000 | H8: Pending | I8: Confirm ring size, ropes, corner pads, canvas, accessory package.
B9: Boxing | C9: Bag systems / speed bag stations | D9: Various | E9: 1 | F9: 14000 | G9: =E9*F9 -> 14000 | H9: Pending | I9: Confirm bag count, support frame type, bag style/weight, speed bag platform.
B10: Boxing | C10: Rubber athletic flooring | D10: Mondo / Ecore / Gerflor | E10: 2500 | F10: 14.5 | G10: =E10*F10 -> 36250 | H10: Pending | I10: Confirm thickness (6/8/10mm), color, transition details, wall base color.
B12: TOTAL EQUIPMENT ALLOWANCES | G12: =SUM(G3:G10) -> 274750
B13: Items Pending Owner Decision | G13: =COUNTIF(H3:H10,"Pending") -> 8

Sheet FLOOR SUMMARY
B1: FLOOR-BY-FLOOR COST SUMMARY
B2: Floor | C2: Base Building Subtotal | D2: Equipment Allowances | E2: Subtotal | F2: General Conditions | G2: OH&P | H2: Contingencies | I2: Bid/Permit/Bonds | J2: Est. Floor Total
B3: BLDG | C3: =SUMPRODUCT((TAKEOFF!$C$5:$C$200=B3)*(TAKEOFF!$O$5:$O$200="Yes")*TAKEOFF!$N$5:$N$200) -> 2451138.8 | D3: =SUMPRODUCT((TAKEOFF!$C$5:$C$200=B3)*(TAKEOFF!$O$5:$O$200="Allowance")*TAKEOFF!$N$5:$N$200) -> 51801.75 | E3: =C3+D3 -> 2502940.5 | F3: =E3*ASSUMPTIONS!$C$19 -> 200235.24 | G3: =(E3+F3)*ASSUMPTIONS!$C$20 -> 270317.57 | H3: =(E3+F3+G3)*(ASSUMPTIONS!$C$21+ASSUMPTIONS!$C$22+ASSUMPTIONS!$C$23) -> 892047.99 | I3: =(E3+F3+G3+H3)*ASSUMPTIONS!$C$24 -> 77310.826 | J3: =SUM(E3:I3) -> 3942852.1
B4: 1F | C4: =SUMPRODUCT((TAKEOFF!$C$5:$C$200=B4)*(TAKEOFF!$O$5:$O$200="Yes")*TAKEOFF!$N$5:$N$200) -> 2905549 | D4: =SUMPRODUCT((TAKEOFF!$C$5:$C$200=B4)*(TAKEOFF!$O$5:$O$200="Allowance")*TAKEOFF!$N$5:$N$200) -> 327318.75 | E4: =C4+D4 -> 3232867.7 | F4: =E4*ASSUMPTIONS!$C$19 -> 258629.42 | G4: =(E4+F4)*ASSUMPTIONS!$C$20 -> 349149.71 | H4: =(E4+F4+G4)*(ASSUMPTIONS!$C$21+ASSUMPTIONS!$C$22+ASSUMPTIONS!$C$23) -> 1152194.1 | I4: =(E4+F4+G4+H4)*ASSUMPTIONS!$C$24 -> 99856.818 | J4: =SUM(E4:I4) -> 5092697.7
B5: 2F | C5: =SUMPRODUCT((TAKEOFF!$C$5:$C$200=B5)*(TAKEOFF!$O$5:$O$200="Yes")*TAKEOFF!$N$5:$N$200) -> 0 | D5: =SUMPRODUCT((TAKEOFF!$C$5:$C$200=B5)*(TAKEOFF!$O$5:$O$200="Allowance")*TAKEOFF!$N$5:$N$200) -> 0 | E5: =C5+D5 -> 0 | F5: =E5*ASSUMPTIONS!$C$19 -> 0 | G5: =(E5+F5)*ASSUMPTIONS!$C$20 -> 0 | H5: =(E5+F5+G5)*(ASSUMPTIONS!$C$21+ASSUMPTIONS!$C$22+ASSUMPTIONS!$C$23) -> 0 | I5: =(E5+F5+G5+H5)*ASSUMPTIONS!$C$24 -> 0 | J5: =SUM(E5:I5) -> 0
B6: SITE | C6: =SUMPRODUCT((TAKEOFF!$C$5:$C$200=B6)*(TAKEOFF!$O$5:$O$200="Yes")*TAKEOFF!$N$5:$N$200) -> 55269 | D6: =SUMPRODUCT((TAKEOFF!$C$5:$C$200=B6)*(TAKEOFF!$O$5:$O$200="Allowance")*TAKEOFF!$N$5:$N$200) -> 94599 | E6: =C6+D6 -> 149868 | F6: =E6*ASSUMPTIONS!$C$19 -> 11989.44 | G6: =(E6+F6)*ASSUMPTIONS!$C$20 -> 16185.744 | H6: =(E6+F6+G6)*(ASSUMPTIONS!$C$21+ASSUMPTIONS!$C$22+ASSUMPTIONS!$C$23) -> 53412.955 | I6: =(E6+F6+G6+H6)*ASSUMPTIONS!$C$24 -> 4629.1228 | J6: =SUM(E6:I6) -> 236085.26
B7: TOTAL
B8: TOTAL | C8: =SUM(C3:C6) -> 5411956.7 | D8: =SUM(D3:D6) -> 473719.5 | E8: =SUM(E3:E6) -> 5885676.2 | F8: =SUM(F3:F6) -> 470854.1 | G8: =SUM(G3:G6) -> 635653.03 | H8: =SUM(H3:H6) -> 2097655 | I8: =SUM(I3:I6) -> 181796.77 | J8: =SUM(J3:J6) -> 9271635.1
B10: ↑ Total Project ROM feeds BID SUMMARY and SF BENCHMARK sheets.

Sheet BID SUMMARY
B1: ROM COST ESTIMATE — EXECUTIVE SUMMARY
B2: ="Project: " & ASSUMPTIONS!C3 -> Project: M-Well Community Health Campus
B3: ="Estimate Date: " & TEXT(ASSUMPTIONS!C4,"mm/dd/yyyy") & " | Type: " & ASSUMPTIONS!C5 -> Estimate Date: 01/00/1900 | Type: ROM / Conceptual
B4: Summary Item | C4: Amount | E4: Pricing Basis / Notes
B5: Base Building Subtotal | C5: =IFERROR(SUMIF('FLOOR SUMMARY'!B3:B8,"<>TOTAL",'FLOOR SUMMARY'!C3:C8),0) -> 5411956.7 | E5: Architectural / interior renovation ROM with quantity-based takeoff. Excludes allowances.
B6: Equipment Allowances | C6: =IFERROR(SUM('FLOOR SUMMARY'!D3:D6),0) -> 473719.5 | E6: Owner-selection-dependent athletic and specialty equipment. Pending confirmation.
B7: Subtotal Before Markups | C7: =C5+C6 -> 5885676.2
B8: General Conditions | C8: =C7*ASSUMPTIONS!$C$19 -> 470854.1 | E8: Rate: per ASSUMPTIONS!C19
B9: Overhead & Profit (OH&P) | C9: =(C7+C8)*ASSUMPTIONS!$C$20 -> 635653.03 | E9: Rate: per ASSUMPTIONS!C20
B10: Total Contingencies | C10: =(C7+C8+C9)*(ASSUMPTIONS!C21+ASSUMPTIONS!C22+ASSUMPTIONS!C23) -> 2097655 | E10: Design + existing conditions + equipment/owner selection contingencies.
B11: Bid / Permit / Bonds | C11: =(C7+C8+C9+C10)*ASSUMPTIONS!$C$24 -> 181796.77 | E11: Rate: per ASSUMPTIONS!C24
B12: TOTAL PROJECT ROM | C12: =C5+C8+C9+C10+C11 -> 8797915.6
B14: Project Cost per SF | C14: =IFERROR(C12/ASSUMPTIONS!$C$9,0) -> 320.48359 | E14: Reference only. Compare to SF BENCHMARK sheet for sanity check.
B16: CONTINGENCY BREAKDOWN (for reference)
B17: Design Contingency | C17: =(C7+C8+C9)*ASSUMPTIONS!C21 -> 839062
B18: Existing Conditions Contingency | C18: =(C7+C8+C9)*ASSUMPTIONS!C22 -> 699218.34
B19: Equipment/Owner Selection Contingency | C19: =(C7+C8+C9)*ASSUMPTIONS!C23 -> 559374.67
B21: SOFT COSTS & TOTAL PROJECT INVESTMENT (see SOFT COSTS and TOTAL PROJECT BUDGET sheets)
B22: Architecture Fee (from SOFT COSTS) | C22: ='SOFT COSTS'!F54 -> 690636.38 | E22: Base fee + renovation premium per M4Di fee schedule.
B23: Total Engineering Fees | C23: ='SOFT COSTS'!F84 -> 818206.15 | E23: Structural, MEP, FP, Civil, Geotech.
B24: Other Consultant & Owner Costs | C24: ='SOFT COSTS'!F85 -> 439895.78 | E24: Technology, legal, permits, insurance, testing, environmental.
B25: TOTAL SOFT COSTS | C25: ='SOFT COSTS'!F86 -> 1948738.3 | E25: See SOFT COSTS sheet for detail and overrides.
B26: Owner Contingency | C26: ='TOTAL PROJECT BUDGET'!C34 -> 439895.78 | E26: Post-GMP owner contingency and program reserves.
B27: TOTAL PROJECT INVESTMENT | C27: ='TOTAL PROJECT BUDGET'!C36 -> 11186550 | E27: Full project cost: hard + soft + owner costs.

Sheet SF BENCHMARK
B1: COST PER SF — BENCHMARK DASHBOARD
B2: Compares current ROM estimate to M4Di historical database and facility type benchmarks.
B3: Metric | C3: Value | E3: Historical Comparison | F3: Value
B4: Project Area (SF) | C4: =ASSUMPTIONS!C9 -> 27452 | E4: Project $/SF vs. Hist. Avg | F4: =IFERROR(C6/C7,"N/A - no data") -> 0.00016056292
B5: ROM Construction Cost | C5: ='BID SUMMARY'!C12 -> 8797915.6 | E5: Project $/SF vs. Hist. Median | F5: =IFERROR(C6/C8,"N/A - no data") -> 0.00015261124
B6: Calculated Project Cost/SF | C6: ='BID SUMMARY'!C14 -> 320.48359 | E6: Sanity Check | F6: =IF(C6>C10,"Above historical max",IF(C6>C7,"Above historical average",IF(C6<C9,"Below historical min","Within historical range"))) -> Within historical range
B7: Historical Average $/SF | C7: =IFERROR(AVERAGE('HISTORICAL DB'!G4:G103),0) -> 1996000
B8: Historical Median $/SF | C8: =IFERROR(MEDIAN('HISTORICAL DB'!G4:G103),0) -> 2100000
B9: Historical Min $/SF | C9: =IFERROR(MIN(IF('HISTORICAL DB'!G4:G103>0,'HISTORICAL DB'!G4:G103)),0) -> 0
B10: Historical Max $/SF | C10: =IFERROR(MAX('HISTORICAL DB'!G4:G103),0) -> 3200000
B11: Historical Data Count | C11: =COUNTA('HISTORICAL DB'!A4:A103) -> 0
B13: FACILITY TYPE BENCHMARK RANGES ($/SF)
B14: Facility Type | C14: Low $/SF | D14: High $/SF | F14: Check vs. Project
B15: Community Facility Renovation | C15: 120 | D15: 250 | F15: =IF('BID SUMMARY'!C14=0,"Enter data",IF('BID SUMMARY'!C14<C15,"Below range",IF('BID SUMMARY'!C14>D15,"Above range","Within range"))) -> Above range
B16: Church / Faith-Based Renovation | C16: 110 | D16: 230 | F16: =IF('BID SUMMARY'!C14=0,"Enter data",IF('BID SUMMARY'!C14<C16,"Below range",IF('BID SUMMARY'!C14>D16,"Above range","Within range"))) -> Above range
B17: Athletic Facility Upgrade | C17: 150 | D17: 320 | F17: =IF('BID SUMMARY'!C14=0,"Enter data",IF('BID SUMMARY'!C14<C17,"Below range",IF('BID SUMMARY'!C14>D17,"Above range","Within range"))) -> Above range
B18: Athletic Flooring Replacement | C18: 80 | D18: 165 | F18: =IF('BID SUMMARY'!C14=0,"Enter data",IF('BID SUMMARY'!C14<C18,"Below range",IF('BID SUMMARY'!C14>D18,"Above range","Within range"))) -> Above range
B19: Adaptive Reuse — Community Use | C19: 140 | D19: 290 | F19: =IF('BID SUMMARY'!C14=0,"Enter data",IF('BID SUMMARY'!C14<C19,"Below range",IF('BID SUMMARY'!C14>D19,"Above range","Within range"))) -> Above range
B20: New Construction — Community Fac. | C20: 220 | D20: 420 | F20: =IF('BID SUMMARY'!C14=0,"Enter data",IF('BID SUMMARY'!C14<C20,"Below range",IF('BID SUMMARY'!C14>D20,"Above range","Within range"))) -> Within range
B21: Mixed-Use (residential + community) | C21: 260 | D21: 480 | F21: =IF('BID SUMMARY'!C14=0,"Enter data",IF('BID SUMMARY'!C14<C21,"Below range",IF('BID SUMMARY'!C14>D21,"Above range","Within range"))) -> Within range
B24: HOW TO READ THIS DASHBOARD
B25: If project $/SF is BELOW all ranges: | C25: Scope may be missing items, quantities may be understated, or allowances are not yet included.
B26: If project $/SF is ABOVE all ranges: | C26: Owner selections, specialty equipment, corrosion remediation, or code upgrades may be driving cost.
B27: If project aligns with historical average: | C27: ROM is behaving like a plausible early estimate. Continue to P3 for detailed scope confirmation.
B28: Historical database: | C28: Replace example rows in HISTORICAL DB with M4Di's own completed projects over time. This is the proprietary asset.

Sheet HISTORICAL DB
B1: M4Di HISTORICAL PROJECT COST DATABASE — PROPRIETARY ASSET
B2: CRITICAL: Enter every completed M4Di engagement in this database. This is M4Di's proprietary competitive advantage. Do not distribute externally. Source for SF BENCHMARK dashboard and annual cost reports.
B3: Project Name / Code | C3: Project Type | D3: Location / Region | E3: Year Completed | F3: Building Area (SF) | G3: Final Const. Cost | H3: Cost / SF | I3: Scope Description | J3: Data Source / Notes
B4: YMCA Gymnasium Renovation | C4: Athletic Facility Upgrade | D4: Pennsylvania | E4: 2023 | F4: 18000 | G4: 3200000 | H4: =IFERROR(G4/F4,0) -> 177.77778 | I4: Gym upgrades, flooring, bleachers, scoring equipment, wall padding. | J4: Example benchmark — replace with M4Di project data
B5: High School Gymnasium Upgrade | C5: Athletic Facility Upgrade | D5: Delaware | E5: 2022 | F5: 12000 | G5: 2100000 | H5: =IFERROR(G5/F5,0) -> 175 | I5: Bleacher replacement, floor refinish, scoreboard, accessible path of travel. | J5: Example benchmark — replace with M4Di project data
B6: Community Rec Center Interior | C6: Community Facility Renovation | D6: Maryland | E6: 2021 | F6: 8000 | G6: 950000 | H6: =IFERROR(G6/F6,0) -> 118.75 | I6: Interior renovation, athletic flooring, community room upgrades. | J6: Example benchmark — replace with M4Di project data
B7: Church Fellowship Hall Adaptive Reuse | C7: Adaptive Reuse — Community Use | D7: Delaware | E7: 2023 | F7: 6500 | G7: 1450000 | H7: =IFERROR(G7/F7,0) -> 223.07692 | I7: Fellowship hall converted to community clinic and gathering space. ADA upgrades. | J7: Example benchmark — replace with M4Di project data
B8: Faith-Based Youth Center Renovation | C8: Community Facility Renovation | D8: New Jersey | E8: 2024 | F8: 9200 | G8: 2280000 | H8: =IFERROR(G8/F8,0) -> 247.82609 | I8: Full interior renovation, new MEP, gymnasium floor, community kitchen. | J8: Example benchmark — replace with M4Di project data
B10: → ADD NEW COMPLETED PROJECTS ABOVE THIS LINE. Copy Cost/SF formula from column H. Fill all fields at project closeout.
B12: DATABASE STATISTICS (auto-calculated — used by SF BENCHMARK)
B13: Total Projects in Database | C13: =COUNTA(B4:B9) -> 5
B14: Average Cost / SF | C14: =IFERROR(AVERAGE(H4:H9),0) -> 188.48616
B15: Median Cost / SF | C15: =IFERROR(MEDIAN(H4:H9),0) -> 177.77778
B16: Minimum Cost / SF | C16: =IFERROR(MIN(IF(H4:H9>0,H4:H9)),0) -> 0
B17: Maximum Cost / SF | C17: =IFERROR(MAX(H4:H9),0) -> 247.82609

Sheet OWNER SELECTIONS
B1: OWNER ATHLETIC EQUIPMENT SELECTION MATRIX
B2: Use this sheet to document owner selections affecting allowances and final bid comparability. Each "Pending" item represents an open decision that must be resolved before the estimate can be finalized.
B3: Allowance Ref | C3: Category | D3: Equipment / System | E3: Spec Section | F3: Basis of Design | G3: Owner Confirm? | H3: Selected Mfr. | I3: Selected Model/Series | J3: Color/ Finish | K3: Allowance Each | L3: Qty | M3: Allowance Total | N3: Critical Owner Decision
B4: ATH-01 | C4: Gym | D4: Wall padding / graphics | E4: 11 66 23 | F4: Jaypro / Safety Padding / Bison | G4: Pending | K4: 32000 | L4: 1 | M4: =K4*L4 -> 32000 | N4: Confirm padding extents, color, logos/graphics, stage pad scope.
B5: ATH-02 | C5: Gym | D5: Scoreboard / controls | E5: 11 66 23 | F5: Daktronics / Watchfire / Electro-Mech | G5: Pending | K5: 18000 | L5: 1 | M5: =K5*L5 -> 18000 | N5: Confirm display type, clock size, controller, optional shot clock package.
B6: ATH-03 | C6: Gym | D6: Telescoping bleachers | E6: 11 66 23 | F6: Jaypro / Irwin / Hussey | G6: Pending | K6: 95000 | L6: 1 | M6: =K6*L6 -> 95000 | N6: Confirm row count, rail configuration, ADA seating layout, finish.
B7: ATH-04 | C7: Gym | D7: Basketball backstop systems | E7: 11 66 23 | F7: Jaypro / Porter / Draper | G7: Pending | K7: 14500 | L7: 4 | M7: =K7*L7 -> 58000 | N7: Select exact model/series, extension length, mounting type.
B8: ATH-05 | C8: Gym | D8: Volleyball system | E8: 11 66 23 | F8: Jaypro / Porter / Draper | G8: Pending | K8: 3500 | L8: 1 | M8: =K8*L8 -> 3500 | N8: Select post/sleeve system and exact 7000-series configuration.
B9: ATH-06 | C9: Boxing | D9: Boxing ring and accessories | E9: 11 66 43 | F9: Title / Ringside / Everlast | G9: Pending | K9: 18000 | L9: 1 | M9: =K9*L9 -> 18000 | N9: Confirm ring size, ropes, corner pads, canvas, accessory package.
B10: BOX-ALW | C10: Boxing | D10: Bag systems / speed bag stations | E10: 11 66 43 | F10: Various | G10: Pending | K10: 14000 | L10: 1 | M10: =K10*L10 -> 14000 | N10: Confirm bag count, support frame type, bag style/weight, speed bag platform.
B11: FIN-04 | C11: Boxing | D11: Rubber athletic flooring | E11: 09 65 66 | F11: Mondo / Ecore / Gerflor | G11: Pending | K11: 14.5 | L11: 2500 | M11: =K11*L11 -> 36250 | N11: Confirm thickness (6/8/10mm), color, transition details, wall base color.
B13: TOTAL OWNER SELECTION ALLOWANCES | M13: =SUM(M4:M11) -> 274750
B14: Items Still Pending Owner Decision | M14: =COUNTIF(G4:G11,"Pending") -> 8

Sheet ALLOWANCE LOG
B1: ALLOWANCE LOG — Living Tracker for ALDi Gate Reporting
B2: Export this log monthly as part of ALDi gate reporting. Each row represents an open allowance that must be resolved before GMP. Status should be updated as owner decisions are confirmed.
B3: Allowance ID | C3: Spec Section | D3: Category | E3: Description | F3: Allowance Amount | G3: Basis / Reason | H3: Owner Decision Required? | I3: Status | J3: Notes / Next Action
B4: ALW-01 | C4: 11 66 23 | D4: Gym Equipment | E4: Basketball backstop systems | F4: 65000 | G4: Model TBD — Jaypro J800 family or equal | H4: Yes | I4: Pending | J4: Owner to confirm: model/series, extension length, mounting type. Due before DD.
B5: ALW-02 | C5: 11 66 23 | D5: Gym Equipment | E5: Telescoping bleacher system | F5: 95000 | G5: Layout and ADA seating TBD | H5: Yes | I5: Pending | J5: Owner to confirm: row count, ADA configuration, finish. Structural coordination required.
B6: ALW-03 | C6: 11 66 23 | D6: Gym Equipment | E6: Scoreboard / control system | F6: 18000 | G6: Manufacturer TBD | H6: Yes | I6: Pending | J6: Owner to confirm: display type, clock size, controller. Power/data coordination required.
B7: ALW-04 | C7: 11 66 23 | D7: Gym Equipment | E7: Wall padding and graphics | F7: 32000 | G7: Owner graphics and color scope TBD | H7: Yes | I7: Pending | J7: Owner to confirm: extents, color, logos, stage pad scope.
B8: ALW-05 | C8: 11 66 43 | D8: Boxing Equipment | E8: Boxing ring and accessories | F8: 18000 | G8: Model TBD — Title/Ringside/Everlast | H8: Yes | I8: Pending | J8: Owner to confirm: ring size (14x14 assumed), ropes, corner pads, canvas.
B9: ALW-06 | C9: 09 65 00 | D9: Athletic Flooring | E9: Rubber flooring — boxing gym | F9: 28000 | G9: Thickness and color TBD by owner | H9: Yes | I9: Pending | J9: Owner to confirm: thickness (6/8/10mm), color, wall base. Coordinate transitions.
B10: ALW-07 | C10: 22 11 00 | D10: MEP | E10: Plumbing modifications — pump room | F10: 15000 | G10: Scope pending MEP engineer review | H10: No | I10: Pending | J10: Pending MEP engineer opinion. Allowance covers minor modifications only.
B11: ALW-08 | C11: 26 05 00 | D11: MEP | E11: Electrical — scoreboard/equipment feeds | F11: 9000 | G11: Pending scoreboard/equipment selection | H11: Yes | I11: Pending | J11: Allowance pending owner equipment selections. Coordinate with ELC.
B13: TOTAL OPEN ALLOWANCES | F13: =SUM(F4:F11) -> 280000
B14: Items Pending Owner Decision | F14: =COUNTIF(I4:I11,"Pending") -> 8
B16: ALW-SGN-01 | C16: 10 14 00 | D16: Signage | E16: Room ID + Numbering System | F16: 10000 | G16: M4Di room schedule generated from SIGNAGE PROGRAM tab. 57 interior sign locations + hardware. | H16: Yes | I16: Pending | J16: See SIGNAGE PROGRAM tab for full room schedule and brand framework.
B17: ALW-SGN-02 | C17: 10 14 53 | D17: Signage | E17: Wayfinding + Directional System | F17: 38000 | G17: Campus orientation map, floor directories, corridor directionals. Exterior entry identification. | H17: Yes | I17: Pending | J17: See SIGNAGE PROGRAM tab for full room schedule and brand framework.
B18: ALW-SGN-03 | C18: 10 14 00 | D18: Signage | E18: Exterior + Campus Identity | F18: 18000 | G18: Building name sign, address numerals, accessible parking. NCC sign permit required. | H18: Yes | I18: Pending | J18: See SIGNAGE PROGRAM tab for full room schedule and brand framework.
B19: ALW-SGN-04 | C19: 10 14 00 | D19: Signage | E19: Donor / Community Identity (optional) | F19: 0 | G19: Budget TBD by owner. Recommend IDD-appropriate sensory-calm displays. $0 if not pursued. | H19: Yes | I19: Pending | J19: See SIGNAGE PROGRAM tab for full room schedule and brand framework.

Sheet CLARIFICATIONS
B1: CLARIFICATIONS / EXCLUSIONS / RISK LOG
B2: Include this sheet in all client deliverables. It defines the boundaries of the estimate and protects M4Di from scope disputes. Update at every estimate revision.
B3: Category | C3: Item | D3: Included / Excluded / Allowance | E3: Risk Level | F3: Comment / Mitigation
B4: General | C4: All quantities are conceptual and require field verification before GMP | D4: Included | E4: High | F4: Use as ROM only. Not a GMP or guaranteed maximum price.
B5: General | C5: Estimate based on scope narrative and program only — no drawings | D5: Included | E5: High | F5: Unit quantities are estimator's judgment. Field verify before DD.
B6: Equipment | C6: Athletic equipment model numbers and manufacturers | D6: Allowance | E6: High | F6: Owner selections pending. Allowances will be updated as selections are confirmed.
B7: Equipment | C7: Boxing equipment package | D7: Allowance | E7: High | F7: Basis of design still open. Owner to confirm model and accessory scope.
B8: MEP | C8: Power and data modifications for scoreboards and specialty equipment | D8: Allowance | E8: Medium | F8: Allowance included. Requires MEP engineer coordination and load calculations.
B9: MEP | C9: HVAC modifications or upgrades | D9: Excluded | E9: Medium | F9: Not in scope unless noted. Carry separate MEP budget if HVAC work is anticipated.
B10: MEP | C10: Plumbing — new fixtures or drainage | D10: Excluded | E10: Medium | F10: Minor modifications covered by allowance. Major new plumbing excluded.
B11: Existing Conditions | C11: Concealed corrosion or substrate damage beyond scope assumptions | D11: Excluded | E11: High | F11: Carry contingency or unit rates for concealed conditions. Field verification recommended.
B12: Existing Conditions | C12: Hazardous material abatement (asbestos, lead paint) | D12: Excluded | E12: High | F12: Requires testing and licensed abatement contractor. Separate budget required.
B13: Existing Conditions | C13: Structural deficiencies identified during construction | D13: Excluded | E13: High | F13: Not in scope. Structural engineer review recommended before estimate finalization.
B14: Schedule | C14: Cost escalation beyond current estimate date | D14: Excluded | E14: Medium | F14: Adjust ENR escalation factor in ASSUMPTIONS for revised bid dates.
... B21: Accessibility | C21: ADA path of travel upgrades beyond specified scope | D21: Excluded | E21: Medium | F21: ADA items within designated scope are included. Full-building accessibility audit not in scope.
B23: → ADD PROJECT-SPECIFIC CLARIFICATIONS ABOVE. Always include this sheet in client deliverable packages.

Sheet SOFT COSTS
B1: SOFT COSTS — Professional Fees & Pre-Construction Budget
B2: Soft costs are calculated as a percentage of the Total Hard Cost ROM (from BID SUMMARY). Architecture fee uses the M4Di Base Fee Schedule (AIA-aligned). Engineering and specialty fees use benchmark percentages adjustable per project. All rates are user-overridable.
B4: A — PROJECT BASIS (from ASSUMPTIONS & BID SUMMARY)
B5: Total Hard Cost ROM | C5: ='BID SUMMARY'!C12 -> 8797915.6 | D5: Pulled from BID SUMMARY. This is the construction cost base for all fee calculations.
B6: Project Type (for fee schedule) | C6: =ASSUMPTIONS!C6 -> Adaptive Reuse | D6: Auto-pulled from ASSUMPTIONS. Drives fee type classification below.
B7: Estimate Phase | C7: =ASSUMPTIONS!C5 -> ROM / Conceptual | D7: ROM / Conceptual | Schematic | Design Development | GMP
B8: Gross Area (SF) | C8: =ASSUMPTIONS!C9 -> 27452 | D8: From ASSUMPTIONS. Used for cost/SF benchmarking.
B10: B — ARCHITECTURE FEE (M4Di Base Fee Schedule)
B11: Fee lookup uses the M4Di Base Fee Schedule. Select the Project Type Code (A–E) based on complexity. For renovation/adaptive reuse, apply the renovation premium. New Construction = base rate only. Renovation = base + premium.
B13: FEE SCHEDULE REFERENCE TABLE — Base % of Construction Cost
B14: Construction Budget Range | D14: Type A | E14: Type B | F14: Type C | G14: Type D | H14: Type E
B15: Up to – $49,999 | D15: 0.089 | E15: 0.099 | F15: 0.109 | G15: 0.117 | H15: 0.12
B16: $50,000 – $99,999 | D16: 0.084 | E16: 0.094 | F16: 0.107 | G16: 0.111 | H16: 0.119
B17: $100,000 – $149,999 | D17: 0.081 | E17: 0.091 | F17: 0.104 | G17: 0.109 | H17: 0.115
B18: $150,000 – $199,999 | D18: 0.079 | E18: 0.089 | F18: 0.101 | G18: 0.105 | H18: 0.112
B19: $200,000 – $299,999 | D19: 0.074 | E19: 0.084 | F19: 0.099 | G19: 0.103 | H19: 0.11
B20: $300,000 – $499,999 | D20: 0.072 | E20: 0.082 | F20: 0.094 | G20: 0.1 | H20: 0.107
B21: $500,000 – $749,999 | D21: 0.069 | E21: 0.079 | F21: 0.091 | G21: 0.097 | H21: 0.104
B22: $750,000 – $999,999 | D22: 0.067 | E22: 0.077 | F22: 0.089 | G22: 0.094 | H22: 0.101
B23: $1,000,000 – $1,499,999 | D23: 0.064 | E23: 0.074 | F23: 0.084 | G23: 0.091 | H23: 0.098
B24: $1,500,000 – $1,999,999 | D24: 0.062 | E24: 0.072 | F24: 0.082 | G24: 0.088 | H24: 0.095
B25: $2,000,000 – $2,999,999 | D25: 0.059 | E25: 0.069 | F25: 0.079 | G25: 0.085 | H25: 0.092
B26: $3,000,000 – $3,999,999 | D26: 0.057 | E26: 0.067 | F26: 0.077 | G26: 0.083 | H26: 0.09
... B33: Renovation premium (add to above) | D33: 0.005 | E33: 0.0065 | F33: 0.0075 | G33: 0.0085 | H33: 0.01
B35: PROJECT TYPE CLASSIFICATION — Select the code that matches your facility
B36: Type A | C36: Warehouse, Public Garage, Residential (standard)
B37: Type B | C37: Office, Parking Facility, Retail, Visitor Center, Maintenance Garage, Tenant Fit-out
B38: Type C | C38: School, Training Facility, Day Care, Fitness Center, Mixed-Use, Adult Care, Laundry
B39: Type D | C39: Library, Restaurant, Theater (no stage), Outpatient Clinic, Detention, Courthouse, Data Center
B40: Type E | C40: Hospital, Research, Museum, Stadium, Prison, Emergency Ops, Theater/Auditorium with stage
B41: M4Di Default — Community Facility Renovation | C41: Use Type C (Fitness Center / Mixed-Use) for church/community renovation. Use Type D for clinic or complex adaptive reuse.
B44: C — FEE INPUTS & CALCULATIONS (enter yellow cells; formulas auto-populate)
B45: Discipline / Fee Item | C45: % of Hard Cost (enter or auto) | D45: Calculated Fee ($) | E45: User Override ($ if fixed) | F45: Fee Used (calc or override) | G45: Included in Budget? | H45: Notes / Assumptions
B46: PROJECT TYPE CODE & RENOVATION SELECTION (user inputs)
B47: AIA Project Type Code (A / B / C / D / E) | C47: C | D47: Type A=warehouse/parking, B=office/retail, C=school/fitness/mixed-use (M4Di default), D=clinic/library/theater, E=hospital/research. See guide above.
B48: Renovation / Adaptive Reuse? (Yes / No) | C48: Yes | D48: Yes: adds renovation premium to base Arch fee per fee schedule. WHACC = Yes (interior improvement + adaptive reuse elements).
B50: ARCHITECTURE & ENGINEERING FEES
B51: Discipline / Fee Item | C51: % of Hard Cost | D51: Calculated Fee ($) | E51: User Override ($) leave blank = use calc | F51: Fee Used | G51: Include? | H51: Notes / Source
