Workbook

Sheet Budget
A1: M4Di — Merge 4 Development Institute
A2: Wells Fargo / Enterprise Housing Affordability Breakthrough Challenge — 2026 Cycle
A3: BUDGET — Finance Category | Lead Applicant: Central Baptist CDC | Grant Period: 24 Months | Total Request: $2,000,000
A5: Budget Line Item | B5: Description / Justification | C5: Qty | D5: Unit | E5: Year 1 ($) | F5: Year 2 ($) | G5: Total ($)
A6: A PERSONNEL & CONTRACTOR SERVICES
A7: Personnel costs reflect the proportional FTE time of M4Di principals and a program associate dedicated to grant-funded activities. All rates are commensurate with nonprofit Mid-Atlantic professional compensation standards.
A8: David Ainsworth, AIA — Predevelopment Lead | B8: 0.5 FTE. Methodology leadership, OI Tool build direction, client engagement, grant reporting. | C8: 0.5 | D8: FTE/yr | E8: 62500 | F8: 65000 | G8: =E8+F8 -> 127500
A9: Travis Davis — Platform Operator / GMD | B9: 0.4 FTE. Web app build coordination, platform operation, visualization, M4Di Terminal. | C9: 0.4 | D9: FTE/yr | E9: 50000 | F9: 52000 | G9: =E9+F9 -> 102000
A10: Leo Lynch — Operations & Grant Compliance | B10: 0.3 FTE. Grant reporting, financial management, CDFI partner development. | C10: 0.3 | D10: FTE/yr | E10: 37500 | F10: 39000 | G10: =E10+F10 -> 76500
A11: Trevor Knight — Strategy & Business Development | B11: 0.2 FTE. CDFI relationships, funder outreach, Academy partner development. | C11: 0.2 | D11: FTE/yr | E11: 25000 | F11: 26000 | G11: =E11+F11 -> 51000
A12: Program Associate (new hire, Year 2) | B12: 0.8 FTE, Year 2 only. Client engagement support, ALDDB data entry, Academy coordination. | C12: 0 | D12: FTE/yr | E12: 0 | F12: 48000 | G12: =E12+F12 -> 48000
A13: Contracted Developer — Web App Build | B13: Part-time contractor. Auth, Supabase database, deployment pipeline, security audit. ~140 hrs @ $100/hr. | C13: 140 | D13: hrs | E13: 14000 | F13: 0 | G13: =E13+F13 -> 14000
A14: CB CDC Administrative Fee (8%) | B14: Fiscal sponsor oversight, financial controls, compliance, grant administration. | C14: 1 | D14: lump sum | E14: 80000 | F14: 80000 | G14: =E14+F14 -> 160000
A15: A PERSONNEL SUBTOTAL | D15: =SUM(E8:E14) -> 269000 | E15: =SUM(F8:F14) -> 310000 | F15: =D15+E15 -> 579000
A16: B TECHNOLOGY & INFRASTRUCTURE
A17: Cloud Hosting — Vercel + Supabase (Production) | B17: Frontend (Vercel Pro) + database (Supabase Pro). Supports 10–20 users, multi-project storage. | C17: 1 | D17: yr | E17: 1800 | F17: 1800 | G17: =E17+F17 -> 3600
A18: Anthropic Claude API — Build Phase + AI Advisor | B18: Code generation during build phase + ongoing AI Advisor feature for scope narrative generation. | C18: 1 | D18: yr | E18: 1200 | F18: 1200 | G18: =E18+F18 -> 2400
A19: Regrid API — Parcel Data Integration | B19: Address-driven parcel/zoning auto-population for ZONING & CODE ANALYSIS tab. Nonprofit pricing. | C19: 1 | D19: yr | E19: 1800 | F19: 1800 | G19: =E19+F19 -> 3600
A20: Security & Code Audit (one-time) | B20: Third-party security review before client access. Required before external user access granted. | C20: 1 | D20: lump sum | E20: 3000 | F20: 0 | G20: =E20+F20 -> 3000
A21: BLS / ENR Data Subscriptions | B21: Regional labor cost data (BLS OEWS) and construction cost index (ENR) for OI Tool regional factors. | C21: 1 | D21: yr | E21: 500 | F21: 500 | G21: =E21+F21 -> 1000
A22: Software Licenses & Tools | B22: Revit 2026, Microsoft 365, GitHub org, design tools. Allocated portion for M4Di program use. | C22: 1 | D22: yr | E22: 3000 | F22: 3000 | G22: =E22+F22 -> 6000
A23: B TECHNOLOGY SUBTOTAL | D23: =SUM(E17:E22) -> 11300 | E23: =SUM(F17:F22) -> 8300 | F23: =D23+E23 -> 19600
A24: C M4Di ACADEMY — CURRICULUM & PROGRAM
A25: Academy Curriculum Development — Phase 1 | B25: FeasOps™ P1–P3 curriculum, 6-module course build, contractor cost literacy track. Writer + instructional design. | C25: 1 | D25: lump sum | E25: 45000 | F25: 0 | G25: =E25+F25 -> 45000
A26: Academy Curriculum Development — Phase 2 | B26: Advanced modules: CLT/SIP cost methodology, CDFI funder budget formats, ALDi gate controls. | C26: 1 | D26: lump sum | E26: 0 | F26: 54000 | G26: =E26+F26 -> 54000
A27: Cohort Delivery — Year 1 Pilot (15 participants) | B27: First cohort facilitation, materials, participant support. LEEP x M4Di Academy co-delivery. | C27: 1 | D27: cohort | E27: 12000 | F27: 0 | G27: =E27+F27 -> 12000
A28: Cohort Delivery — Year 2 (2 cohorts, 15 avg.) | B28: Two cohorts at full delivery cost. Participant fee offset reduces net grant spend. | C28: 1 | D28: cohort | E28: 0 | F28: 18000 | G28: =E28+F28 -> 18000
A29: Academy Platform & LMS Setup | B29: Learning management system setup, course hosting, participant portal. One-time Year 1 build. | C29: 1 | D29: lump sum | E29: 8000 | F29: 0 | G29: =E29+F29 -> 8000
A30: Nonprofit Development Kit — Content Build | B30: Subscriber-ready digital toolkit: templates, guides, benchmark summaries. Year 2 launch. | C30: 1 | D30: lump sum | E30: 0 | F30: 12000 | G30: =E30+F30 -> 12000
A31: C ACADEMY SUBTOTAL | D31: =SUM(E25:E30) -> 65000 | E31: =SUM(F25:F30) -> 84000 | F31: =D31+E31 -> 149000
A32: D ALDDB HISTORICAL COST DATABASE
A33: ALDDB Cloud Database Architecture | B33: Supabase schema design, data migration from Excel, API endpoints for OI Tool integration. | C33: 1 | D33: lump sum | E33: 8000 | F33: 0 | G33: =E33+F33 -> 8000
A34: Data Entry & Validation (closed projects) | B34: Entry and QA of historical project cost records into ALDDB. Target: 10+ records Year 1. | C34: 20 | D34: hrs | E34: 2000 | F34: 2000 | G34: =E34+F34 -> 4000
A35: Annual Mid-Atlantic Cost Benchmark Report — Year 2 | B35: Design, data analysis, and publishing of first public benchmark report. Travis leads production. | C35: 1 | D35: report | E35: 0 | F35: 15000 | G35: =E35+F35 -> 15000
A36: CDFI Partner Data Sharing Agreements | B36: Legal review and execution of data sharing agreements with CDFI pilot subscribers. | C36: 2 | D36: agreements | E36: 3000 | F36: 3000 | G36: =E36+F36 -> 6000
A37: D ALDDB SUBTOTAL | D37: =SUM(E33:E36) -> 13000 | E37: =SUM(F33:F36) -> 20000 | F37: =D37+E37 -> 33000
A38: E CLT/SIP MANUFACTURING MARKET STUDY SEED
A39: Market Study — Demand Analysis Phase | B39: Regional CLT/SIP demand quantification. Mid-Atlantic project pipeline, cost modeling, supply chain gap analysis. | C39: 1 | D39: lump sum | E39: 35000 | F39: 0 | G39: =E39+F39 -> 35000
A40: Market Study — Site & Pro Forma Phase | B40: I-95 corridor site identification, manufacturing facility pro forma, capital stack modeling. | C40: 1 | D40: lump sum | E40: 0 | F40: 75000 | G40: =E40+F40 -> 75000
A41: University Research Partnership Setup | B41: MOU with U of Delaware or Delaware State. Federal grant co-PI pathway development. | C41: 1 | D41: lump sum | E41: 5000 | F41: 5000 | G41: =E41+F41 -> 10000
...

Sheet Sources and Uses
A1: M4Di — SOURCES AND USES TABLE
A2: Wells Fargo / Enterprise Housing Affordability Breakthrough Challenge | Grant Period: 24 Months
A3: Source / Use Category | B3: Year 1 | C3: Year 2 | D3: Total
A4: SOURCES
A5: Wells Fargo / Enterprise Grant | B5: 1000000 | C5: 1000000 | D5: =B5+C5 -> 2000000
A6: M4Di Principal In-Kind (estimated soft match) | B6: 120000 | C6: 130000 | D6: =B6+C6 -> 250000
A7: CB CDC In-Kind Oversight | B7: 20000 | C7: 20000 | D7: =B7+C7 -> 40000
A8: Earned Revenue (FeasOps, ALDi retainers — not grant-funded) | B8: 259000 | C8: 340000 | D8: =B8+C8 -> 599000
A9: TOTAL SOURCES | B9: =SUM(B5:B8) -> 1399000 | C9: =SUM(C5:C8) -> 1490000 | D9: =B9+C9 -> 2889000
A11: USES (from Budget tab)
A12: A — Personnel & Contractor Services | B12: =Budget!E15 -> 310000 | C12: =Budget!F15 -> 579000 | D12: =B12+C12 -> 889000
A13: B — Technology & Infrastructure | B13: =Budget!E23 -> 8300 | C13: =Budget!F23 -> 19600 | D13: =B13+C13 -> 27900
A14: C — M4Di Academy | B14: =Budget!E31 -> 84000 | C14: =Budget!F31 -> 149000 | D14: =B14+C14 -> 233000
A15: D — ALDDB Historical Cost Database | B15: =Budget!E37 -> 20000 | C15: =Budget!F37 -> 33000 | D15: =B15+C15 -> 53000
A16: E — CLT/SIP Manufacturing Study Seed | B16: =Budget!E45 -> 100000 | C16: =Budget!F45 -> 155000 | D16: =B16+C16 -> 255000
A17: F — Outreach & Partnerships | B17: =Budget!E52 -> 32000 | C17: =Budget!F52 -> 66000 | D17: =B17+C17 -> 98000
A18: G — Contingency (5%) | B18: =Budget!E55 -> 50000 | C18: =Budget!F55 -> 100000 | D18: =B18+C18 -> 150000
A19: TOTAL USES | B19: =SUM(B12:B18) -> 604300 | C19: =SUM(C12:C18) -> 1101600 | D19: =B19+C19 -> 1705900
A21: GRANT FUNDS BALANCE CHECK (Sources - Uses should = $0) | D21: =D9-D19 -> 1183100
