Workbook

Sheet Overview
B1: M4Di FORWARD HOME ROM — FOUR-TIER COST INTELLIGENCE SUMMARY
B2: G0 ROM ±25% · 10-unit Type D lot cluster · 1,350 SF/unit · Merge 4 Design LLC × L.E.E.P., Inc. · May 2026
B3: Cost element | C3: T1 — Code+ | D3: T2 — Zero | E3: T3 — Positive | F3: T4 — Harvest
B4: HARD COSTS PER UNIT | C4: — | D4: — | E4: — | F4: —
B5: 4Ward-SIB Forward Panel | C5: 41999 | D5: 41999 | E5: 41999 | F5: 41999
B6: Foundation / structural | C6: 27999 | D6: 29999 | E6: 29999 | F6: 29999
B7: MEP systems — base | C7: 18994 | D7: 21006 | E7: 22005 | F7: 22005
B8: Finishes / millwork / appliances | C8: 23004 | D8: 23004 | E8: 23004 | F8: 23004
B9: Tier-specific upgrades (net) | C9: 0 | D9: 47750 | E9: 54100 | F9: 76300
B10: HARD COST SUBTOTAL | C10: 111996 | D10: 163758 | E10: 171107 | F10: 193307
B11: SOFT COSTS PER UNIT | C11: — | D11: — | E11: — | F11: —
B12: A&E architectural fee | C12: 5500 | D12: 5500 | E12: 5500 | F12: 5500
B13: MEP PE fee (first typology) | C13: 3200 | D13: 3200 | E13: 3200 | F13: 3200
B14: Permits + M4Di OI Tool | C14: 3000 | D14: 3000 | E14: 3000 | F14: 3000
B15: Certification / rater fees | C15: 0 | D15: 2000 | E15: 4250 | F15: 7500
B16: Tier-specific MEP PE premium | C16: 0 | D16: 0 | E16: 3200 | F16: 3200
B17: SOFT COST SUBTOTAL | C17: 11700 | D17: 13700 | E17: 19150 | F17: 22400
B18: Contingency (8%) | C18: 9896 | D18: 14196 | E18: 15220 | F18: 17352
B19: Loan carry (31 wks) | C19: 6531 | D19: 7819 | E19: 8374 | F19: 9530
B20: TOTAL BUILD COST / UNIT | C20: 140123 | D20: 199473 | E20: 213851 | F20: 242589
B21: Sale price / unit | C21: 235000 | D21: 250000 | E21: 265000 | F21: 290000
B22: IRA §45L developer credit | C22: 0 | D22: 5000 | E22: 5000 | F22: 5000
B23: NET DEVELOPER MARGIN / UNIT | C23: 94877 | D23: 55527 | E23: 56149 | F23: 52411
B24: Developer margin % | C24: 40.4% | D24: 22.2% | E24: 21.2% | F24: 18.1%
B26: UNIT COUNT | C26: 10 | D26: 10 | E26: 10 | F26: 10
B27: TOTAL BUILD COST (all units) | C27: 1401230 | D27: 1994730 | E27: 2138510 | F27: 2425890
B28: GROSS REVENUE (all units) | C28: 2350000 | D28: 2500000 | E28: 2650000 | F28: 2900000
B29: NET MARGIN (all units) | C29: 948770 | D29: 555270 | E29: 561490 | F29: 524110
B30: HERS index target | C30: 55–70 | D30: 0–30 | E30: Neg to +10 | F30: Net positive
B31: Blower door ACH50 | C31: < 2.0 (auto) | D31: < 1.0 | E31: < 0.6 | F31: < 0.6
B32: Certification path | C32: Energy Star auto | D32: DOE ZERH | E32: PHIUS+ | F32: Off-grid verified
B34: NOTE: All values G0 ROM ±25%. Soft costs per CBai MEP SOP v1. Override margin % reflects IRA §45L credit offset (T2–T4). Navigate tabs below for full line-item ROM by tier. Update Assumptions tab to recalculate all tiers.
B36: WORKBOOK NAVIGATION
B37: Overview | C37: This sheet — four-tier ROM summary
B38: Assumptions | C38: Shared inputs — change here to update all tiers
B39: T1 — Code+ | C39: Tier 1 full ROM: hard + soft + contingency + carry + return
B40: T2 — Zero | C40: Tier 2 full ROM: adds Quilt, SPAN, PV, battery, LiveRoof Std
B41: T3 — Positive | C41: Tier 3 full ROM: adds Mitsubishi FX, PV 8.5kW, LiveRoof MAXX + edible
B42: T4 — Harvest | C42: Tier 4 full ROM: off-grid battery, agrivoltaic PV, Crop Circle Farms

Sheet Assumptions
B1: SHARED ASSUMPTIONS — M4Di FORWARD HOME ROM
B2: Blue/yellow cells = inputs. Change here — all tier ROM tabs update automatically.
B4: HARD COST RATES (per SF of gross floor area — blended installed)
B5: 4Ward-SIB Forward Panel — all tiers (per SF) | C5: 31.11 | D5: Blended installed: $42K/unit @ 1,350 SF · M4Di ALDDB / Barricade SIB ROM May 2026
B6: Foundation — T1 standard CMU / poured (per SF) | C6: 20.74 | D6: Blended installed: $28K/unit @ 1,350 SF · M4Di ROM Claymont AE24-002
B7: Foundation — T2–T4 Superior Walls Xi Plus (per SF) | C7: 22.22 | D7: Blended installed: $30K/unit @ 1,350 SF · TER 2211-02 premium over CMU
B8: MEP — T1 standard heat pump (per SF) | C8: 14.07 | D8: Blended installed: $19K/unit @ 1,350 SF · cold-climate mini-split SEER2 ≥18
B9: MEP — T2 Quilt 3-zone + Vitoair ERV base (per SF) | C9: 15.56 | D9: Blended installed: $21K/unit · SEER2 25.3 / HSPF2 12 · ERV budgeted separately
B10: MEP — T3–T4 Mitsubishi FX H2i sumo (per SF) | C10: 16.3 | D10: Blended installed: $22K/unit · SEER2 29.9 · 10-yr warranty
B11: Finishes / millwork / appliances — all tiers (per SF) | C11: 17.04 | D11: Blended installed: $23K/unit @ 1,350 SF · mid-range Forward Home spec
B13: SOFT COST SUB-COMPONENTS (per unit — all tiers base)
B14: Typology toggle (1 = First · 2 = Repeat / Claymont template) | C14: 1 | D14: Toggle affects MEP PE fee only · 2 = 40–50% compression per CBai MEP SOP v1
B15: A&E architectural fee (per unit) | C15: 5500 | D15: AOR + schematic + permit drawings · fixed regardless of typology
B16: MEP PE fee — first typology (per unit, G0–G3) | C16: 3200 | D16: CBai-assisted target · M4Di CBai MEP Workflow SOP v1 Table 2
B17: MEP PE fee — repeat / Claymont template (per unit) | C17: 1800 | D17: 40–50% of full-service · available Q4 2026 after Claymont G4 archive
B18: Permits / filing / AHJ fees (per unit) | C18: 1800 | D18: City of Wilmington residential permit · fixed
B19: M4Di OI Tool / ALDi Tracker (per unit) | C19: 1200 | D19: G0 ROM + ALDi gate tracking G1–G4 · OED cost-verification standard
B20: SOFT COSTS / UNIT (base, active typology) | C20: =C15+IF(C14=1,C16,C17)+C18+C19 -> 11700 | D20: Active total · First: ~$11,700 · Repeat: ~$10,300
B22: FINANCING
B23: Construction loan rate (annual) | C23: 0.1025 | D23: Delaware construction market May 2026 · New Silver / PRMI
B24: Build schedule — weeks (4Ward-SIB Forward Panel) | C24: 31 | D24: vs. 35 wks std SIP · 39 wks stick frame · Offsite Builder 2025
B25: Loan-to-cost ratio (LTC) | C25: 0.8 | D25: Typical residential construction LTC
B27: REVENUE & RENTAL
B28: T1 avg. sale price / unit | C28: 235000 | D28: City target $220K–$250K · Type D cluster higher end
B29: T2 avg. sale price / unit | C29: 250000
B30: T3 avg. sale price / unit | C30: 265000
B31: T4 avg. sale price / unit | C31: 290000
B32: Monthly rent / unit (all tiers) | C32: 1550 | D32: Wilmington forward housing market · affordable range
B33: Stabilized expense ratio | C33: 0.45 | D33: NOI = 55%
B34: Cap rate (valuation) | C34: 0.062 | D34: Delaware multifamily Q1 2026 estimate
B36: CITY PROGRAM
B37: Land cost per lot (City program) | C37: 1 | D37: City of Wilmington vacant lot initiative
B38: Site work / utilities (City-funded) | C38: 0 | D38: Developer cost = $0 · City-covered in program
B41: COLOR CODE: Blue = hardcoded input · Yellow = key assumption · Green = formula cross-reference · Typology toggle C10 (1=First / 2=Repeat Claymont)

Sheet T1 — Code+
B1: TIER 1 — FORWARD CODE+ | FORWARD HOME ROM
B2: G0 ROM ±25% · HERS 55–70 · ACH50 < 2.0 (auto) · Cert: Energy Star (auto) · Land: $1 (City program) · Site/utilities: City-funded
B3: Line item | C3: Input | D3: Per unit | E3: Total (10 units) | F3: Source / note
B4: PROJECT INPUTS
B5: Number of units | C5: 10 | D5: =C5 -> 10 | F5: Investor equity activated at site control (LOI)
B6: Avg. unit size (SF) | C6: 1350 | D6: =C6 -> 1350 | E6: =D6*C5 -> 13500
B7: Sale price / unit (from Assumptions) | C7: =Assumptions!C35 -> 0 | D7: =Assumptions!C35 -> 0 | E7: =D7*C5 -> 0
B9: SOURCES
B10: Investor equity (site control triggered) | C10: 500000 | D10: =C10/C5 -> 50000 | E10: =C10 -> 500000 | F10: Deployed at LOI · covers 20% LTC gap + pre-construction soft costs
B11: Construction loan (80% LTC × total cost) | C11: (calculated) | D11: =D32*Assumptions!C32 -> 7.9099419e+23 | E11: =D11*C5 -> 7.9099419e+24
B12: City land ($1 × 10 lots) + site/utilities | C12: City-funded | D12: City-funded | E12: City-funded
B14: HARD COSTS
B15: 4Ward-SIB Forward Panel system (SF × rate) | C15: =Assumptions!C5 -> 31.11 | D15: =C6*Assumptions!C5 -> 41998.5 | E15: =D15*C5 -> 419985 | F15: TER 1507-09 · Barricade INDEVCO · all tiers
B16: Foundation / structural (SF × rate) | C16: =Assumptions!C6 -> 20.74 | D16: =C6*Assumptions!C6 -> 27999 | E16: =D16*C5 -> 279990 | F16: CMU (T1) · Superior Walls Xi Plus TER 2211-02 (T2–T4)
B17: MEP systems — base HVAC + plumbing + elec. (SF × rate) | C17: =Assumptions!C8 -> 14.07 | D17: =C6*Assumptions!C8 -> 18994.5 | E17: =D17*C5 -> 189945 | F17: T1: std mini-split · T2: Quilt 3-zone · T3–T4: Mitsubishi FX H2i sumo
B18: Finishes / millwork / appliances (SF × rate) | C18: =Assumptions!C11 -> 17.04 | D18: =C6*Assumptions!C11 -> 23004 | E18: =D18*C5 -> 230040 | F18: Mid-range Forward Home spec · all tiers
B19: HARD COST SUBTOTAL (all installed costs) | D19: =SUM(D15:D18) -> 111996 | E19: =SUM(E15:E18) -> 1119960
B21: SOFT COSTS
B22: A&E architectural fee | C22: =Assumptions!C15 -> 5500 | D22: =Assumptions!C15 -> 5500 | E22: =D22*C5 -> 55000 | F22: AOR + permit drawings · fixed all tiers
B23: MEP PE fee (CBai-assisted, active typology) | C23: =IF(Assumptions!C14=1,Assumptions!C16,Assumptions!C17) -> 3200 | D23: =IF(Assumptions!C14=1,Assumptions!C16,Assumptions!C17) -> 3200 | E23: =D23*C5 -> 32000 | F23: First: $3,200 · Repeat/Claymont: $1,800 · CBai MEP SOP v1
B24: Permits / filing / AHJ fees | C24: =Assumptions!C18 -> 1800 | D24: =Assumptions!C18 -> 1800 | E24: =D24*C5 -> 18000 | F24: City of Wilmington residential permit
B25: M4Di OI Tool / ALDi Tracker | C25: =Assumptions!C19 -> 1200 | D25: =Assumptions!C19 -> 1200 | E25: =D25*C5 -> 12000 | F25: G0 ROM + ALDi gate G1–G4 · OED cost-verification standard
B26: SOFT COST SUBTOTAL | D26: =SUM(D21:D25) -> 11700 | E26: =SUM(E21:E25) -> 117000
B28: CONTINGENCY + LOAN CARRY
B29: Contingency (8% of hard + soft) | C29: =Assumptions!C18 -> 1800 | D29: =(D19+D26)*Assumptions!C18 -> 222652800 | E29: =D29*C5 -> 2226528000 | F29: 8% of combined hard + soft · per M4Di ALDi standard
B30: Loan carry (31 wks @ 10.25% · 80% LTC) | D30: =(D19+D26+D29)*(Assumptions!C30/52)*Assumptions!C32*Assumptions!C31 -> 5.1031883e+20 | E30: =D30*C5 -> 5.1031883e+21 | F30: Rate from Assumptions · 31-week schedule · 80% LTC
B32: TOTAL PROJECT COST | D32: =D19+D26+D29+D30 -> 5.1031883e+20 | E32: =E19+E26+E29+E30 -> 5.1031883e+21
B34: FOR-SALE RETURN ANALYSIS
B35: Gross sale revenue | D35: =Assumptions!C35 -> 0 | E35: =D35*C5 -> 0 | F35: Assumptions C35 · City target range
B36: Less: total project cost | D36: =D32 -> 5.1031883e+20 | E36: =E32 -> 5.1031883e+21 | F36: From TOTAL PROJECT COST row above
B37: DEVELOPER NET MARGIN | D37: =D35-D32 -> -5.1031883e+20 | E37: =E35-E32 -> -5.1031883e+21
B38: Developer margin % | D38: =D37/D35 -> #DIV/0! | E38: =E37/E35 -> #DIV/0!
B40: RENTAL ALTERNATIVE (hold scenario)
B41: Monthly rent / unit | D41: =Assumptions!C39 -> 0 | E41: =D41*C5 -> 0 | F41: From Assumptions · all tiers
B42: Gross annual income | D42: =D41*12 -> 0 | E42: =E41*12 -> 0
B43: Net operating income (55%) | D43: =D41*(1-Assumptions!C40) -> 0 | E43: =E41*(1-Assumptions!C40) -> 0 | F43: NOI = 55% of gross
B44: Stabilized cap rate | D44: =Assumptions!C41 -> 0 | F44: 6.2% Delaware multifamily Q1 2026
B45: Stabilized asset value (NOI ÷ cap rate) | D45: =D41/Assumptions!C41 -> #DIV/0! | E45: =E41/Assumptions!C41 -> #DIV/0!
B47: G0 ROM ±25% · All rates blended installed per floor SF · Soft costs disaggregated per CBai MEP Workflow SOP v1 · Update Assumptions!C10 to toggle first vs. repeat typology MEP PE fee · Land = $1/lot (City program) · Site work + utilities City-funded

Sheet T2 — Zero
B1: TIER 2 — FORWARD ZERO | FORWARD HOME ROM
B2: G0 ROM ±25% · HERS 0–30 · ACH50 < 1.0 · Cert: DOE Zero Energy Ready Home · Land: $1 (City program) · Site/utilities: City-funded
B3: Line item | C3: Input | D3: Per unit | E3: Total (10 units) | F3: Source / note
B4: PROJECT INPUTS
B5: Number of units | C5: 10 | D5: =C5 -> 10 | F5: Investor equity activated at site control (LOI)
B6: Avg. unit size (SF) | C6: 1350 | D6: =C6 -> 1350 | E6: =D6*C5 -> 13500
B7: Sale price / unit (from Assumptions) | C7: =Assumptions!C36 -> 0 | D7: =Assumptions!C36 -> 0 | E7: =D7*C5 -> 0
B9: SOURCES
B10: Investor equity (site control triggered) | C10: 500000 | D10: =C10/C5 -> 50000 | E10: =C10 -> 500000 | F10: Deployed at LOI · covers 20% LTC gap + pre-construction soft costs
B11: Construction loan (80% LTC × total cost) | C11: (calculated) | D11: =D41*Assumptions!C32 -> 1.1270945e+24 | E11: =D11*C5 -> 1.1270945e+25
B12: City land ($1 × 10 lots) + site/utilities | C12: City-funded | D12: City-funded | E12: City-funded
B14: HARD COSTS
B15: 4Ward-SIB Forward Panel system (SF × rate) | C15: =Assumptions!C5 -> 31.11 | D15: =C6*Assumptions!C5 -> 41998.5 | E15: =D15*C5 -> 419985 | F15: TER 1507-09 · Barricade INDEVCO · all tiers
B16: Foundation / structural (SF × rate) | C16: =Assumptions!C7 -> 22.22 | D16: =C6*Assumptions!C7 -> 29997 | E16: =D16*C5 -> 299970 | F16: CMU (T1) · Superior Walls Xi Plus TER 2211-02 (T2–T4)
B17: MEP systems — base HVAC + plumbing + elec. (SF × rate) | C17: =Assumptions!C9 -> 15.56 | D17: =C6*Assumptions!C9 -> 21006 | E17: =D17*C5 -> 210060 | F17: T1: std mini-split · T2: Quilt 3-zone · T3–T4: Mitsubishi FX H2i sumo
B18: Finishes / millwork / appliances (SF × rate) | C18: =Assumptions!C11 -> 17.04 | D18: =C6*Assumptions!C11 -> 23004 | E18: =D18*C5 -> 230040 | F18: Mid-range Forward Home spec · all tiers
B19: TIER-SPECIFIC HARD COST UPGRADES
B20: Window upgrade — Magnus 4500 triple-pane / krypton | C20: 3000 | D20: =C20 -> 3000 | E20: =C20*C5 -> 30000 | F20: U ≤ 0.18 · SHGC tuned by orientation
B21: SPAN MAIN 40 smart panel | C21: 4000 | D21: =C21 -> 4000 | E21: =C21*C5 -> 40000 | F21: First UL 3141 certified · Eaton-backed
B22: PV system — 5.5 kW Enphase IQ8 microinverters | C22: 17250 | D22: =C22 -> 17250 | E22: =C22*C5 -> 172500 | F22: Mid of $15K–$19.5K range
B23: Battery — Enphase IQ Battery 5P or Tesla Powerwall 3 | C23: 11500 | D23: =C23 -> 11500 | E23: =C23*C5 -> 115000 | F23: 13.5–20 kWh · 15-yr warranty
B24: LiveRoof® Standard — 700 SF roof | C24: 7350 | D24: =C24 -> 7350 | E24: =C24*C5 -> 73500 | F24: 4.25" soil · FM 4477 · ASTM E108 Class A
B25: Viessmann Vitoair ERV | C25: 2700 | D25: =C25 -> 2700 | E25: =C25*C5 -> 27000 | F25: 85% SRE · MERV 13 · CO₂-responsive
B26: Drainwater heat recovery | C26: 750 | D26: =C26 -> 750 | E26: =C26*C5 -> 7500 | F26: Shower stack recovery · all T2–T4
B27: HARD COST SUBTOTAL (all installed costs) | D27: =SUM(D15:D18)+SUM(D20:D26) -> 162555.5 | E27: =SUM(E15:E18)+SUM(E20:E26) -> 1625555
B29: SOFT COSTS
B30: A&E architectural fee | C30: =Assumptions!C15 -> 5500 | D30: =Assumptions!C15 -> 5500 | E30: =D30*C5 -> 55000 | F30: AOR + permit drawings · fixed all tiers
B31: MEP PE fee (CBai-assisted, active typology) | C31: =IF(Assumptions!C14=1,Assumptions!C16,Assumptions!C17) -> 3200 | D31: =IF(Assumptions!C14=1,Assumptions!C16,Assumptions!C17) -> 3200 | E31: =D31*C5 -> 32000 | F31: First: $3,200 · Repeat/Claymont: $1,800 · CBai MEP SOP v1
B32: Permits / filing / AHJ fees | C32: =Assumptions!C18 -> 1800 | D32: =Assumptions!C18 -> 1800 | E32: =D32*C5 -> 18000 | F32: City of Wilmington residential permit
B33: M4Di OI Tool / ALDi Tracker | C33: =Assumptions!C19 -> 1200 | D33: =Assumptions!C19 -> 1200 | E33: =D33*C5 -> 12000 | F33: G0 ROM + ALDi gate G1–G4 · OED cost-verification standard
B34: HERS rating + DOE ZERH enrollment | C34: 2000 | D34: =C34 -> 2000 | E34: =C34*C5 -> 20000 | F34: HERS rater at CO + DOE program documentation
B35: SOFT COST SUBTOTAL | D35: =SUM(D29:D34) -> 13700 | E35: =SUM(E29:E34) -> 137000
B37: CONTINGENCY + LOAN CARRY
B38: Contingency (8% of hard + soft) | C38: =Assumptions!C18 -> 1800 | D38: =(D27+D35)*Assumptions!C18 -> 317259900 | E38: =D38*C5 -> 3172599000 | F38: 8% of combined hard + soft · per M4Di ALDi standard
B39: Loan carry (31 wks @ 10.25% · 80% LTC) | D39: =(D27+D35+D38)*(Assumptions!C30/52)*Assumptions!C32*Assumptions!C31 -> 7.2715772e+20 | E39: =D39*C5 -> 7.2715772e+21 | F39: Rate from Assumptions · 31-week schedule · 80% LTC
B41: TOTAL PROJECT COST | D41: =D27+D35+D38+D39 -> 7.2715772e+20 | E41: =E27+E35+E38+E39 -> 7.2715772e+21
B43: FOR-SALE RETURN ANALYSIS
B44: Gross sale revenue | D44: =Assumptions!C36 -> 0 | E44: =D44*C5 -> 0 | F44: Assumptions C36 · City target range
B45: Less: total project cost | D45: =D41 -> 7.2715772e+20 | E45: =E41 -> 7.2715772e+21 | F45: From TOTAL PROJECT COST row above
B46: IRA §45L developer credit (DOE Zero Energy Ready Home) | C46: 5000 | D46: =C46 -> 5000 | E46: =C46*C5 -> 50000 | F46: $5,000/unit developer credit · T2–T4 DOE ZERH eligible
...

Sheet T3 — Positive
B1: TIER 3 — FORWARD POSITIVE | FORWARD HOME ROM
B2: G0 ROM ±25% · HERS Neg to +10 · ACH50 < 0.6 · Cert: PHIUS+ / PHIUS Zero · Land: $1 (City program) · Site/utilities: City-funded
B3: Line item | C3: Input | D3: Per unit | E3: Total (10 units) | F3: Source / note
B4: PROJECT INPUTS
B5: Number of units | C5: 10 | D5: =C5 -> 10 | F5: Investor equity activated at site control (LOI)
B6: Avg. unit size (SF) | C6: 1350 | D6: =C6 -> 1350 | E6: =D6*C5 -> 13500
B7: Sale price / unit (from Assumptions) | C7: =Assumptions!C37 -> 1 | D7: =Assumptions!C37 -> 1 | E7: =D7*C5 -> 10
B9: SOURCES
B10: Investor equity (site control triggered) | C10: 600000 | D10: =C10/C5 -> 60000 | E10: =C10 -> 600000 | F10: Deployed at LOI · covers 20% LTC gap + pre-construction soft costs
B11: Construction loan (80% LTC × total cost) | C11: (calculated) | D11: =D44*Assumptions!C32 -> 1.3035808e+24 | E11: =D11*C5 -> 1.3035808e+25
B12: City land ($1 × 10 lots) + site/utilities | C12: City-funded | D12: City-funded | E12: City-funded
B14: HARD COSTS
B15: 4Ward-SIB Forward Panel system (SF × rate) | C15: =Assumptions!C5 -> 31.11 | D15: =C6*Assumptions!C5 -> 41998.5 | E15: =D15*C5 -> 419985 | F15: TER 1507-09 · Barricade INDEVCO · all tiers
B16: Foundation / structural (SF × rate) | C16: =Assumptions!C7 -> 22.22 | D16: =C6*Assumptions!C7 -> 29997 | E16: =D16*C5 -> 299970 | F16: CMU (T1) · Superior Walls Xi Plus TER 2211-02 (T2–T4)
B17: MEP systems — base HVAC + plumbing + elec. (SF × rate) | C17: =Assumptions!C10 -> 16.3 | D17: =C6*Assumptions!C10 -> 22005 | E17: =D17*C5 -> 220050 | F17: T1: std mini-split · T2: Quilt 3-zone · T3–T4: Mitsubishi FX H2i sumo
B18: Finishes / millwork / appliances (SF × rate) | C18: =Assumptions!C11 -> 17.04 | D18: =C6*Assumptions!C11 -> 23004 | E18: =D18*C5 -> 230040 | F18: Mid-range Forward Home spec · all tiers
B19: TIER-SPECIFIC HARD COST UPGRADES
B20: Window upgrade — Magnus 4700 Passive House certified | C20: 5600 | D20: =C20 -> 5600 | E20: =C20*C5 -> 56000 | F20: U ≤ 0.14 · PHIUS compliant
B21: SPAN MAIN 40 smart panel | C21: 4000 | D21: =C21 -> 4000 | E21: =C21*C5 -> 40000 | F21: UL 3141 · circuit-level control
B22: PV system — 8.5 kW high-efficiency TOPCon/HJT | C22: 25750 | D22: =C22 -> 25750 | E22: =C22*C5 -> 257500 | F22: ≥ 22% efficiency · Enphase IQ8
B23: Battery — Enphase IQ5P stack (13–20 kWh) | C23: 11500 | D23: =C23 -> 11500 | E23: =C23*C5 -> 115000 | F23: Stackable · 15-yr warranty · island-capable
B24: LiveRoof® MAXX + productive edible rows (Up Top Acres) | C24: 14000 | D24: =C24 -> 14000 | E24: =C24*C5 -> 140000 | F24: 8" soil · RoofBlue riser · lettuce/herbs/tomatoes
B25: Cistern stub + Rain Bird XFS-CV subsurface drip | C25: 1600 | D25: =C25 -> 1600 | E25: =C25*C5 -> 16000 | F25: T3 stub-out for T4 cistern upgrade
B26: Interior air barrier membrane — Pro Clima Intello+ | C26: 1800 | D26: =C26 -> 1800 | E26: =C26*C5 -> 18000 | F26: Continuous · PHIUS compliant
B27: Viessmann Vitoair ERV | C27: 2700 | D27: =C27 -> 2700 | E27: =C27*C5 -> 27000 | F27: 85% SRE · MERV 13
B28: Drainwater heat recovery | C28: 750 | D28: =C28 -> 750 | E28: =C28*C5 -> 7500 | F28: Required at T3–T4
B29: HARD COST SUBTOTAL (all installed costs) | D29: =SUM(D15:D18)+SUM(D20:D28) -> 184704.5 | E29: =SUM(E15:E18)+SUM(E20:E28) -> 1847045
B31: SOFT COSTS
B32: A&E architectural fee | C32: =Assumptions!C15 -> 5500 | D32: =Assumptions!C15 -> 5500 | E32: =D32*C5 -> 55000 | F32: AOR + permit drawings · fixed all tiers
B33: MEP PE fee (CBai-assisted, active typology) | C33: =IF(Assumptions!C14=1,Assumptions!C16,Assumptions!C17) -> 3200 | D33: =IF(Assumptions!C14=1,Assumptions!C16,Assumptions!C17) -> 3200 | E33: =D33*C5 -> 32000 | F33: First: $3,200 · Repeat/Claymont: $1,800 · CBai MEP SOP v1
B34: Tier 3–4 MEP PE premium (cistern/agrivoltaic/island elec.) | C34: 3200 | D34: =C34 -> 3200 | E34: =C34*C5 -> 32000 | F34: Cistern plumbing + agrivoltaic structural + island-mode elec · SOP v1
B35: Permits / filing / AHJ fees | C35: =Assumptions!C18 -> 1800 | D35: =Assumptions!C18 -> 1800 | E35: =D35*C5 -> 18000 | F35: City of Wilmington residential permit
B36: M4Di OI Tool / ALDi Tracker | C36: =Assumptions!C19 -> 1200 | D36: =Assumptions!C19 -> 1200 | E36: =D36*C5 -> 12000 | F36: G0 ROM + ALDi gate G1–G4 · OED cost-verification standard
B37: PHIUS rater + commissioning plan | C37: 4250 | D37: =C37 -> 4250 | E37: =C37*C5 -> 42500 | F37: PHIUS+ 2021 rater engagement · third-party commissioning
B38: SOFT COST SUBTOTAL | D38: =SUM(D31:D37) -> 19150 | E38: =SUM(E31:E37) -> 191500
B40: CONTINGENCY + LOAN CARRY
B41: Contingency (8% of hard + soft) | C41: =Assumptions!C18 -> 1800 | D41: =(D29+D38)*Assumptions!C18 -> 366938100 | E41: =D41*C5 -> 3669381000 | F41: 8% of combined hard + soft · per M4Di ALDi standard
B42: Loan carry (31 wks @ 10.25% · 80% LTC) | D42: =(D29+D38+D41)*(Assumptions!C30/52)*Assumptions!C32*Assumptions!C31 -> 8.4101984e+20 | E42: =D42*C5 -> 8.4101984e+21 | F42: Rate from Assumptions · 31-week schedule · 80% LTC
B44: TOTAL PROJECT COST | D44: =D29+D38+D41+D42 -> 8.4101984e+20 | E44: =E29+E38+E41+E42 -> 8.4101984e+21
B46: FOR-SALE RETURN ANALYSIS
...

Sheet T4 — Harvest
B1: TIER 4 — FORWARD HARVEST | FORWARD HOME ROM
B2: G0 ROM ±25% · HERS Net positive · ACH50 < 0.6 · Cert: Off-grid verified · Land: $1 (City program) · Site/utilities: City-funded
B3: Line item | C3: Input | D3: Per unit | E3: Total (10 units) | F3: Source / note
B4: PROJECT INPUTS
B5: Number of units | C5: 10 | D5: =C5 -> 10 | F5: Investor equity activated at site control (LOI)
B6: Avg. unit size (SF) | C6: 1350 | D6: =C6 -> 1350 | E6: =D6*C5 -> 13500
B7: Sale price / unit (from Assumptions) | C7: =Assumptions!C38 -> 0 | D7: =Assumptions!C38 -> 0 | E7: =D7*C5 -> 0
B9: SOURCES
B10: Investor equity (site control triggered) | C10: 750000 | D10: =C10/C5 -> 75000 | E10: =C10 -> 750000 | F10: Deployed at LOI · covers 20% LTC gap + pre-construction soft costs
B11: Construction loan (80% LTC × total cost) | C11: (calculated) | D11: =D45*Assumptions!C32 -> 1.3780786e+24 | E11: =D11*C5 -> 1.3780786e+25
B12: City land ($1 × 10 lots) + site/utilities | C12: City-funded | D12: City-funded | E12: City-funded
B14: HARD COSTS
B15: 4Ward-SIB Forward Panel system (SF × rate) | C15: =Assumptions!C5 -> 31.11 | D15: =C6*Assumptions!C5 -> 41998.5 | E15: =D15*C5 -> 419985 | F15: TER 1507-09 · Barricade INDEVCO · all tiers
B16: Foundation / structural (SF × rate) | C16: =Assumptions!C7 -> 22.22 | D16: =C6*Assumptions!C7 -> 29997 | E16: =D16*C5 -> 299970 | F16: CMU (T1) · Superior Walls Xi Plus TER 2211-02 (T2–T4)
B17: MEP systems — base HVAC + plumbing + elec. (SF × rate) | C17: =Assumptions!C10 -> 16.3 | D17: =C6*Assumptions!C10 -> 22005 | E17: =D17*C5 -> 220050 | F17: T1: std mini-split · T2: Quilt 3-zone · T3–T4: Mitsubishi FX H2i sumo
B18: Finishes / millwork / appliances (SF × rate) | C18: =Assumptions!C11 -> 17.04 | D18: =C6*Assumptions!C11 -> 23004 | E18: =D18*C5 -> 230040 | F18: Mid-range Forward Home spec · all tiers
B19: TIER-SPECIFIC HARD COST UPGRADES
B20: Window upgrade — Magnus 4700 Passive House certified | C20: 5600 | D20: =C20 -> 5600 | E20: =C20*C5 -> 56000 | F20: U ≤ 0.14 · PHIUS compliant
B21: SPAN MAIN 40 — island-mode configured | C21: 4000 | D21: =C21 -> 4000 | E21: =C21*C5 -> 40000 | F21: Off-grid load-shedding priority schedule
B22: Agrivoltaic PV trellis — 8.5–12 kW bifacial TOPCon | C22: 28250 | D22: =C22 -> 28250 | E22: =C22*C5 -> 282500 | F22: Elevated 5–6 ft above Crop Circle growing beds
B23: Off-grid battery — EcoFlow DELTA Pro Ultra + FranklinWH aPower 2 | C23: 18000 | D23: =C23 -> 18000 | E23: =C23*C5 -> 180000 | F23: 19.2–90 kWh · true island mode · no utility interconnect
B24: Crop Circle Farms® modular rooftop food system | C24: 10000 | D24: =C24 -> 10000 | E24: =C24*C5 -> 100000 | F24: Patented · 40+ country trademark · 200–600 lbs/yr yield
B25: 500-gal cistern + gravity-fed Rain Bird XFS-CV drip | C25: 4000 | D25: =C25 -> 4000 | E25: =C25*C5 -> 40000 | F25: Closed water loop: roof → crops → compost
B26: NatureMill indoor composter | C26: 1000 | D26: =C26 -> 1000 | E26: =C26*C5 -> 10000 | F26: 5W · 2-week cycle · feeds rooftop growing medium
B27: Interior air barrier membrane — Pro Clima Intello+ | C27: 1800 | D27: =C27 -> 1800 | E27: =C27*C5 -> 18000 | F27: Critical for off-grid battery efficiency
B28: Viessmann Vitoair ERV | C28: 2700 | D28: =C28 -> 2700 | E28: =C28*C5 -> 27000 | F28: 85% SRE · MERV 13
B29: Drainwater heat recovery | C29: 750 | D29: =C29 -> 750 | E29: =C29*C5 -> 7500 | F29: Required T3–T4
B30: HARD COST SUBTOTAL (all installed costs) | D30: =SUM(D15:D18)+SUM(D20:D29) -> 193104.5 | E30: =SUM(E15:E18)+SUM(E20:E29) -> 1931045
B32: SOFT COSTS
B33: A&E architectural fee | C33: =Assumptions!C15 -> 5500 | D33: =Assumptions!C15 -> 5500 | E33: =D33*C5 -> 55000 | F33: AOR + permit drawings · fixed all tiers
B34: MEP PE fee (CBai-assisted, active typology) | C34: =IF(Assumptions!C14=1,Assumptions!C16,Assumptions!C17) -> 3200 | D34: =IF(Assumptions!C14=1,Assumptions!C16,Assumptions!C17) -> 3200 | E34: =D34*C5 -> 32000 | F34: First: $3,200 · Repeat/Claymont: $1,800 · CBai MEP SOP v1
B35: Tier 3–4 MEP PE premium (cistern/agrivoltaic/island elec.) | C35: 3200 | D35: =C35 -> 3200 | E35: =C35*C5 -> 32000 | F35: Cistern plumbing + agrivoltaic structural + island-mode elec · SOP v1
B36: Permits / filing / AHJ fees | C36: =Assumptions!C18 -> 1800 | D36: =Assumptions!C18 -> 1800 | E36: =D36*C5 -> 18000 | F36: City of Wilmington residential permit
B37: M4Di OI Tool / ALDi Tracker | C37: =Assumptions!C19 -> 1200 | D37: =Assumptions!C19 -> 1200 | E37: =D37*C5 -> 12000 | F37: G0 ROM + ALDi gate G1–G4 · OED cost-verification standard
B38: PHIUS rater + off-grid performance verification | C38: 7500 | D38: =C38 -> 7500 | E38: =C38*C5 -> 75000 | F38: PHIUS rater + annual energy/food production audit plan
B39: SOFT COST SUBTOTAL | D39: =SUM(D32:D38) -> 22400 | E39: =SUM(E32:E38) -> 224000
B41: CONTINGENCY + LOAN CARRY
B42: Contingency (8% of hard + soft) | C42: =Assumptions!C18 -> 1800 | D42: =(D30+D39)*Assumptions!C18 -> 387908100 | E42: =D42*C5 -> 3879081000 | F42: 8% of combined hard + soft · per M4Di ALDi standard
B43: Loan carry (31 wks @ 10.25% · 80% LTC) | D43: =(D30+D39+D42)*(Assumptions!C30/52)*Assumptions!C32*Assumptions!C31 -> 8.8908295e+20 | E43: =D43*C5 -> 8.8908295e+21 | F43: Rate from Assumptions · 31-week schedule · 80% LTC
B45: TOTAL PROJECT COST | D45: =D30+D39+D42+D43 -> 8.8908295e+20 | E45: =E30+E39+E42+E43 -> 8.8908295e+21
...
