Workbook

Sheet COVER
B1: M4Di | ALDi Design & Construction Budget Tracker
B2: Forward Home Program · City of Wilmington Vacant Lot Initiative
B4: Project Name / Code: | I4: Enter official M4Di project code (e.g., FH-WIL-001)
B5: Project Address: | I5: Full site address including lot numbers
B6: Owner / Client: | C6: L.E.E.P., Inc. / City of Wilmington Program | I6: Legal entity name
B7: Architect of Record: | C7: Aubyn Architecture LLC (AOR) | M4D lead
B8: M4Di Project Lead:
B9: Gross Area (SF — all units): | C9: =ASSUMPTIONS!C13 -> 13500 | I9: Total project SF: units × SF/unit
B10: ALDi Start Date: | I10: Date M4Di ALDi engagement begins
B11: ROM Estimate Date: | C11: May 2026 | I11: Date of M4Di G0 ROM
B12: ALDi Gate Status: | C12: Gate 0 — ROM Baseline In Progress
B14: COLUMN GUIDE — Four Estimate Stages (ALDi Gate Architecture)
B15: Column D M4Di ROM | C15: Rough Order of Magnitude | D15: At ALDi Gate 0 (G0) | I15: The locked baseline. Never changes after ALDi Gate 0. All variances measured against this.
B16: Column E 75% DD Estimate | C16: Design Development (75%) | D16: At ALDi Gate 2 | I16: First major design-informed reality check. Variance >15% triggers formal review and log entry.
B17: Column F 100% CD / SOV | C17: Construction Documents / GMP | D17: At ALDi Gate 3 | I17: The contracted number. All future change orders are logged against this column.
B18: Column G Actual Cost | C18: Construction Closeout | D18: Updated monthly G4 | I18: Running total of all committed costs: executed SOV line items + approved change orders.

Sheet ASSUMPTIONS
B1: PROJECT ASSUMPTIONS & CONTROLS
B2: Forward Home Program · M4Di OI Tool v2 · G0 ROM ±25%
B3: Input | C3: Value | E3: Notes
B4: A — PROJECT BASIS
B5: Project Name | C5: Forward Home — Type D 10-Unit Cluster | E5: Enter the official M4Di project code (e.g., FH-WIL-001)
B6: Estimate Date | C6: May 2026 | E6: Enter as MM/DD/YYYY. Update with each revision.
B7: Estimate Type | C7: ROM / Conceptual | E7: ROM / Conceptual | Schematic | Design Development | GMP
B8: Project Type | C8: New Construction — Residential | E8: New Construction | Adaptive Reuse | Interior Improvement
B9: Client / Owner | C9: L.E.E.P., Inc. / City of Wilmington Program | E9: Legal entity name of the owner organization.
B10: Site Address | C10: City of Wilmington Vacant Lot Cluster, Wilmington DE 19801 | E10: Full property address for zoning lookup reference.
B11: Total Gross Area (SF) — per unit | C11: 1350 | E11: Gross floor area per unit. Total = this × number of units.
B12: Number of units (Type D cluster) | C12: 10 | E12: Pilot: 10-unit lot cluster. Adjust for Type A (4 units).
B13: Total Project SF (all units) | C13: =C11*C12 -> 13500 | E13: Computed: unit SF × number of units.
B14: Base Region | C14: Delaware | E14: Delaware = M4Di baseline. All unit prices sourced from DE bid data.
B15: Selected Pricing Region | C15: New Castle / Wilmington | E15: Must match REGIONAL FACTORS regional factor table.
B17: B — COST ESCALATION
B18: ENR Construction Cost Index (CCI) escalation % | C18: 0.027 | E18: Source: ENR CCI Q1 2026. Update quarterly. Applied to labor-intensive items.
B19: ENR Building Cost Index (BCI) escalation % | C19: 0.043 | E19: Source: ENR BCI Q1 2026. Update quarterly. Applied to material-intensive items.
B20: Blended escalation rate | C20: =AVERAGE(C17,C18) -> 0.027 | E20: Average of CCI and BCI. Applied uniformly in unit price library.
B21: Material / market factor | C21: 1 | E21: Adjust for procurement pressure, bid climate, supply chain risk. 1.00 = neutral.
B23: C — MARKUPS & CONTINGENCIES
B24: General Conditions (GC) % | C24: 0.08 | E24: Typical range: 6%–10%. On-site supervision, temp facilities, insurance.
B25: Overhead & Profit (OH&P) % | C25: 0.1 | E25: Typical range: 8%–12%. Applied to subtotal after GC.
B26: Design Contingency % | C26: 0.12 | E26: Reduce to 8% at SD; 5% at DD; 0% at GMP. ROM = 12%.
B27: Existing Conditions Contingency % | C27: 0 | E27: New construction = 0%. Renovation/adaptive reuse: 8%–15%.
B28: Owner Selection / Equipment Contingency % | C28: 0.05 | E28: Reduce as owner selections confirmed. Tier upgrades reduce this.
B29: Bid / Permit / Bonds % | C29: 0.02 | E29: Permitting fees, bid bonds, performance bonds. Delaware residential.
B30: Total Contingency % | C30: =C26+C27+C28 -> 0.17 | E30: Sum of all contingency lines. ROM = ~17%.
B32: D — HARD COST UNIT RATES (blended installed per floor SF — all tiers)
B33: 4Ward-SIB Forward Panel — base (all tiers) | C33: 31.11 | E33: Blended installed per floor SF · $42K/unit at 1,350 SF · Barricade INDEVCO ROM May 2026
B34: Foundation — T1 CMU/poured slab | C34: 20.74 | E34: $28K/unit at 1,350 SF · Includes CMU party wall bearing element
B35: Foundation — T2–T4 Superior Walls Xi Plus | C35: 22.22 | E35: $30K/unit · TER 2211-02 (DrJ/ANAB) · premium over T1 CMU
B36: MEP base — T1 std mini-split HVAC + plumbing + electrical | C36: 14.07 | E36: $19K/unit · cold-climate mini-split SEER2 ≥18 · residential MEP bundle
B37: MEP base — T2 Quilt 3-zone + plumbing + electrical | C37: 15.56 | E37: $21K/unit · SEER2 25.3 / HSPF2 12 · ERV separate line item
B38: MEP base — T3–T4 Mitsubishi FX H2i sumo + plumbing + electrical | C38: 16.3 | E38: $22K/unit · SEER2 29.9 · 10-yr warranty
B39: Finishes / millwork / appliances — all tiers | C39: 17.04 | E39: $23K/unit · mid-range Forward Home spec
B41: E — SOFT COST RATES (CBai MEP SOP v1 disaggregated)
B42: Typology toggle (1=First use · 2=Repeat/Claymont template) | C42: 1 | E42: 1 = first Forward Home engagement · 2 = Claymont template repeat (Q4 2026+)
B43: A&E architectural fee (per unit, fixed) | C43: 5500 | E43: AOR + schematic + permit drawings · fixed regardless of typology
B44: MEP PE fee — first typology (per unit) | C44: 3200 | E44: CBai-assisted target · full G0–G3 scope · M4Di CBai MEP Workflow SOP v1 Table 2
...

Sheet BID SUMMARY
B1: ROM COST ESTIMATE — FORWARD HOME PROGRAM · FOUR-TIER SUMMARY
B2: =ASSUMPTIONS!C5 & " | " & ASSUMPTIONS!C6 -> Forward Home — Type D 10-Unit Cluster | May 2026
B3: Summary Item | C3: T1 Code+ | D3: T2 Zero | E3: T3 Positive | F3: T4 Harvest | G3: Notes / Basis
B4: SECTION 1 — HARD COSTS (Pre-Markup Subtotal by CSI Division)
B5: DIV 01 — General Requirements / GC Conditions | C5: ='HARD COST TAKEOFF'!D9 -> 607.5 | D5: ='HARD COST TAKEOFF'!E9 -> 607.5 | E5: ='HARD COST TAKEOFF'!F9 -> #VALUE! | F5: ='HARD COST TAKEOFF'!G9 -> #VALUE! | G5: On-site supervision, temp facilities, site logistics per ALDi standard rates
B6: DIV 02 — Existing Conditions / Demolition | C6: ='HARD COST TAKEOFF'!D16 -> 750 | D6: ='HARD COST TAKEOFF'!E16 -> 750 | E6: ='HARD COST TAKEOFF'!F16 -> 750 | F6: ='HARD COST TAKEOFF'!G16 -> #VALUE! | G6: New construction = $0 demo. Allowance for minor site clearing.
B7: DIV 03 — Concrete (foundation, slab, CMU party wall) | C7: ='HARD COST TAKEOFF'!D22 -> 200 | D7: ='HARD COST TAKEOFF'!E22 -> 200 | E7: ='HARD COST TAKEOFF'!F22 -> 200 | F7: ='HARD COST TAKEOFF'!G22 -> 200 | G7: T1: CMU+slab. T2–T4: Superior Walls Xi Plus + slab.
B8: DIV 04 — Masonry (CMU party wall complement) | C8: ='HARD COST TAKEOFF'!D26 -> 10351.8 | D8: ='HARD COST TAKEOFF'!E26 -> 10351.8 | E8: ='HARD COST TAKEOFF'!F26 -> #VALUE! | F8: ='HARD COST TAKEOFF'!G26 -> #VALUE! | G8: 8″ CMU party wall continuous foundation to underside of roof deck. All tiers.
B9: DIV 05 — Metals (structural, misc) | C9: ='HARD COST TAKEOFF'!D29 -> 10901.8 | D9: ='HARD COST TAKEOFF'!E29 -> 10901.8 | E9: ='HARD COST TAKEOFF'!F29 -> #VALUE! | F9: ='HARD COST TAKEOFF'!G29 -> #VALUE!
B10: DIV 06 — Wood / CLT Structural Spine + Framing | C10: ='HARD COST TAKEOFF'!D33 -> 3500 | D10: ='HARD COST TAKEOFF'!E33 -> 3500 | E10: ='HARD COST TAKEOFF'!F33 -> 3500 | F10: ='HARD COST TAKEOFF'!G33 -> 3500 | G10: T1–T2: 2×6 SPF-S light frame. T3–T4: TerraLam TL500S CLT ESR-5053 where specified.
B11: DIV 07 — 4Ward-SIB Panel + Thermal/Moisture Protection | C11: ='HARD COST TAKEOFF'!D38 -> 6075 | D11: ='HARD COST TAKEOFF'!E38 -> 6075 | E11: ='HARD COST TAKEOFF'!F38 -> — | F11: ='HARD COST TAKEOFF'!G38 -> — | G11: Barricade Thermo-Brace SIB TER 1507-09. Includes WRB, R-5 CI, air barrier. T3-4 adds Intello+.
B12: DIV 08 — Openings (windows, doors) | C12: ='HARD COST TAKEOFF'!D47 -> 22005 | D12: ='HARD COST TAKEOFF'!E47 -> 22005 | E12: ='HARD COST TAKEOFF'!F47 -> #VALUE! | F12: ='HARD COST TAKEOFF'!G47 -> #VALUE! | G12: T1-2: Crystal Magnus 4500 tilt-turn U≤0.20. T3-4: Magnus 4700 PH U≤0.14.
B13: DIV 09 — Finishes (GWB, flooring, paint, tile) | C13: ='HARD COST TAKEOFF'!D53 -> 400 | D13: ='HARD COST TAKEOFF'!E53 -> 0 | E13: ='HARD COST TAKEOFF'!F53 -> 0 | F13: ='HARD COST TAKEOFF'!G53 -> 0 | G13: Interior finishes · mid-range Forward Home spec
B14: DIV 10 — Specialties (cladding, accessories) | C14: ='HARD COST TAKEOFF'!D67 -> 0 | D14: ='HARD COST TAKEOFF'!E67 -> 4725 | E14: ='HARD COST TAKEOFF'!F67 -> #VALUE! | F14: ='HARD COST TAKEOFF'!G67 -> #VALUE! | G14: Allura fiber cement cladding. T1: Lap. T2-3: Panel. T3-4: Panel+Shakes. 50-yr warranty.
B15: DIV 11 — Equipment (appliances, kitchen, specialty) | C15: ='HARD COST TAKEOFF'!D76 -> 1200 | D15: ='HARD COST TAKEOFF'!E76 -> 1200 | E15: ='HARD COST TAKEOFF'!F76 -> 1200 | F15: ='HARD COST TAKEOFF'!G76 -> 1200 | G15: T4: Crop Circle Farms rooftop system. NatureMill composter.
B16: DIV 12 — Furnishings (FF&E allowance) | C16: ='HARD COST TAKEOFF'!D83 -> 4500 | D16: ='HARD COST TAKEOFF'!E83 -> 4500 | E16: ='HARD COST TAKEOFF'!F83 -> 5000 | F16: ='HARD COST TAKEOFF'!G83 -> 5000
B17: DIV 14 — Conveying (elevator — if applicable) | C17: ='HARD COST TAKEOFF'!D89 -> 0 | D17: ='HARD COST TAKEOFF'!E89 -> 0 | E17: ='HARD COST TAKEOFF'!F89 -> 0 | F17: ='HARD COST TAKEOFF'!G89 -> 0 | G17: Type D pilot: 2-story — no elevator. Allow for 3+ story future configurations.
B18: DIV 21 — Fire Suppression (NFPA 13R residential) | C18: ='HARD COST TAKEOFF'!D93 -> 2100 | D18: ='HARD COST TAKEOFF'!E93 -> 2100 | E18: ='HARD COST TAKEOFF'!F93 -> 2800 | F18: ='HARD COST TAKEOFF'!G93 -> 2800 | G18: NFPA 13R townhouse sprinkler system.
B19: DIV 22 — Plumbing (DWV, domestic water, fixtures) | C19: ='HARD COST TAKEOFF'!D97 -> 0 | D19: ='HARD COST TAKEOFF'!E97 -> 0 | E19: ='HARD COST TAKEOFF'!F97 -> 0 | F19: ='HARD COST TAKEOFF'!G97 -> 0 | G19: T4: includes cistern plumbing, gravity-fed drip irrigation.
B20: DIV 23 — HVAC / Mechanical | C20: ='HARD COST TAKEOFF'!D103 -> 0 | D20: ='HARD COST TAKEOFF'!E103 -> 0 | E20: ='HARD COST TAKEOFF'!F103 -> 0 | F20: ='HARD COST TAKEOFF'!G103 -> 0 | G20: T1: std mini-split. T2: Quilt 3-zone + ERV. T3: Mitsubishi FX H2i sumo. T4: Quilt battery-opt.
B21: DIV 26 — Electrical (service, panels, wiring, lighting) | C21: ='HARD COST TAKEOFF'!D110 -> 0 | D21: ='HARD COST TAKEOFF'!E110 -> 0 | E21: ='HARD COST TAKEOFF'!F110 -> 0 | F21: ='HARD COST TAKEOFF'!G110 -> 4000 | G21: T2-4: SPAN MAIN 40 UL 3141. T4: island-mode configured.
B22: DIV 26E — PV + Battery Storage (energy systems) | C22: ='HARD COST TAKEOFF'!D118 -> 500 | D22: ='HARD COST TAKEOFF'!E118 -> 500 | E22: ='HARD COST TAKEOFF'!F118 -> 500 | F22: ='HARD COST TAKEOFF'!G118 -> 500 | G22: T1: stub only. T2: 5.5kW+Enphase IQ5P. T3: 8.5kW+Powerwall 3. T4: Agrivoltaic+EcoFlow/FranklinWH.
B23: DIV 27/28 — Communications + Security | C23: ='HARD COST TAKEOFF'!D125 -> 0 | D23: ='HARD COST TAKEOFF'!E125 -> 4000 | E23: ='HARD COST TAKEOFF'!F125 -> 4000 | F23: ='HARD COST TAKEOFF'!G125 -> 4000
B24: DIV 32/33 — Site Work + Landscaping + Rooftop | C24: ='HARD COST TAKEOFF'!D131 -> 14000 | D24: ='HARD COST TAKEOFF'!E131 -> 14800 | E24: ='HARD COST TAKEOFF'!F131 -> #VALUE! | F24: ='HARD COST TAKEOFF'!G131 -> #VALUE! | G24: T2: LiveRoof Standard. T3: LiveRoof MAXX+edible rows. T4: Crop Circle Farms agrivoltaic trellis.
B25: BASE BUILDING SUBTOTAL (pre-markup, all CSI divisions) | C25: =SUM(C5:C24) -> 77091.1 | D25: =SUM(D5:D24) -> 86216.1 | E25: =SUM(E5:E24) -> #VALUE! | F25: =SUM(F5:F24) -> #VALUE! | G25: Sum of all CSI division line items. Pre-GC, pre-OH&P, pre-contingency.
B27: SECTION 2 — MARKUPS & CONTINGENCIES
B28: General Conditions (GC overhead) | C28: =C25*ASSUMPTIONS!C24 -> 6167.288 | D28: =D25*ASSUMPTIONS!C24 -> 6897.288 | E28: =E25*ASSUMPTIONS!C24 -> #VALUE! | F28: =F25*ASSUMPTIONS!C24 -> #VALUE! | G28: Rate: ASSUMPTIONS!C24 (8%). On-site supervision, temp facilities.
B29: Overhead & Profit (OH&P) | C29: =(C25+C28)*ASSUMPTIONS!C25 -> 8325.8388 | D29: =(D25+D28)*ASSUMPTIONS!C25 -> 9311.3388 | E29: =(E25+E28)*ASSUMPTIONS!C25 -> #VALUE! | F29: =(F25+F28)*ASSUMPTIONS!C25 -> #VALUE! | G29: Rate: ASSUMPTIONS!C25
B30: Total Contingencies (design + existing + owner selection) | C30: =(C25+C28+C29)*(ASSUMPTIONS!C26+ASSUMPTIONS!C27+ASSUMPTIONS!C28) -> 15569.319 | D30: =(D25+D28+D29)*(ASSUMPTIONS!C26+ASSUMPTIONS!C27+ASSUMPTIONS!C28) -> 17412.204 | E30: =(E25+E28+E29)*(ASSUMPTIONS!C26+ASSUMPTIONS!C27+ASSUMPTIONS!C28) -> #VALUE! | F30: =(F25+F28+F29)*(ASSUMPTIONS!C26+ASSUMPTIONS!C27+ASSUMPTIONS!C28) -> #VALUE! | G30: ROM: Design 12% + Existing 0% + Owner 5% = 17%
B31: Bid / Permit / Bonds | C31: =(C25+C28+C29+C30)*ASSUMPTIONS!C29 -> 2143.0709 | D31: =(D25+D28+D29+D30)*ASSUMPTIONS!C29 -> 2396.7386 | E31: =(E25+E28+E29+E30)*ASSUMPTIONS!C29 -> #VALUE! | F31: =(F25+F28+F29+F30)*ASSUMPTIONS!C29 -> #VALUE! | G31: 2% covers permitting, bid bonds, performance bonds.
B32: TOTAL PROJECT ROM (hard costs only) | C32: =C25+C28+C29+C30+C31 -> 109296.62 | D32: =D25+D28+D29+D30+D31 -> 122233.67 | E32: =E25+E28+E29+E30+E31 -> #VALUE! | F32: =F25+F28+F29+F30+F31 -> #VALUE! | G32: Hard cost only. Soft costs, owner contingency in TOTAL PROJECT BUDGET.
B34: Project Cost per SF (hard ROM) | C34: =IFERROR(C32/ASSUMPTIONS!C10,0) -> 0 | D34: =IFERROR(D32/ASSUMPTIONS!C10,0) -> 0 | E34: =IFERROR(E32/ASSUMPTIONS!C10,0) -> 0 | F34: =IFERROR(F32/ASSUMPTIONS!C10,0) -> 0 | G34: $/SF per unit. Compare to SF BENCHMARK for reasonableness check.
B37: SECTION 3 — SOFT COSTS + TOTAL (from SOFT COSTS sheet)
B38: Architecture Fee (from SOFT COSTS) | C38: ='SOFT COSTS'!F54 -> 0 | D38: ='SOFT COSTS'!F54 -> 0 | E38: ='SOFT COSTS'!F54 -> 0 | F38: ='SOFT COSTS'!F54 -> 0 | G38: M4Di fee schedule · Type A residential · % of hard cost ROM
B39: Total Engineering Fees | C39: ='SOFT COSTS'!F84 -> 0 | D39: ='SOFT COSTS'!F84 -> 0 | E39: ='SOFT COSTS'!F84 -> 0 | F39: ='SOFT COSTS'!F84 -> 0 | G39: Structural + MEP PE (CBai-assisted) + FP + civil
B40: Other Consultants & Owner Costs | C40: ='SOFT COSTS'!F85 -> 0 | D40: ='SOFT COSTS'!F85 -> 0 | E40: ='SOFT COSTS'!F85 -> 0 | F40: ='SOFT COSTS'!F85 -> 0 | G40: Permits, M4Di OI, testing, legal, insurance
B41: TOTAL SOFT COSTS | C41: ='SOFT COSTS'!F86 -> 0 | D41: ='SOFT COSTS'!F86 -> 0 | E41: ='SOFT COSTS'!F86 -> 0 | F41: ='SOFT COSTS'!F86 -> 0 | G41: See SOFT COSTS sheet for full detail.
B42: Owner Contingency (post-GMP reserve) | C42: ='TOTAL PROJECT BUDGET'!C34 -> 0 | D42: ='TOTAL PROJECT BUDGET'!C34 -> 0 | E42: ='TOTAL PROJECT BUDGET'!C34 -> 0 | F42: ='TOTAL PROJECT BUDGET'!C34 -> 0 | G42: 5% owner contingency on hard costs
B43: TOTAL PROJECT INVESTMENT | C43: ='TOTAL PROJECT BUDGET'!C36 -> 0 | D43: ='TOTAL PROJECT BUDGET'!C36 -> 0 | E43: ='TOTAL PROJECT BUDGET'!C36 -> 0 | F43: ='TOTAL PROJECT BUDGET'!C36 -> 0 | G43: Hard + Soft + Owner contingency. Full project cost.
B45: SECTION 4 — SITE & UTILITY INFRASTRUCTURE (City contribution — for reference)
...

Sheet HARD COST TAKEOFF
B1: M4Di | Forward Home Program — Hard Cost Takeoff by CSI Division
B2: =ASSUMPTIONS!C5 -> Forward Home — Type D 10-Unit Cluster
B3: Budget Item / Scope | C3: CSI / Ref | D3: T1 Code+ ROM (LOCKED) | E3: T2 Zero ROM (LOCKED) | F3: T3 Positive ROM (LOCKED) | G3: T4 Harvest ROM (LOCKED) | H3: ROM vs. DD Variance | I3: GC Quote | J3: Notes / Source
B4: SECTION 1 — HARD COSTS (Construction) · Per-Unit ROM Values
B5: 1A — DIV 01 General Requirements / GC Conditions | C5: DIV 00/01
B6: General Conditions (GC time, overhead) | C6: DIV 00/01 | D6: =D38*0.08 -> 486 | E6: =E38*0.08 -> 486 | F6: =F38*0.08 -> #VALUE! | G6: =G38*0.08 -> #VALUE! | H6: — | J6: 8% of base building subtotal at each tier. See ASSUMPTIONS GC rate.
B7: Temporary facilities, utilities, hoarding | C7: DIV 01-TF | D7: 2500 | E7: 2500 | F7: 2500 | G7: 2500 | H7: — | J7: Allowance per unit — 10-unit cluster
B8: Site safety, security & signage | C8: DIV 01-SS | D8: 800 | E8: 800 | F8: 800 | G8: 800 | H8: — | J8: Allowance per unit
B9: GC fee / OH&P | C9: DIV 00-OH | D9: =D38*0.1 -> 607.5 | E9: =E38*0.1 -> 607.5 | F9: =F38*0.1 -> #VALUE! | G9: =G38*0.1 -> #VALUE! | H9: — | J9: 10% of base subtotal. See ASSUMPTIONS OH&P rate.
B10: DIV 01 SUBTOTAL | C10: DIV 01 | D10: =D6+D7+D8+D9 -> 4393.5 | E10: =E6+E7+E8+E9 -> 4393.5 | F10: =F6+F7+F8+F9 -> #VALUE! | G10: =G6+G7+G8+G9 -> #VALUE!
B12: 1B — DIV 02 Existing Conditions / Demolition | C12: DIV 02
B13: Selective demolition — interior | C13: DIV 02-DI | D13: 0 | E13: 0 | F13: 0 | G13: — | H13: — | J13: New construction. $0. Allowance only if renovating an existing unit.
B14: Site clearing / minor demolition | C14: DIV 02-SC | D14: 500 | E14: 500 | F14: 500 | G14: 500 | H14: — | J14: Allowance per unit — lot clearing, minor grading
B15: Hazardous materials survey (Phase I allowance) | C15: DIV 02-HT | D15: 250 | E15: 250 | F15: 250 | G15: 250 | H15: — | J15: Allowance per lot — Phase I required for City program parcels
B16: DIV 02 SUBTOTAL | C16: DIV 02 | D16: =D13+D14+D15 -> 750 | E16: =E13+E14+E15 -> 750 | F16: =F13+F14+F15 -> 750 | G16: =G13+G14+G15 -> #VALUE!
B18: 1C — DIV 03 Concrete (foundation, slab, CMU party wall base) | C18: DIV 03
B19: Cast-in-place slab-on-grade (4" with R-10 under) | C19: DIV 03-CF | D19: =ASSUMPTIONS!C11*6.5 -> 8775 | E19: =ASSUMPTIONS!C11*6.5 -> 8775 | F19: =ASSUMPTIONS!C10*6.5 -> #VALUE! | G19: =ASSUMPTIONS!C10*6.5 -> #VALUE! | H19: — | J19: $6.50/SF floor area · includes sub-slab EPS R-10 · all tiers
B20: Foundation — T1 CMU / poured (see also DIV 04) | C20: DIV 03-CM | D20: =ASSUMPTIONS!C11*ASSUMPTIONS!C39*0.55 -> 12652.2 | E20: 0 | F20: 0 | G20: 0 | H20: — | J20: T1: 55% of found. rate is concrete/forming. Remainder in DIV 04 CMU.
B21: Foundation — T2–T4 Superior Walls Xi Plus | C21: DIV 03-SW | D21: 0 | E21: =ASSUMPTIONS!C11*ASSUMPTIONS!C40 -> 0 | F21: =ASSUMPTIONS!C10*ASSUMPTIONS!C40 -> #VALUE! | G21: =ASSUMPTIONS!C10*ASSUMPTIONS!C40 -> #VALUE! | H21: — | J21: TER 2211-02 · 5,000 psi precast · built-in EPS+polyiso · Tiers 2–4
B22: Concrete repair / patching (new const. allowance) | C22: DIV 03-CR | D22: 200 | E22: 200 | F22: 200 | G22: 200 | H22: — | J22: Punch-list allowance per unit
B23: DIV 03 SUBTOTAL | C23: DIV 03 | D23: =D19+D20+D21+D22 -> 21627.2 | E23: =E19+E20+E21+E22 -> 8975 | F23: =F19+F20+F21+F22 -> #VALUE! | G23: =G19+G20+G21+G22 -> #VALUE!
B25: 1D — DIV 04 Masonry (8″ CMU party wall — ALL TIERS) | C25: DIV 04
B26: 8" CMU party wall — continuous foundation to roof underside | C26: DIV 04-NM | D26: =ASSUMPTIONS!C11*ASSUMPTIONS!C39*0.45 -> 10351.8 | E26: =ASSUMPTIONS!C11*ASSUMPTIONS!C39*0.45 -> 10351.8 | F26: =ASSUMPTIONS!C10*ASSUMPTIONS!C39*0.45 -> #VALUE! | G26: =ASSUMPTIONS!C10*ASSUMPTIONS!C39*0.45 -> #VALUE! | H26: — | J26: 8" CMU inherent 2-hr fire / STC≥50. All tiers. ~45% of foundation rate.
B27: Thermafiber SafingFire mineral wool (firestop at CLT/CMU) | C27: DIV 04-FS | D27: 400 | E27: 400 | F27: 400 | G27: 400 | H27: — | J27: Firestop joint detail at every CLT floor/CMU bearing intersection. All tiers.
B28: Hilti FS-ONE MAX sealant at penetrations | C28: DIV 04-HL | D28: 150 | E28: 150 | F28: 150 | G28: 150 | H28: — | J28: Both faces of CMU at all MEP penetrations.
B29: DIV 04 SUBTOTAL | C29: DIV 04 | D29: =D26+D27+D28 -> 10901.8 | E29: =E26+E27+E28 -> 10901.8 | F29: =F26+F27+F28 -> #VALUE! | G29: =G26+G27+G28 -> #VALUE!
B31: 1E — DIV 05 Metals (structural, misc, stairs) | C31: DIV 05
B32: Structural steel connections / lintels / angles | C32: DIV 05-MM | D32: 1200 | E32: 1200 | F32: 1800 | G32: 1800 | H32: — | J32: Light residential — lintels, hold-downs, CMU bearing plates
B33: Stairs — metal pan or open-riser steel | C33: DIV 05-ST | D33: 3500 | E33: 3500 | F33: 3500 | G33: 3500 | H33: — | J33: 2-story unit: one stair per unit. Allowance.
B34: Miscellaneous metals — railings, guards | C34: DIV 05-RL | D34: 1800 | E34: 1800 | F34: 1800 | G34: 1800 | H34: — | J34: Guardrails, handrails per IBC. Allowance per unit.
B35: DIV 05 SUBTOTAL | C35: DIV 05 | D35: =D32+D33+D34 -> 6500 | E35: =E32+E33+E34 -> 6500 | F35: =F32+F33+F34 -> 7100 | G35: =G32+G33+G34 -> 7100
B37: 1F — DIV 06 Wood / CLT Structural Spine + Light Framing | C37: DIV 06
B38: Light-frame wall — 2×6 SPF-S @ 16″ OC (T1–T2) | C38: DIV 06-LF | D38: =ASSUMPTIONS!C11*4.5 -> 6075 | E38: =ASSUMPTIONS!C11*4.5 -> 6075 | F38: — | G38: — | H38: — | J38: $4.50/SF floor area for 2×6 framing. T1–T2 light frame wall system.
B39: CLT structural spine — TerraLam TL500S 5-ply ESR-5053 (T3–T4) | C39: DIV 06-CLT | D39: 0 | E39: 0 | F39: =ASSUMPTIONS!C10*9.8 -> #VALUE! | G39: =ASSUMPTIONS!C10*9.8 -> #VALUE! | H39: — | J39: $9.80/SF · T3–T4 Type C/D CLT structural spine. ESR-5053. EOR required.
B40: Floor framing — 2×10 SPF-S joists + ¾" T&G subfloor | C40: DIV 06-FL | D40: =ASSUMPTIONS!C11*5.2 -> 7020 | E40: =ASSUMPTIONS!C11*5.2 -> 7020 | F40: =ASSUMPTIONS!C10*5.2 -> #VALUE! | G40: =ASSUMPTIONS!C10*5.2 -> #VALUE! | H40: — | J40: $5.20/SF floor area. All types (or CLT floor deck substitute at T3–T4).
B41: Roof framing — stick rafters / pre-eng trusses @ 24" OC | C41: DIV 06-RF | D41: =ASSUMPTIONS!C11*4.8 -> 6480 | E41: =ASSUMPTIONS!C11*4.8 -> 6480 | F41: =ASSUMPTIONS!C10*4.8 -> #VALUE! | G41: =ASSUMPTIONS!C10*4.8 -> #VALUE! | H41: — | J41: R-49 blown-in attic above. T2–T4: LiveRoof / agrivoltaic at roof plane.
B42: Rough carpentry — blocking, nailers, backing | C42: DIV 06-RC | D42: 800 | E42: 800 | F42: 800 | G42: 800 | H42: — | J42: Allowance per unit.
B43: Finish carpentry / millwork / casework | C43: DIV 06-FC | D43: 4500 | E43: 4500 | F43: 4500 | G43: 4500 | H43: — | J43: Kitchen cabinets, vanities, closets. All tiers.
B44: DIV 06 SUBTOTAL | C44: DIV 06 | D44: =D38+D39+D40+D41+D42+D43 -> 24875 | E44: =E38+E39+E40+E41+E42+E43 -> 24875 | F44: =F38+F39+F40+F41+F42+F43 -> #VALUE! | G44: =G38+G39+G40+G41+G42+G43 -> #VALUE!
B46: 1G — DIV 07 4Ward-SIB Panel + Thermal & Moisture Protection | C46: DIV 07
...

Sheet SOFT COSTS
B1: SOFT COSTS — Professional Fees & Pre-Construction Costs
B2: Forward Home Program · Soft costs per M4Di fee schedule + CBai MEP SOP v1
B3: A — PROJECT BASIS (from ASSUMPTIONS & BID SUMMARY)
B4: Discipline / Fee Item | C4: % of Hard Cost (calc or input) | E4: Calculated Fee ($) | F4: User Override ($ if fixed) | G4: Fee Used | H4: Source / Notes
B5: Total Hard Cost ROM | C5: ='BID SUMMARY'!C12 -> 22005 | H5: Pulled from BID SUMMARY. This is the construction ROM driving all % fees.
B6: Project Type (for fee schedule) | C6: =ASSUMPTIONS!C8 -> New Construction — Residential | H6: From ASSUMPTIONS. Drives M4Di fee schedule lookup.
B7: Gross Area — per unit (SF) | C7: =ASSUMPTIONS!C10 -> City of Wilmington Vacant Lot Cluster, Wilmington DE 19801 | H7: Unit SF from ASSUMPTIONS.
B8: B — M4Di FEE SCHEDULE REFERENCE (Type A–E · Residential = Type A)
B9: C — FEE INPUTS & CALCULATIONS
B10: AIA Project Type Code (A=residential · C=fitness/school · etc.) | C10: A | H10: A=warehouse/residential, B=office/retail, C=school/fitness, D=library/restaurant, E=hospital/research
B11: New Construction (vs. Renovation)? | C11: New Construction | H11: New Construction = no renovation premium. Renovation/adaptive reuse adds 0.5%–1.0% to arch fee.
B13: ARCHITECTURE & ENGINEERING FEES
B14: Architecture — Base Fee (M4Di fee schedule Type A) | C14: 0.074 | E14: ='BID SUMMARY'!C12*C14 -> 1628.37 | G14: =IF(AND(F14<>"",F14<>0),F14,E14) -> 1628.37 | H14: Type A residential, ~$1.4M hard cost ROM = 7.4%. Override with actual contract.
B15: + Renovation Premium (N/A — new construction) | C15: 0 | E15: ='BID SUMMARY'!C12*C15 -> 0 | G15: =IF(AND(F15<>"",F15<>0),F15,E15) -> 0 | H15: New construction = $0 renovation premium.
B16: Architecture — TOTAL FEE | G16: =F14+F15 -> 0
B18: ENGINEERING DISCIPLINES
B19: Structural Engineering | C19: 0.015 | E19: ='BID SUMMARY'!C12*C19 -> 330.075 | G19: =IF(AND(F19<>"",F19<>0),F19,E19) -> 330.075 | H19: Typical 1.0%–2.0%. EOR required for CLT/CMU party wall system.
B20: Mechanical Engineering (HVAC — CBai-assisted) | C20: 0.009 | E20: ='BID SUMMARY'!C12*C20 -> 198.045 | G20: =IF(AND(F20<>"",F20<>0),F20,E20) -> 198.045 | H20: CBai-assisted target: $3,200/unit first typology = ~0.9% at T1 ROM. SOP v1.
B21: Electrical Engineering | C21: 0.012 | E21: ='BID SUMMARY'!C12*C21 -> 264.06 | G21: =IF(AND(F21<>"",F21<>0),F21,E21) -> 264.06 | H21: Typical 1.0%–2.0%. SPAN MAIN 40 + PV + battery adds scope at T2–T4.
B22: Plumbing Engineering | C22: 0.008 | E22: ='BID SUMMARY'!C12*C22 -> 176.04 | G22: =IF(AND(F22<>"",F22<>0),F22,E22) -> 176.04 | H22: 0.8%–1.5%. T4: cistern plumbing + drip system adds ~$3,200/unit PE premium.
B23: Fire Protection Engineering | C23: 0.006 | E23: ='BID SUMMARY'!C12*C23 -> 132.03 | G23: =IF(AND(F23<>"",F23<>0),F23,E23) -> 132.03 | H23: 0.5%–1.0%. NFPA 13R residential sprinkler system.
B24: Civil Engineering | C24: 0.008 | E24: ='BID SUMMARY'!C12*C24 -> 176.04 | G24: =IF(AND(F24<>"",F24<>0),F24,E24) -> 176.04 | H24: 0.8%–2.0%. Minimal — City covers site work/utilities. Grading plan only.
B25: Geotechnical / Soils Report | C25: 0.004 | E25: ='BID SUMMARY'!C12*C25 -> 88.02 | G25: =IF(AND(F25<>"",F25<>0),F25,E25) -> 88.02 | H25: 0.3%–0.8% or fixed. Required for Superior Walls Xi Plus seismic confirmation.
B26: Landscape Architecture | C26: 0.003 | E26: ='BID SUMMARY'!C12*C26 -> 66.015 | G26: =IF(AND(F26<>"",F26<>0),F26,E26) -> 66.015 | H26: 0.3%–0.8%. Entry + foundation planting plan.
B27: ADA / Accessibility Consultant | C27: 0.003 | E27: ='BID SUMMARY'!C12*C27 -> 66.015 | G27: =IF(AND(F27<>"",F27<>0),F27,E27) -> 66.015 | H27: 0.3%–0.5%. Required for City program ADA compliance documentation.
B28: HERS Rater / DOE ZERH (T2) | C28: 0 | E28: ='BID SUMMARY'!C12*C28 -> 0 | G28: =IF(AND(F28<>"",F28<>0),F28,E28) -> 0 | H28: $2,000 fixed at T2. Override with actual.
B29: PHIUS Rater + Commissioning (T3–T4) | C29: 0 | E29: ='BID SUMMARY'!C12*C29 -> 0 | G29: =IF(AND(F29<>"",F29<>0),F29,E29) -> 0 | H29: $4,250–$7,500 fixed at T3–T4. Override with actual.
B30: Engineering Subtotal (all disciplines) | G30: =SUM(G19:G29) -> 1496.34
B32: SPECIALTY CONSULTANTS & OWNER COSTS
B33: M4Di OI Tool / ALDi Tracker (this engagement) | C33: 0 | E33: ='BID SUMMARY'!C12*C33 -> 0 | G33: =IF(AND(F33<>"",F33<>0),F33,E33) -> 0 | H33: $1,200/unit = $12,000 for 10 units. Override with actual contract.
B34: Permitting / Plan Review Fees | C34: 0.015 | E34: ='BID SUMMARY'!C12*C34 -> 330.075 | G34: =IF(AND(F34<>"",F34<>0),F34,E34) -> 330.075 | H34: ~1.5% typical City of Wilmington residential. $1,800/unit fixed preferred.
B35: Builder's Risk Insurance | C35: 0.008 | E35: ='BID SUMMARY'!C12*C35 -> 176.04 | G35: =IF(AND(F35<>"",F35<>0),F35,E35) -> 176.04 | H35: 0.5%–1.5% of total project cost. Override with actual premium quote.
B36: Testing / Special Inspections | C36: 0.004 | E36: ='BID SUMMARY'!C12*C36 -> 88.02 | G36: =IF(AND(F36<>"",F36<>0),F36,E36) -> 88.02 | H36: IBC-required. Concrete, CLT bearing, blower door (T2–T4), PHIUS (T3–T4).
B37: Legal / Title / Closing | C37: 0.003 | E37: ='BID SUMMARY'!C12*C37 -> 66.015 | G37: =IF(AND(F37<>"",F37<>0),F37,E37) -> 66.015 | H37: Property matters, contract review. Allowance.
B38: Financing / Loan Origination (CDFI) | C38: 0.01 | E38: ='BID SUMMARY'!C12*C38 -> 220.05 | G38: =IF(AND(F38<>"",F38<>0),F38,E38) -> 220.05 | H38: 0.5%–1.5% of construction loan. Delaware market estimate.
B39: IRA §45L Developer Credit (T2–T4) — OFFSET | C39: 0 | E39: ='BID SUMMARY'!C12*C39 -> 0 | G39: =IF(AND(F39<>"",F39<>0),F39,E39) -> 0 | H39: $5,000/unit credit at T2–T4. Reduces net soft cost. Enter as negative override.
B40: Other Consultants & Owner Costs Subtotal | G40: =SUM(G33:G39) -> 880.2
B42: TOTAL SOFT COSTS | G42: =G16+G30+G40 -> 2376.54
B44: Soft costs benchmarks: 18%–25% of hard cost ROM is typical for community facility renovation. New residential = 10%–15% of hard cost. CBai MEP SOP v1 reduces PE fees 30%–40% vs. full-service. Toggle ASSUMPTIONS typology to model Claymont repeat savings.

Sheet TOTAL PROJECT BUDGET
B1: TOTAL PROJECT BUDGET — Hard Costs + Soft Costs + Owner Contingency
B2: =ASSUMPTIONS!C5 & " | " & "ROM Date: " & ASSUMPTIONS!C6 -> Forward Home — Type D 10-Unit Cluster | ROM Date: May 2026
B4: Budget Item | C4: Amount ($) | D4: % of Hard Cost | E4: % of Total | F4: Notes
B5: SECTION 1 — HARD COSTS (Construction)
B6: Base Building Subtotal (all CSI divisions) | C6: ='BID SUMMARY'!C7 -> 200 | D6: =IFERROR(C7/C13,0) -> 0 | E6: =IFERROR(C7/C36,0) -> 0 | F6: Quantity-based takeoff from HARD COST TAKEOFF sheet.
B7: General Conditions | C7: ='BID SUMMARY'!C8 -> 10351.8 | D7: =IFERROR(C8/C13,0) -> 0 | E7: =IFERROR(C8/C36,0) -> 0 | F7: On-site supervision, temp facilities, insurance.
B8: Overhead & Profit (OH&P) | C8: ='BID SUMMARY'!C9 -> 10901.8 | D8: =IFERROR(C9/C13,0) -> 0 | E8: =IFERROR(C9/C36,0) -> 0
B9: Total Contingencies | C9: ='BID SUMMARY'!C10 -> 3500 | D9: =IFERROR(C10/C13,0) -> 0 | E9: =IFERROR(C10/C36,0) -> 0 | F9: Design 12% + Existing 0% + Owner Selection 5% = 17% ROM
B10: Bid / Permit / Bonds | C10: ='BID SUMMARY'!C11 -> 6075 | D10: =IFERROR(C11/C13,0) -> 0 | E10: =IFERROR(C11/C36,0) -> 0
B11: TOTAL HARD COST (Construction ROM) | C11: ='BID SUMMARY'!C12 -> 22005 | D11: 1 | E11: =IFERROR(C13/C36,0) -> 0
B13: SECTION 2 — SOFT COSTS (Professional Fees)
B14: Architecture — Total Fee (base + renovation premium) | C14: ='SOFT COSTS'!G54 -> 0 | D14: =IFERROR(C16/C13,0) -> 0 | E14: =IFERROR(C16/C36,0) -> 0 | F14: Base fee per M4Di fee schedule Type A residential.
B15: Structural Engineering | C15: ='SOFT COSTS'!G57 -> 0 | D15: =IFERROR(C17/C13,0) -> 0 | E15: =IFERROR(C17/C36,0) -> 0
B16: MEP Engineering (Mech+Elec+Plumbing+FP — CBai-assisted) | C16: =IFERROR(SUM('SOFT COSTS'!G58,'SOFT COSTS'!G59,'SOFT COSTS'!G60,'SOFT COSTS'!G61),0) -> 0 | D16: =IFERROR(C18/C13,0) -> 0 | E16: =IFERROR(C18/C36,0) -> 0 | F16: CBai MEP SOP v1 — 30%–40% below full-service PE fees
B17: Civil + Geotechnical | C17: =IFERROR(SUM('SOFT COSTS'!G62,'SOFT COSTS'!G63),0) -> 0 | D17: =IFERROR(C19/C13,0) -> 0 | E17: =IFERROR(C19/C36,0) -> 0
B18: Other Consultants & Owner Costs | C18: ='SOFT COSTS'!G85 -> 0 | D18: =IFERROR(C20/C13,0) -> 0 | E18: =IFERROR(C20/C36,0) -> 0 | F18: M4Di OI, permits, insurance, testing, legal, financing.
B19: TOTAL SOFT COSTS | C19: ='SOFT COSTS'!G86 -> 0 | D19: =IFERROR(C25/C13,0) -> 0 | E19: =IFERROR(C25/C36,0) -> 0
B21: SECTION 3 — OWNER CONTINGENCY & DIRECT COSTS
B22: Owner Project Contingency (post-GMP reserve) | C22: =IFERROR(D28*C13,0) -> 0 | D22: 0.05 | E22: =IFERROR(C28/C36,0) -> 0 | F22: 5% owner contingency on hard costs. Held by owner post-GMP.
B23: City Land + Site/Infrastructure (City-funded) | C23: 0 | D23: 0 | E23: =IFERROR(C29/C36,0) -> 0 | F23: $0 developer cost. City of Wilmington vacant lot program — land at $1/lot, utilities covered.
B24: Predevelopment Costs (M4Di P1–P3 fees — already incurred) | C24: 0 | D24: 0 | F24: M4Di predevelopment fees are separate contracts per engagement. Enter actual when known.
B25: IRA §45L Developer Credit (T2–T4) — enter as negative | C25: 0 | D25: 0 | F25: –$5,000/unit at T2–T4 DOE ZERH. Enter as negative value to reduce net owner cost.
B26: TOTAL OWNER CONTINGENCY & OTHER | C26: =C28+C29+C30+C31 -> 0 | D26: =IFERROR(C34/C13,0) -> 0 | E26: =IFERROR(C34/C36,0) -> 0
B28: TOTAL PROJECT INVESTMENT | C28: =C13+C25+C34 -> 0
B30: SUMMARY METRICS
B31: Total Project Investment | C31: =C36 -> 0
B32: Hard Cost ROM | C32: ='BID SUMMARY'!C12 -> 22005
B33: Total Soft Costs | C33: ='SOFT COSTS'!G86 -> 0
B34: Soft Costs as % of Hard Costs | C34: =IFERROR('SOFT COSTS'!G86/'BID SUMMARY'!C12,0) -> 0
B35: Total Project Cost / SF (all units) | C35: =IFERROR(C36/ASSUMPTIONS!C12,0) -> 0
B36: Hard Cost / SF | C36: ='BID SUMMARY'!C14 -> 0
B38: SECTION 4 — SITE & UTILITY INFRASTRUCTURE (City Program Contribution)
B39: Estimated site infrastructure cost the City of Wilmington provides under the vacant lot program. Shown for transparency, grant documentation, and NMTC/CDFI funder reporting. A full City credit offsets this cost to $0 developer exposure.
B40: Site demolition & clearing | C40: 18000 | D40: =IFERROR(C40/'BID SUMMARY'!C12,0) -> 0.81799591 | F40: City-covered cost. Shown for program/grant transparency.
B41: Rough grading & earthwork | C41: 32000 | D41: =IFERROR(C41/'BID SUMMARY'!C12,0) -> 1.454215 | F41: City-covered cost. Shown for program/grant transparency.
B42: Sanitary sewer laterals (10 units) | C42: 45000 | D42: =IFERROR(C42/'BID SUMMARY'!C12,0) -> 2.0449898 | F42: City-covered cost. Shown for program/grant transparency.
B43: Water service laterals (10 units) | C43: 38000 | D43: =IFERROR(C43/'BID SUMMARY'!C12,0) -> 1.7268803 | F43: City-covered cost. Shown for program/grant transparency.
B44: Storm drainage / stormwater management | C44: 24000 | D44: =IFERROR(C44/'BID SUMMARY'!C12,0) -> 1.0906612 | F44: City-covered cost. Shown for program/grant transparency.
B45: Electric utility primary service (10 meters) | C45: 35000 | D45: =IFERROR(C45/'BID SUMMARY'!C12,0) -> 1.5905476 | F45: City-covered cost. Shown for program/grant transparency.
B46: Sidewalk, curb & gutter restoration | C46: 28000 | D46: =IFERROR(C46/'BID SUMMARY'!C12,0) -> 1.2724381 | F46: City-covered cost. Shown for program/grant transparency.
...

Sheet ALDi BUDGET TRACKER
B1: M4Di | ALDi Design & Construction Budget Tracker
B2: =COVER!C4 & " · " & "M4Di ALDi Controls · G0 ROM Baseline" -> · M4Di ALDi Controls · G0 ROM Baseline
B3: Budget Item | C3: CSI / Ref | D3: M4Di ROM (LOCKED BASELINE) | E3: 75% DD ESTIMATE (Gate 2) | F3: 100% CD / SOV (Gate 3 — Contracted) | G3: ACTUAL COST (Running Total) | H3: ROM vs. DD Variance | I3: GC QUOTE / PROPOSAL (Pre-SOV) | J3: GC ACTUALS (Running Total) | K3: ROM vs. GC Variance | L3: CD vs. Actual Variance | M3: % Var | N3: Notes / Status
B4: ► Col D: M4Di ROM (locked Gate 0) ► Col E: Enter at Gate 2 (75% DD) ► Col F: Enter at Gate 3 (GMP/SOV) ► Col G: Update monthly during construction ► Cols I–J: GC direct quote + actuals
B5: SECTION 1 — HARD COSTS (Construction) · ROM = T1 Code+ per unit (update for selected tier)
B6: 1A — DIV 01 General Requirements
B7: General Conditions (GC time, overhead) | C7: DIV 00/01 | H7: =IF(AND(ISNUMBER(D7),ISNUMBER(E7)),E7-D7,"") | K7: =IF(AND(ISNUMBER(D7),ISNUMBER(I7)),I7-D7,"") | L7: =IFERROR(G7-F7,"-") -> 0 | M7: =IFERROR((G7-F7)/F7,"-") -> - | N7: 8% of base building subtotal
B8: Temporary Facilities, Utilities & Hoarding | C8: DIV 01-TF | H8: =IF(AND(ISNUMBER(D8),ISNUMBER(E8)),E8-D8,"") | K8: =IF(AND(ISNUMBER(D8),ISNUMBER(I8)),I8-D8,"") | L8: =IFERROR(G8-F8,"-") -> 0 | M8: =IFERROR((G8-F8)/F8,"-") -> - | N8: Per unit allowance
B9: Site Safety, Security & Signage | C9: DIV 01-SS | H9: =IF(AND(ISNUMBER(D9),ISNUMBER(E9)),E9-D9,"") | K9: =IF(AND(ISNUMBER(D9),ISNUMBER(I9)),I9-D9,"") | L9: =IFERROR(G9-F9,"-") -> 0 | M9: =IFERROR((G9-F9)/F9,"-") -> - | N9: Per unit allowance
B10: GC Fee / Overhead & Profit | C10: DIV 00-OH | H10: =IF(AND(ISNUMBER(D10),ISNUMBER(E10)),E10-D10,"") | K10: =IF(AND(ISNUMBER(D10),ISNUMBER(I10)),I10-D10,"") | L10: =IFERROR(G10-F10,"-") -> 0 | M10: =IFERROR((G10-F10)/F10,"-") -> - | N10: 10% of subtotal per ASSUMPTIONS
B11: 1A SUBTOTAL — General Requirements | C11: DIV 01 | D11: =SUM(D7,D8,D9,D10) -> 0 | E11: =SUM(E7,E8,E9,E10) -> 0 | F11: =SUM(F7,F8,F9,F10) -> 0 | G11: =SUM(G7,G8,G9,G10) -> 0
B12: 1B — DIV 02 Existing Conditions
B13: Selective Demolition — Interior | C13: DIV 02-DI | H13: =IF(AND(ISNUMBER(D13),ISNUMBER(E13)),E13-D13,"") | K13: =IF(AND(ISNUMBER(D13),ISNUMBER(I13)),I13-D13,"") | L13: =IFERROR(G13-F13,"-") -> 0 | M13: =IFERROR((G13-F13)/F13,"-") -> - | N13: New const = $0. Renovation allowance.
B14: Site Clearing / Minor Demolition | C14: DIV 02-SC | H14: =IF(AND(ISNUMBER(D14),ISNUMBER(E14)),E14-D14,"") | K14: =IF(AND(ISNUMBER(D14),ISNUMBER(I14)),I14-D14,"") | L14: =IFERROR(G14-F14,"-") -> 0 | M14: =IFERROR((G14-F14)/F14,"-") -> - | N14: Lot clearing allowance per unit
B15: Hazardous Materials Survey (Phase I) | C15: DIV 02-HT | H15: =IF(AND(ISNUMBER(D15),ISNUMBER(E15)),E15-D15,"") | K15: =IF(AND(ISNUMBER(D15),ISNUMBER(I15)),I15-D15,"") | L15: =IFERROR(G15-F15,"-") -> 0 | M15: =IFERROR((G15-F15)/F15,"-") -> - | N15: Required for City program parcels
B16: 1B SUBTOTAL | C16: DIV 02 | D16: =SUM(D13,D14,D15) -> 0 | E16: =SUM(E13,E14,E15) -> 0 | F16: =SUM(F13,F14,F15) -> 0 | G16: =SUM(G13,G14,G15) -> 0
B17: 1C — DIV 03 Concrete
B18: Cast-in-Place Slab-on-Grade (4" + R-10 EPS under) | C18: DIV 03-CF | H18: =IF(AND(ISNUMBER(D18),ISNUMBER(E18)),E18-D18,"") | K18: =IF(AND(ISNUMBER(D18),ISNUMBER(I18)),I18-D18,"") | L18: =IFERROR(G18-F18,"-") -> 0 | M18: =IFERROR((G18-F18)/F18,"-") -> - | N18: $6.50/SF floor area
B19: Foundation — T1 CMU/poured OR T2–T4 Superior Walls | C19: DIV 03-CM/SW | H19: =IF(AND(ISNUMBER(D19),ISNUMBER(E19)),E19-D19,"") | K19: =IF(AND(ISNUMBER(D19),ISNUMBER(I19)),I19-D19,"") | L19: =IFERROR(G19-F19,"-") -> 0 | M19: =IFERROR((G19-F19)/F19,"-") -> - | N19: See ASSUMPTIONS for tier rate
B20: Concrete Repair / Patching (allowance) | C20: DIV 03-CR | H20: =IF(AND(ISNUMBER(D20),ISNUMBER(E20)),E20-D20,"") | K20: =IF(AND(ISNUMBER(D20),ISNUMBER(I20)),I20-D20,"") | L20: =IFERROR(G20-F20,"-") -> 0 | M20: =IFERROR((G20-F20)/F20,"-") -> - | N20: Punch-list allowance
B21: 1C SUBTOTAL | C21: DIV 03 | D21: =SUM(D18,D19,D20) -> 0 | E21: =SUM(E18,E19,E20) -> 0 | F21: =SUM(F18,F19,F20) -> 0 | G21: =SUM(G18,G19,G20) -> 0
B22: 1D — DIV 04 Masonry (8" CMU party wall — ALL TIERS)
B23: 8" CMU party wall — foundation to underside of roof deck | C23: DIV 04-NM | H23: =IF(AND(ISNUMBER(D23),ISNUMBER(E23)),E23-D23,"") | K23: =IF(AND(ISNUMBER(D23),ISNUMBER(I23)),I23-D23,"") | L23: =IFERROR(G23-F23,"-") -> 0 | M23: =IFERROR((G23-F23)/F23,"-") -> - | N23: ALL TIERS. 2-hr fire + STC≥50 inherent. Continuous per IRC R302.2.
B24: Thermafiber SafingFire mineral wool (firestop at CLT/CMU intersections) | C24: DIV 04-FS | H24: =IF(AND(ISNUMBER(D24),ISNUMBER(E24)),E24-D24,"") | K24: =IF(AND(ISNUMBER(D24),ISNUMBER(I24)),I24-D24,"") | L24: =IFERROR(G24-F24,"-") -> 0 | M24: =IFERROR((G24-F24)/F24,"-") -> - | N24: All levels · CLT floor/CMU bearing joint
B25: Hilti FS-ONE MAX sealant at MEP penetrations | C25: DIV 04-HL | H25: =IF(AND(ISNUMBER(D25),ISNUMBER(E25)),E25-D25,"") | K25: =IF(AND(ISNUMBER(D25),ISNUMBER(I25)),I25-D25,"") | L25: =IFERROR(G25-F25,"-") -> 0 | M25: =IFERROR((G25-F25)/F25,"-") -> - | N25: Both CMU faces
B26: 1D SUBTOTAL | C26: DIV 04 | D26: =SUM(D23,D24,D25) -> 0 | E26: =SUM(E23,E24,E25) -> 0 | F26: =SUM(F23,F24,F25) -> 0 | G26: =SUM(G23,G24,G25) -> 0
B27: 1E — DIV 05 Metals
B28: Structural Steel Connections / Lintels / Angles | C28: DIV 05-MM | H28: =IF(AND(ISNUMBER(D28),ISNUMBER(E28)),E28-D28,"") | K28: =IF(AND(ISNUMBER(D28),ISNUMBER(I28)),I28-D28,"") | L28: =IFERROR(G28-F28,"-") -> 0 | M28: =IFERROR((G28-F28)/F28,"-") -> - | N28: Allowance per unit
B29: Stairs — Metal Pan or Open-Riser | C29: DIV 05-ST | H29: =IF(AND(ISNUMBER(D29),ISNUMBER(E29)),E29-D29,"") | K29: =IF(AND(ISNUMBER(D29),ISNUMBER(I29)),I29-D29,"") | L29: =IFERROR(G29-F29,"-") -> 0 | M29: =IFERROR((G29-F29)/F29,"-") -> - | N29: One stair per unit allowance
B30: Miscellaneous Metals — Railings, Guards | C30: DIV 05-RL | H30: =IF(AND(ISNUMBER(D30),ISNUMBER(E30)),E30-D30,"") | K30: =IF(AND(ISNUMBER(D30),ISNUMBER(I30)),I30-D30,"") | L30: =IFERROR(G30-F30,"-") -> 0 | M30: =IFERROR((G30-F30)/F30,"-") -> - | N30: IBC code-required allowance
B31: 1E SUBTOTAL | C31: DIV 05 | D31: =SUM(D28,D29,D30) -> 0 | E31: =SUM(E28,E29,E30) -> 0 | F31: =SUM(F28,F29,F30) -> 0 | G31: =SUM(G28,G29,G30) -> 0
B32: 1F — DIV 06 Wood / CLT Structural Spine + Framing
B33: Light Frame — 2×6 SPF-S @ 16" OC (T1–T2) | C33: DIV 06-LF | H33: =IF(AND(ISNUMBER(D33),ISNUMBER(E33)),E33-D33,"") | K33: =IF(AND(ISNUMBER(D33),ISNUMBER(I33)),I33-D33,"") | L33: =IFERROR(G33-F33,"-") -> 0 | M33: =IFERROR((G33-F33)/F33,"-") -> - | N33: $4.50/SF T1–T2
B34: CLT Structural Spine — TerraLam TL500S 5-ply ESR-5053 (T3–T4) | C34: DIV 06-CLT | H34: =IF(AND(ISNUMBER(D34),ISNUMBER(E34)),E34-D34,"") | K34: =IF(AND(ISNUMBER(D34),ISNUMBER(I34)),I34-D34,"") | L34: =IFERROR(G34-F34,"-") -> 0 | M34: =IFERROR((G34-F34)/F34,"-") -> - | N34: $9.80/SF T3–T4. EOR required.
B35: Floor Framing — 2×10 SPF-S + ¾" T&G Subfloor | C35: DIV 06-FL | H35: =IF(AND(ISNUMBER(D35),ISNUMBER(E35)),E35-D35,"") | K35: =IF(AND(ISNUMBER(D35),ISNUMBER(I35)),I35-D35,"") | L35: =IFERROR(G35-F35,"-") -> 0 | M35: =IFERROR((G35-F35)/F35,"-") -> - | N35: $5.20/SF all types
B36: Roof Framing — Stick Rafters / Pre-Eng Trusses @ 24" OC | C36: DIV 06-RF | H36: =IF(AND(ISNUMBER(D36),ISNUMBER(E36)),E36-D36,"") | K36: =IF(AND(ISNUMBER(D36),ISNUMBER(I36)),I36-D36,"") | L36: =IFERROR(G36-F36,"-") -> 0 | M36: =IFERROR((G36-F36)/F36,"-") -> - | N36: $4.80/SF · R-49 blown attic above
B37: Rough Carpentry — Blocking, Nailers, Backing | C37: DIV 06-RC | H37: =IF(AND(ISNUMBER(D37),ISNUMBER(E37)),E37-D37,"") | K37: =IF(AND(ISNUMBER(D37),ISNUMBER(I37)),I37-D37,"") | L37: =IFERROR(G37-F37,"-") -> 0 | M37: =IFERROR((G37-F37)/F37,"-") -> - | N37: Allowance per unit
B38: Finish Carpentry / Millwork / Casework | C38: DIV 06-FC | H38: =IF(AND(ISNUMBER(D38),ISNUMBER(E38)),E38-D38,"") | K38: =IF(AND(ISNUMBER(D38),ISNUMBER(I38)),I38-D38,"") | L38: =IFERROR(G38-F38,"-") -> 0 | M38: =IFERROR((G38-F38)/F38,"-") -> - | N38: Kitchens, vanities, closets. All tiers.
B39: 1F SUBTOTAL | C39: DIV 06 | D39: =SUM(D33,D34,D35,D36,D37,D38) -> 0 | E39: =SUM(E33,E34,E35,E36,E37,E38) -> 0 | F39: =SUM(F33,F34,F35,F36,F37,F38) -> 0 | G39: =SUM(G33,G34,G35,G36,G37,G38) -> 0
B40: 1G — DIV 07 4Ward-SIB Panel + Thermal & Moisture
...
