Workbook

Sheet COVER
B3: Construction Cost Estimate
B4: 607 Concord Avenue · Wilmington, Delaware 19802
B5: ROUGH ORDER OF MAGNITUDE · FULL GUT REHABILITATION WITH COMPLETE MEP REPLACEMENT
B7: TOTAL PROJECT COST — ORDER OF MAGNITUDE
B8: =SUMMARY!P10 -> 292744.82 | O8: =SUMMARY!P10/1300 -> 225.18832
B9: ="CONSTRUCTION "&TEXT(SUMMARY!P8,"$#,##0")&" A/E FEES "&TEXT(SUMMARY!P9,"$#,##0")&" GROSS AREA "&TEXT(1300,"#,##0")&" SF" -> CONSTRUCTION $276,174 A/E FEES $16,570 GROSS AREA 1,300 SF
B11: Project information | L11: Prepared by
B12: PROJECT | F12: 607 Concord Avenue | L12: FIRM | P12: Merge 4 Design LLC
B13: LOCATION | F13: Wilmington, DE 19802 | L13: ADDRESS | P13: 500 Delaware Ave, Suite 1 #1551
B14: PARCEL | F14: 2601530162 | P14: Wilmington, DE 19899
B15: JURISDICTION | F15: New Castle County | L15: PROJECT NO. | P15: M2-2026-016
B16: BUILDING | F16: Rowhouse — end unit, corner | L16: ESTIMATE DATE | P16: 23 July 2026
B17: CONFIGURATION | F17: 2 story + basement + attic | L17: DRAWING BASIS | P17: AD-01 / A-101 / AD-03
B18: GROSS AREA | F18: 1,300 SF above grade | L18: DRAWING DATE | P18: 28 June 2026
B19: SCOPE | F19: Full gut rehabilitation | L19: ACCURACY | P19: ± 20% · AACE Class 4
B21: Project cost control stage
B22: ROM estimate | F22: Feasibility | J22: Design development | N22: GMP / contract | R22: Closeout
B23: COMPLETE | F23: PENDING | J23: PENDING | N23: PENDING | R23: PENDING
B25: Basis of estimate
B26: This estimate is a rough order of magnitude prepared from the architectural drawing set referenced above. Quantities are derived from plan takeoff and field-verifiable dimensions. Unit rates reflect current Wilmington-area subcontractor pricing for residential rehabilitation of comparable scale and complexity.
B27: All mechanical, electrical and plumbing systems are carried as complete replacement, including a 200-amp electrical service upgrade, new gas-fired forced-air heating with cooling, new supply and drain-waste-vent piping, and a new gas water heater.
B28: Exterior scope reflects observed existing conditions including roof replacement to the rafters, porch reconstruction, selective masonry repointing, and re-cladding of the rear wing.
B29: The estimate carries an 8% design and construction contingency and a 10% general contractor overhead and profit allowance. Architecture and engineering fees are shown separately at 6% of construction cost.
B30: Prepared for budgeting, financing and feasibility purposes. This is not a bid, a guaranteed maximum price, or an offer to perform work. Competitive contractor pricing should be obtained prior to any funding commitment or construction contract.
B32: Merge 4 Design LLC · M4Di Construction ROM · Project M2-2026-016 · Issued 23 July 2026 · Page 1 of 4

Sheet SUMMARY
B3: Cost summary
B5: Direct construction cost | K5: 52 line items · 10 divisions | P5: =DETAIL!G79 -> 232470
B6: Design & construction contingency | K6: 8% of direct cost | P6: =DETAIL!G79*0.08 -> 18597.6
B7: General contractor overhead & profit | K7: 10% | P7: =(DETAIL!G79+P6)*0.1 -> 25106.76
B8: Total construction cost | K8: Hard cost | P8: =DETAIL!G79+P6+P7 -> 276174.36
B9: Architecture & engineering fees | K9: 6% of construction | P9: =P8*0.06 -> 16570.462
B10: TOTAL PROJECT COST | K10: Order of magnitude | P10: =P8+P9 -> 292744.82
B12: Cost metrics
B13: GROSS FLOOR AREA | G13: DIRECT COST / SF | L13: CONSTRUCTION / SF | Q13: TOTAL PROJECT / SF
B14: =1300 -> 1300 | G14: =DETAIL!G79/1300 -> 178.82308 | L14: =P8/1300 -> 212.44182 | Q14: =P10/1300 -> 225.18832
B16: Cost distribution by division
B17: Division | L17: Subtotal | Q17: Share of direct
B18: 01 GENERAL CONDITIONS | L18: =DETAIL!G9 -> 9200 | Q18: =DETAIL!G9/DETAIL!G79 -> 0.039574999
B19: 02 DEMOLITION | L19: =DETAIL!G17 -> 20050 | Q19: =DETAIL!G17/DETAIL!G79 -> 0.086247688
B20: 03 FOUNDATIONS & STRUCTURE | L20: =DETAIL!G23 -> 14300 | Q20: =DETAIL!G23/DETAIL!G79 -> 0.061513314
B21: 04 EXTERIOR ENVELOPE | L21: =DETAIL!G34 -> 42450 | Q21: =DETAIL!G34/DETAIL!G79 -> 0.18260421
B22: 05 INTERIOR CONSTRUCTION | L22: =DETAIL!G40 -> 19520 | Q22: =DETAIL!G40/DETAIL!G79 -> 0.083967824
B23: 06 FINISHES | L23: =DETAIL!G47 -> 21300 | Q23: =DETAIL!G47/DETAIL!G79 -> 0.091624726
B24: 07 KITCHEN & BATHS | L24: =DETAIL!G56 -> 35600 | Q24: =DETAIL!G56/DETAIL!G79 -> 0.15313804
B25: 08 PLUMBING | L25: =DETAIL!G63 -> 21200 | Q25: =DETAIL!G63/DETAIL!G79 -> 0.091194563
B26: 09 HVAC | L26: =DETAIL!G70 -> 22650 | Q26: =DETAIL!G70/DETAIL!G79 -> 0.097431927
B27: 10 ELECTRICAL | L27: =DETAIL!G78 -> 26200 | Q27: =DETAIL!G78/DETAIL!G79 -> 0.11270271
B28: Direct construction cost | L28: =DETAIL!G79 -> 232470 | Q28: 1
B30: Existing condition observations
B31: FRONT ELEVATION | F31: Two-story brick rowhouse with attic dormer. Arched masonry window surrounds intact. Full-width covered porch. Entry door boarded in current imagery — structure vacant and secured.
B32: CORNER / SIDE | F32: End-unit condition exposes the full side elevation. Stone foundation shows moisture staining and efflorescence at grade. Basement openings boarded.
B33: REAR WING | F33: Addition clad in vinyl siding, weathered and deteriorated. Re-clad carried in Division 04.
B34: ROOF | F34: Existing roof aged beyond serviceable life. Full strip to rafters carried in Division 02.
B35: HAZARDOUS MATERIALS | F35: Structure predates 1978. Lead paint and asbestos presumed present. Survey and abatement excluded — see Exclusions, page 4.
B37: Merge 4 Design LLC · M4Di Construction ROM · Project M2-2026-016 · Issued 23 July 2026 · Page 2 of 4

Sheet DETAIL
B3: Construction cost detail — full quantity and rate buildup
B4: Scope item | C4: CSI ref | D4: Qty | E4: Unit | F4: Unit cost | G4: Line total | H4: % of dir.
B5: 01 GENERAL CONDITIONS
B6: Temporary protection, site safety, dumpsters, cleanup | C6: DIV 01-TF | D6: 1 | E6: LS | F6: 4500 | G6: =D6*F6 -> 4500 | H6: =G6/$G$79 -> 0.019357336
B7: Permits & inspections — New Castle County | C7: DIV 01-PM | D7: 1 | E7: LS | F7: 3500 | G7: =D7*F7 -> 3500 | H7: =G7/$G$79 -> 0.015055706
B8: Final clean | C8: DIV 01-FC | D8: 1 | E8: LS | F8: 1200 | G8: =D8*F8 -> 1200 | H8: =G8/$G$79 -> 0.0051619564
B9: Division subtotal | G9: =SUM(G6:G8) -> 9200
B10: 02 DEMOLITION
B11: Selective demo — windows, exterior doors, sidelights | C11: DIV 02-DI | D11: 1 | E11: LS | F11: 3500 | G11: =D11*F11 -> 3500 | H11: =G11/$G$79 -> 0.015055706
B12: Remove exterior brick wall to roof level | C12: DIV 02-DE | D12: 1 | E12: LS | F12: 4200 | G12: =D12*F12 -> 4200 | H12: =G12/$G$79 -> 0.018066847
B13: Remove load-bearing structural wall (interior) | C13: DIV 02-DS | D13: 1 | E13: LS | F13: 2800 | G13: =D13*F13 -> 2800 | H13: =G13/$G$79 -> 0.012044565
B14: Roof demolition — strip to rafters | C14: DIV 02-DR | D14: 1300 | E14: SF | F14: 2.5 | G14: =D14*F14 -> 3250 | H14: =G14/$G$79 -> 0.013980299
B15: Floor sheathing removal / porch decking demo | C15: DIV 02-DF | D15: 1 | E15: LS | F15: 1800 | G15: =D15*F15 -> 1800 | H15: =G15/$G$79 -> 0.0077429346
B16: MEP demolition — remove systems back to mains | C16: DIV 02-DM | D16: 1 | E16: LS | F16: 4500 | G16: =D16*F16 -> 4500 | H16: =G16/$G$79 -> 0.019357336
B17: Division subtotal | G17: =SUM(G11:G16) -> 20050
B18: 03 FOUNDATIONS & STRUCTURE
B19: Repair & parge foundation — front and side elevations | C19: DIV 03-CR | D19: 1 | E19: LS | F19: 2800 | G19: =D19*F19 -> 2800 | H19: =G19/$G$79 -> 0.012044565
B20: Repair basement slab — patch / limited pour | C20: DIV 03-CS | D20: 1 | E20: LS | F20: 1800 | G20: =D20*F20 -> 1800 | H20: =G20/$G$79 -> 0.0077429346
B21: New LVL beam & posts at each end | C21: DIV 06-SF | D21: 1 | E21: LS | F21: 6500 | G21: =D21*F21 -> 6500 | H21: =G21/$G$79 -> 0.027960597
B22: New 2x10 floor joists | C22: DIV 06-FJ | D22: 5 | E22: EA | F22: 640 | G22: =D22*F22 -> 3200 | H22: =G22/$G$79 -> 0.013765217
B23: Division subtotal | G23: =SUM(G19:G22) -> 14300
B24: 04 EXTERIOR ENVELOPE
B25: Asphalt shingle roof — main pitched areas | C25: DIV 07-RS | D25: 1300 | E25: SF | F25: 7.5 | G25: =D25*F25 -> 9750 | H25: =G25/$G$79 -> 0.041940896
B26: Low-slope rubber membrane roof — porch / flat area | C26: DIV 07-RM | D26: 1 | E26: LS | F26: 4800 | G26: =D26*F26 -> 4800 | H26: =G26/$G$79 -> 0.020647826
B27: Porch rebuild — decking, vinyl railings, steps | C27: DIV 06-PR | D27: 1 | E27: LS | F27: 5600 | G27: =D27*F27 -> 5600 | H27: =G27/$G$79 -> 0.02408913
B28: Exterior entry door with sidelights — front | C28: DIV 08-DE | D28: 1 | E28: EA | F28: 2800 | G28: =D28*F28 -> 2800 | H28: =G28/$G$79 -> 0.012044565
B29: Exterior rear door | C29: DIV 08-DR | D29: 1 | E29: EA | F29: 1800 | G29: =D29*F29 -> 1800 | H29: =G29/$G$79 -> 0.0077429346
B30: Replacement windows — match existing profile | C30: DIV 08-WD | D30: 8 | E30: EA | F30: 950 | G30: =D30*F30 -> 7600 | H30: =G30/$G$79 -> 0.03269239
B31: Masonry infill at basement window openings | C31: DIV 04-MI | D31: 3 | E31: EA | F31: 800 | G31: =D31*F31 -> 2400 | H31: =G31/$G$79 -> 0.010323913
B32: Rear wing re-clad — fiber cement siding | C32: DIV 07-SD | D32: 1 | E32: LS | F32: 4500 | G32: =D32*F32 -> 4500 | H32: =G32/$G$79 -> 0.019357336
B33: Brick repointing — spot tuckpointing | C33: DIV 04-RP | D33: 1 | E33: LS | F33: 3200 | G33: =D33*F33 -> 3200 | H33: =G33/$G$79 -> 0.013765217
B34: Division subtotal | G34: =SUM(G25:G33) -> 42450
B35: 05 INTERIOR CONSTRUCTION
B36: Gypsum board — walls and ceilings, all levels | C36: DIV 09-GB | D36: 2600 | E36: SF | F36: 4.2 | G36: =D36*F36 -> 10920 | H36: =G36/$G$79 -> 0.046973803
B37: Interior doors per schedule | C37: DIV 08-DI | D37: 8 | E37: EA | F37: 550 | G37: =D37*F37 -> 4400 | H37: =G37/$G$79 -> 0.018927173
B38: Closet shelving / linen storage | C38: DIV 06-MW | D38: 1 | E38: LS | F38: 1800 | G38: =D38*F38 -> 1800 | H38: =G38/$G$79 -> 0.0077429346
B39: Stair repair and refinish | C39: DIV 06-ST | D39: 1 | E39: LS | F39: 2400 | G39: =D39*F39 -> 2400 | H39: =G39/$G$79 -> 0.010323913
B40: Division subtotal | G40: =SUM(G36:G39) -> 19520
B41: 06 FINISHES
B42: Vinyl plank flooring on T&G plywood underlayment | C42: DIV 09-FV | D42: 800 | E42: SF | F42: 6.5 | G42: =D42*F42 -> 5200 | H42: =G42/$G$79 -> 0.022368478
...
