Workbook

Sheet COVER
B1: M4Di | ALDi Design & Construction Budget Tracker
B2: Project Cost Control from ROM Estimate Through Construction Closeout
B4: Project Name: | F4: Enter the official M4Di project code
B5: Project Address: | F5: Full site address
B6: Owner / Client: | F6: Legal entity name
B7: Architect of Record: | F7: e.g., M4D / Aubyn Architecture
B8: M4Di Project Lead:
B9: Gross Area (SF): | F9: Total building SF in scope
B10: ALDi Start Date: | F10: Date M4Di ALDi engagement begins
B11: ROM Estimate Date: | F11: Date of M4Di P3 ROM (v1)
B13: COLUMN GUIDE — Four Estimate Stages
B14: Column | C14: Stage | D14: When Populated | E14: Purpose / Notes
B15: Column D M4Di ROM | C15: Rough Order of Magnitude | D15: At ALDi engagement start (P3 deliverable) | E15: The locked baseline. Never changes after ALDi Gate 0. All variances measured against this column.
B16: Column E 75% DD Estimate | C16: Design Development (75%) | D16: At ALDi Gate 2 (DD milestone) | E16: First major design-informed reality check. Should be within ±15% of ROM. Flag and explain if not.
B17: Column F 100% CD / Contractor SOV | C17: Construction Documents / GMP | D17: At ALDi Gate 3 (GMP execution) | E17: The contracted number. All future change orders are additions to this column. Defines the budget baseline.
B18: Column G Actual Cost | C18: Construction Closeout | D18: Updated monthly during construction | E18: Running total of all committed costs: executed SOV + approved COs + owner direct costs.
B20: CORE RULES FOR THIS WORKBOOK
B21: 1. | C21: Column D (M4Di ROM) is LOCKED after ALDi Gate 0. It never changes. It is the reference baseline for every downstream comparison.
B22: 2. | C22: Column E (75% DD) is entered at Gate 2. If the DD estimate exceeds Column D by more than 15%, a written explanation is required in the VARIANCE LOG before the gate is cleared.
B23: 3. | C23: Column F (100% CD / SOV) is entered at Gate 3 from the executed Contractor Schedule of Values. This is the contracted hard cost. Soft costs in this column come from executed consultant agreements.
B24: 4. | C24: Column G (Actual Cost) is updated monthly. It equals Column F plus all approved change orders plus all owner direct costs incurred to date. It is never projected — only committed costs.
B25: 5. | C25: Every line item in this tracker maps to a line item in the M4Di OI Tool (BID SUMMARY, SOFT COSTS, or TOTAL PROJECT BUDGET). The M4Di project lead maintains both files in sync.
B26: 6. | C26: This workbook is an M4Di ALDi deliverable. It is issued to the Owner and AE at Gate 0 setup. The Owner and AE receive read-only PDF exports monthly. The live Excel file is M4Di-controlled.

Sheet BUDGET TRACKER
B1: M4Di | ALDi Design & Construction Budget Tracker
B2: =IF(COVER!C4="","[Project Name — complete COVER tab]",COVER!C4&" | "& COVER!C6&" | ALDi Start: "&TEXT(COVER!C10,"mm/dd/yyyy")) -> [Project Name — complete COVER tab]
B4: Budget Item | C4: CSI / Ref | D4: M4Di ROM (LOCKED BASELINE) | E4: 75% DD ESTIMATE (Gate 2) | F4: 100% CD / SOV (Gate 3 — Contracted) | G4: ACTUAL COST (Running Total) | H4: ROM vs. DD Variance | I4: GC QUOTE / PROPOSAL (Pre-SOV) | J4: GC ACTUALS (Running Total) | K4: ROM vs. GC Quote Variance | L4: CD vs. Actual Variance | N4: Notes / Status
B5: Budget Item | C5: CSI / Ref | D5: $ Amount | E5: $ Amount | F5: $ Amount | G5: $ Amount | H5: $ Variance | I5: $ Amount | J5: $ Amount | K5: $ Variance | L5: $ Variance | M5: % Var | N5: Notes / Flag
B6: ► Col D: M4Di ROM (locked Gate 0) ► Col E: Enter at Gate 2 (75% DD) ► Col F: Enter at Gate 3 from GMP/SOV ► Col G: Update monthly ► Col I: GC Quote/Proposal (pre-SOV) ► Col J: GC Actuals (monthly)
B7: SECTION 1 — HARD COSTS (Construction)
B8: 1A — Procurement & General Requirements
B9: General Conditions (GC Time & Overhead) | C9: DIV 00/01 | H9: =IF(AND(ISNUMBER(D9),ISNUMBER(E9)),E9-D9,"") | K9: =IF(AND(ISNUMBER(D9),ISNUMBER(I9)),I9-D9,"")
B10: Temporary Facilities, Utilities & Hoarding | C10: DIV 01-TF | H10: =IF(AND(ISNUMBER(D10),ISNUMBER(E10)),E10-D10,"") | K10: =IF(AND(ISNUMBER(D10),ISNUMBER(I10)),I10-D10,"") | L10: =IFERROR(G10-F10,"-") -> 0 | M10: =IFERROR((G10-F10)/F10,"-") -> - | N10: Per takeoff; hazmat TBD pending survey
B11: Site Safety, Security & Signage | C11: DIV 01-SS | H11: =IF(AND(ISNUMBER(D11),ISNUMBER(E11)),E11-D11,"") | K11: =IF(AND(ISNUMBER(D11),ISNUMBER(I11)),I11-D11,"") | L11: =IFERROR(G11-F11,"-") -> 0 | M11: =IFERROR((G11-F11)/F11,"-") -> - | N11: Housekeeping pads; structural repairs
B12: Dumpsters / Debris Removal | C12: DIV 01-DR | H12: =IF(AND(ISNUMBER(D12),ISNUMBER(E12)),E12-D12,"") | K12: =IF(AND(ISNUMBER(D12),ISNUMBER(I12)),I12-D12,"") | L12: =IFERROR(G12-F12,"-") -> 0 | M12: =IFERROR((G12-F12)/F12,"-") -> - | N12: Misc. metals; stair rails; lintels
B13: Payment & Performance Bond | C13: DIV 00-BD | H13: =IF(AND(ISNUMBER(D13),ISNUMBER(E13)),E13-D13,"") | K13: =IF(AND(ISNUMBER(D13),ISNUMBER(I13)),I13-D13,"") | L13: =IFERROR(G13-F13,"-") -> 0 | M13: =IFERROR((G13-F13)/F13,"-") -> - | N13: Interior partition framing
B14: Builder's Risk Insurance | C14: DIV 00-BR | H14: =IF(AND(ISNUMBER(D14),ISNUMBER(E14)),E14-D14,"") | K14: =IF(AND(ISNUMBER(D14),ISNUMBER(I14)),I14-D14,"") | L14: =IFERROR(G14-F14,"-") -> 0 | M14: =IFERROR((G14-F14)/F14,"-") -> - | N14: Roof repairs; waterproofing; sealants
B15: GC Fee / Overhead & Profit | C15: DIV 00-OH | H15: =IF(AND(ISNUMBER(D15),ISNUMBER(E15)),E15-D15,"") | K15: =IF(AND(ISNUMBER(D15),ISNUMBER(I15)),I15-D15,"") | L15: =IFERROR(G15-F15,"-") -> 0 | M15: =IFERROR((G15-F15)/F15,"-") -> - | N15: Anti-ligature hardware; ADA entries
B16: 1B — Existing Conditions | L16: =IFERROR(G16-F16,"-") -> 0 | M16: =IFERROR((G16-F16)/F16,"-") -> - | N16: Rubber athletic; resilient; carpet tile
B17: Selective Demolition — Interior | C17: DIV 02-DI | H17: =IF(AND(ISNUMBER(D17),ISNUMBER(E17)),E17-D17,"") | K17: =IF(AND(ISNUMBER(D17),ISNUMBER(I17)),I17-D17,"") | L17: =IFERROR(G17-F17,"-") -> 0 | M17: =IFERROR((G17-F17)/F17,"-") -> - | N17: High-perf coatings + standard paint
B18: Selective Demolition — Exterior / Site | C18: DIV 02-DE | H18: =IF(AND(ISNUMBER(D18),ISNUMBER(E18)),E18-D18,"") | K18: =IF(AND(ISNUMBER(D18),ISNUMBER(I18)),I18-D18,"") | L18: =IFERROR(G18-F18,"-") -> 0 | M18: =IFERROR((G18-F18)/F18,"-") -> - | N18: ACT; GWB ceilings; soffits
B19: Hazardous Materials Survey / Testing | C19: DIV 02-HT | H19: =IF(AND(ISNUMBER(D19),ISNUMBER(E19)),E19-D19,"") | K19: =IF(AND(ISNUMBER(D19),ISNUMBER(I19)),I19-D19,"") | L19: =IFERROR(G19-F19,"-") -> 0 | M19: =IFERROR((G19-F19)/F19,"-") -> - | N19: Bathroom accessories; millwork
B20: Hazardous Materials Abatement (ACM/Lead/Mold) | C20: DIV 02-HA | H20: =IF(AND(ISNUMBER(D20),ISNUMBER(E20)),E20-D20,"") | K20: =IF(AND(ISNUMBER(D20),ISNUMBER(I20)),I20-D20,"")
B21: Dewatering / Site Preparation | C21: DIV 02-SP | H21: =IF(AND(ISNUMBER(D21),ISNUMBER(E21)),E21-D21,"") | K21: =IF(AND(ISNUMBER(D21),ISNUMBER(I21)),I21-D21,"") | L21: =IFERROR(G21-F21,"-") -> 0 | M21: =IFERROR((G21-F21)/F21,"-") -> - | N21: Full building in Phase 1A per Program Guide
B22: 1C — Concrete | L22: =IFERROR(G22-F22,"-") -> 0 | M22: =IFERROR((G22-F22)/F22,"-") -> - | N22: Full building; NFPA 72 compliant
B23: Cast-in-Place Concrete — Foundations / Slabs | C23: DIV 03-CF | H23: =IF(AND(ISNUMBER(D23),ISNUMBER(E23)),E23-D23,"") | K23: =IF(AND(ISNUMBER(D23),ISNUMBER(I23)),I23-D23,"") | L23: =IFERROR(G23-F23,"-") -> 0 | M23: =IFERROR((G23-F23)/F23,"-") -> - | N23: Sized for full building future build-out
B24: Concrete Repair / Patching | C24: DIV 03-CR | H24: =IF(AND(ISNUMBER(D24),ISNUMBER(E24)),E24-D24,"") | K24: =IF(AND(ISNUMBER(D24),ISNUMBER(I24)),I24-D24,"") | L24: =IFERROR(G24-F24,"-") -> 0 | M24: =IFERROR((G24-F24)/F24,"-") -> - | N24: Partial area; backbone for Phase 1B tie-in
B25: Precast Concrete Elements | C25: DIV 03-PC | H25: =IF(AND(ISNUMBER(D25),ISNUMBER(E25)),E25-D25,"") | K25: =IF(AND(ISNUMBER(D25),ISNUMBER(I25)),I25-D25,"") | L25: =IFERROR(G25-F25,"-") -> 0 | M25: =IFERROR((G25-F25)/F25,"-") -> - | N25: Scalable panels; risers; branch circuits
B26: 1D — Masonry | L26: =IFERROR(G26-F26,"-") -> 0 | M26: =IFERROR((G26-F26)/F26,"-") -> - | N26: Staff monitoring; access control; data
B27: Masonry — New CMU / Brick | C27: DIV 04-NM | H27: =IF(AND(ISNUMBER(D27),ISNUMBER(E27)),E27-D27,"") | K27: =IF(AND(ISNUMBER(D27),ISNUMBER(I27)),I27-D27,"") | L27: =IFERROR(G27-F27,"-") -> 0 | M27: =IFERROR((G27-F27)/F27,"-") -> - | N27: Structural + enclosure allowance; no cab
B28: Masonry Repair / Repointing | C28: DIV 04-MR | H28: =IF(AND(ISNUMBER(D28),ISNUMBER(E28)),E28-D28,"") | K28: =IF(AND(ISNUMBER(D28),ISNUMBER(I28)),I28-D28,"")
B29: 1E — Metals | L29: =IFERROR(G29-F29,"-") -> 0 | M29: =IFERROR((G29-F29)/F29,"-") -> - | N29: Backstops, bleachers, scoreboard — PENDING
B30: Structural Steel — Framing & Connections | C30: DIV 05-SS | H30: =IF(AND(ISNUMBER(D30),ISNUMBER(E30)),E30-D30,"") | K30: =IF(AND(ISNUMBER(D30),ISNUMBER(I30)),I30-D30,"") | L30: =IFERROR(G30-F30,"-") -> 0 | M30: =IFERROR((G30-F30)/F30,"-") -> - | N30: Wall padding, boxing ring, bag systems
B31: Stairs — Structural Steel / Metal Pan | C31: DIV 05-ST | H31: =IF(AND(ISNUMBER(D31),ISNUMBER(E31)),E31-D31,"") | K31: =IF(AND(ISNUMBER(D31),ISNUMBER(I31)),I31-D31,"") | L31: =IFERROR(G31-F31,"-") -> 0 | M31: =IFERROR((G31-F31)/F31,"-") -> - | N31: OT/PT; sensory room; de-escalation rooms
B32: Miscellaneous Metals — Rails, Lintels, Angles | C32: DIV 05-MM | H32: =IF(AND(ISNUMBER(D32),ISNUMBER(E32)),E32-D32,"") | K32: =IF(AND(ISNUMBER(D32),ISNUMBER(I32)),I32-D32,"") | L32: =IFERROR(G32-F32,"-") -> 0 | M32: =IFERROR((G32-F32)/F32,"-") -> - | N32: Commercial kitchen package — PENDING
B33: Metal Decking | C33: DIV 05-MD | H33: =IF(AND(ISNUMBER(D33),ISNUMBER(E33)),E33-D33,"") | K33: =IF(AND(ISNUMBER(D33),ISNUMBER(I33)),I33-D33,"") | L33: =IFERROR(G33-F33,"-") -> 0 | M33: =IFERROR((G33-F33)/F33,"-") -> - | N33: PA, cameras, access control hardware
B34: 1F — Wood, Plastics & Composites | L34: =IFERROR(G34-F34,"-") -> 0 | M34: =IFERROR((G34-F34)/F34,"-") -> -
B35: Rough Carpentry — Blocking, Nailers, Backing | C35: DIV 06-RC | H35: =IF(AND(ISNUMBER(D35),ISNUMBER(E35)),E35-D35,"") | K35: =IF(AND(ISNUMBER(D35),ISNUMBER(I35)),I35-D35,"")
B36: Finish Carpentry — Millwork & Casework | C36: DIV 06-FC | H36: =IF(AND(ISNUMBER(D36),ISNUMBER(E36)),E36-D36,"") | K36: =IF(AND(ISNUMBER(D36),ISNUMBER(I36)),I36-D36,"") | L36: =IFERROR(G36-F36,"-") -> 0 | M36: =IFERROR((G36-F36)/F36,"-") -> - | N36: 8.0% of base
B37: Architectural Woodwork / Custom Millwork | C37: DIV 06-AW | H37: =IF(AND(ISNUMBER(D37),ISNUMBER(E37)),E37-D37,"") | K37: =IF(AND(ISNUMBER(D37),ISNUMBER(I37)),I37-D37,"") | L37: =IFERROR(G37-F37,"-") -> 0 | M37: =IFERROR((G37-F37)/F37,"-") -> - | N37: 10.0% of base + GC
B38: 1G — Thermal & Moisture Protection | L38: =IFERROR(G38-F38,"-") -> 0 | M38: =IFERROR((G38-F38)/F38,"-") -> - | N38: 12.0% — reduce at SD, DD, GMP
B39: Roofing — Membrane System (TPO/EPDM/BUR) | C39: DIV 07-RF | H39: =IF(AND(ISNUMBER(D39),ISNUMBER(E39)),E39-D39,"") | K39: =IF(AND(ISNUMBER(D39),ISNUMBER(I39)),I39-D39,"") | L39: =IFERROR(G39-F39,"-") -> 0 | M39: =IFERROR((G39-F39)/F39,"-") -> - | N39: 12.0% — pre-1980 building; reduce after hazmat survey
B40: Roof Insulation & Cover Board | C40: DIV 07-RI | H40: =IF(AND(ISNUMBER(D40),ISNUMBER(E40)),E40-D40,"") | K40: =IF(AND(ISNUMBER(D40),ISNUMBER(I40)),I40-D40,"") | L40: =IFERROR(G40-F40,"-") -> 0 | M40: =IFERROR((G40-F40)/F40,"-") -> - | N40: 5.0% — reduce as equipment selections confirmed
B41: Wall Insulation (Batt / Rigid / Spray) | C41: DIV 07-WI | H41: =IF(AND(ISNUMBER(D41),ISNUMBER(E41)),E41-D41,"") | K41: =IF(AND(ISNUMBER(D41),ISNUMBER(I41)),I41-D41,"") | L41: =IFERROR(G41-F41,"-") -> 0 | M41: =IFERROR((G41-F41)/F41,"-") -> - | N41: 2.0% of total
...

Sheet VARIANCE LOG
B1: VARIANCE LOG — Cost Changes Requiring Documentation
B2: Any variance >5% between estimate columns must be documented here before the next ALDi gate is cleared.
B4: Line Item / Budget Category | C4: Gate | D4: ROM Amt ($) | E4: New Est. Amt ($) | F4: Var ($) | G4: Var (%) | H4: Status | I4: Root Cause & Resolution | J4: Approved By
B5: Existing Conditions Contingency — higher than ROM | C5: Gate 2 | D5: 347000 | E5: 420000 | F5: 73,000 | G5: 21.0% | H5: Approved | I5: Hazmat survey confirmed asbestos in 3 locations. Abatement scope added. Owner approved $73K increase. | J5: T. Maxwell / M4Di
B6: HVAC — Phase 1A scope expanded per DDDS requirements | C6: Gate 2 | D6: 310000 | E6: 365000 | F6: 55,000 | G6: 17.7% | H6: Watch | I6: DDDS licensing pre-app required supplemental ventilation for clinical areas. Engineering confirmed scope. | J6: Pending owner
B7: [Next Variance Item — enter as identified] | H7: On Track

Sheet CHANGE ORDER LOG
B1: CHANGE ORDER LOG — ALDi Gate 3–4
B2: All changes to the contracted GMP/SOV (Column F) must be logged here. Actual Cost (Column G) = Column F + approved COs below.
B4: CO # | C4: Description | D4: Date | E4: GC Amount ($) | F4: Owner Cost ($) | G4: Cumulative COs ($) | H4: CO Running % of GMP | I4: Status | J4: Category | K4: Notes / Justification
B5: CO-001 | C5: Hazardous Materials Abatement — Phase 1 (asbestos, 3 locations) | D5: 04/15/2026 | E5: 73000 | F5: 0 | G5: 73000 | H5: 2.1% | I5: Approved | J5: Existing Conditions | K5: Required; covered by existing conditions contingency draw
B6: CO-002 | C6: Additional HVAC ductwork — DDDS ventilation compliance | D6: 05/01/2026 | E6: 55000 | F6: 0 | G6: 128000 | H6: 3.7% | I6: Pending | J6: Regulatory | K6: DDDS licensing requirement; pending owner authorization
B7: [Future CO — enter as issued] | I7: Pending
B9: TOTAL APPROVED COs | E9: =SUM(F5:F7) -> 0

Sheet DRAW SCHEDULE
B1: FUNDING DRAW SCHEDULE — Budget vs. Actual Spend
B2: Track each funding source draw against actual project expenditures. Updated monthly with each pay application.
B4: Funding Source | C4: Total Committed ($) | D4: Draw 1 ($) | E4: Draw 2 ($) | F4: Draw 3 ($) | G4: Draw 4 ($) | H4: Draw 5 ($) | I4: Total Drawn ($) | J4: Remaining ($) | K4: % Drawn
B5: Owner / Developer Equity (Dr. Maxwell) | C5: 2500000 | I5: =SUM(D5:H5) -> 0 | J5: =C5-I5 -> 2500000 | K5: =IFERROR(I5/C5,0) -> 0
B6: CDFI Construction Loan (NCALL) | C6: 3500000 | I6: =SUM(D6:H6) -> 0 | J6: =C6-I6 -> 3500000 | K6: =IFERROR(I6/C6,0) -> 0
B7: HUD CDBG Grant | C7: 750000 | I7: =SUM(D7:H7) -> 0 | J7: =C7-I7 -> 750000 | K7: =IFERROR(I7/C7,0) -> 0
B8: Delaware DDDS Capital Support | C8: 500000 | I8: =SUM(D8:H8) -> 0 | J8: =C8-I8 -> 500000 | K8: =IFERROR(I8/C8,0) -> 0
B9: Philanthropic Grants (Longwood / Welfare Fdn) | C9: 750000 | I9: =SUM(D9:H9) -> 0 | J9: =C9-I9 -> 750000 | K9: =IFERROR(I9/C9,0) -> 0
B10: Owner Contingency Reserve (escrowed) | C10: 300000 | I10: =SUM(D10:H10) -> 0 | J10: =C10-I10 -> 300000 | K10: =IFERROR(I10/C10,0) -> 0
B11: TOTAL FUNDING | C11: =SUM(C5:C10) -> 8300000 | D11: =SUM(D5:D10) -> 0 | E11: =SUM(E5:E10) -> 0 | F11: =SUM(F5:F10) -> 0 | G11: =SUM(G5:G10) -> 0 | H11: =SUM(H5:H10) -> 0 | I11: =SUM(I5:I10) -> 0 | J11: =SUM(J5:J10) -> 8300000 | K11: =SUM(K5:K10) -> 0

Sheet GATE DASHBOARD
B1: ALDi GATE DASHBOARD — Project Status Summary
B2: One-page project status for owner, AE, and lender reporting. Update at each gate.
B4: Project | C4: =COVER!C4 -> 0
B5: Owner | C5: =COVER!C6 -> 0
B6: AE | C6: =COVER!C7 -> 0
B7: M4Di Lead | C7: =COVER!C8 -> 0
B8: Building SF | C8: =COVER!C9 -> 0
B9: ALDi Start | C9: =COVER!C10 -> 0
B10: M4Di ROM (Locked Baseline) | C10: ='BUDGET TRACKER'!D80 -> 0
B11: 75% DD Estimate | C11: ='BUDGET TRACKER'!E80 -> 0
B12: 100% CD / GMP (Contracted) | C12: ='BUDGET TRACKER'!F80 -> 0
B13: Actual Cost to Date | C13: ='BUDGET TRACKER'!G80 -> 0
B14: GC Quote Total (pre-SOV) | C14: ='BUDGET TRACKER'!I171 -> 0
B15: GC Actuals to Date | C15: ='BUDGET TRACKER'!J171 -> 0
B16: ROM vs. GC Quote Variance | C16: ='BUDGET TRACKER'!K171
B17: ALDi GATE STATUS
B18: Gate | C18: Name | D18: Target Date | E18: Actual Date | F18: Status | G18: Budget Check | H18: Key Conditions / Notes
B19: Gate 0 | C19: Controls Setup + Budget Baseline Lock | F19: In Progress | G19: ROM Locked | H19: Project charter issued. Budget baseline = Column D. Procurement calendar set.
B20: Gate 1 | C20: Schematic Design Review | F20: Pending | G20: Target ±15% | H20: SD documents reviewed. Constructability input provided. DDDS pre-app status confirmed.
B21: Gate 2 | C21: Design Development + 75% DD Estimate | F21: Pending | G21: Column E entered | H21: DD estimate entered in Column E. Variance log updated. Owner contingency reviewed.
B22: Gate 3 | C22: GMP Execution + SOV Entry | F22: Pending | G22: Column F = GMP | H22: Contractor SOV entered in Column F. GMP executed. Financing closed.
B23: Gate 4 | C23: Construction Controls + Closeout | F23: Pending | G23: Column G current | H23: Monthly actual cost updates. CO log maintained. HISTORICAL DB row completed.

Sheet STRATEGY MEMO
B1: M4Di STRATEGY MEMO — The ALDi Budget Tracker as a Revenue Growth Engine
B3: WHAT THIS TOOL IS
B4: The ALDi Design & Construction Budget Tracker is M4Di’s most direct revenue-generating product after the P1–P3 feasibility packages. Where the OI Tool establishes credibility at the predevelopment stage, the Tracker sustains M4Di’s role — and M4Di’s fees — through the full design and construction lifecycle of every project. This memo outlines the strategic case for how M4Di positions, prices, and grows this product.
B6: THE CORE VALUE PROPOSITION
B7: Every AE firm has a fee agreement. Every contractor has a schedule of values. Every owner has a checkbook. What none of them has is a single document that ties all three to the original feasibility estimate and tracks variance across the full project life. That gap is exactly what this Tracker fills — and it is a gap that costs project owners real money every time a design decision quietly moves the budget without anyone’s explicit awareness.
B8: M4Di owns this Tracker. M4Di controls it. The AE and contractor provide inputs at defined gate milestones; M4Di synthesizes, interprets, and reports. This is not an administrative function — it is the delivery backbone that the M4Di strategy describes as ALDi. The Tracker is the physical artifact of that backbone.
B10: THE FOUR-COLUMN ARCHITECTURE IS THE PRODUCT
B11: The four columns — ROM, 75% DD, 100% CD/SOV, Actual — are not an accident of format. They are the intellectual property. Each column transition is a gate event where M4Di adds specific, billable value:
B12: ▶ Gate 0 → Column D locked M4Di establishes the baseline. No one can move the ROM without going through M4Di. This is leverage — the ROM is the anchor against which every subsequent decision is measured.
B13: ▶ Gate 2 → Column E entered M4Di reviews the 75% DD estimate from the AE. If it exceeds Column D by more than 15%, M4Di flags it, investigates the cause, and either documents a scope-driven explanation or pushes back on the design team. This review function is not available to any other party because only M4Di holds the original takeoff assumptions.
B14: ▶ Gate 3 → Column F = GMP M4Di reviews the contractor SOV against Column D. M4Di identifies any scope that was added during design but not authorized through the ALDi gate process. This review catches overruns before they become change orders.
B15: ▶ Gate 4 → Column G updated monthly M4Di maintains the running actual cost total from contractor pay applications and owner direct costs. M4Di is the single source of truth for how much has been spent, how much remains, and how the project tracks against the original feasibility commitment.
... B34: TEMPLATE VERSION NOTE — This is the M4Di Generic CSI Template v1.0 (April 2026). Built to MasterFormat division structure with subcategories for high-cost divisions. Gray rows = divisions rarely applicable — leave blank rather than delete. Columns I–K are the GC/Contractor mirror columns (Quote + Actuals). Populate project-specific data in COVER tab. ROM values in Column D are locked at Gate 0.
