Workbook

Sheet 00_INSTRUCTIONS
B1: M4Di™ MASTER CODE & LIFE SAFETY WORKBOOK — INSTRUCTIONS
B2: Merge 4 Design LLC | Aubyn Architecture LLC | 215 N Market St Ste 317, Wilmington DE 19801
B4: COLOR KEY
B5: 🟡 YELLOW cells | C5: INPUT — enter data here. Blue text = hardcoded input. Adjust for each project.
B6: 🔵 BLUE cells | C6: FORMULA OUTPUT — do not edit. Recalculates automatically.
B7: ⬜ GREY cells | C7: LABEL — section headers, field names. Do not edit.
B8: 🟢 GREEN cells | C8: PASS / within limits
B9: 🔴 RED cells | C9: FAIL / exceeds limits — requires resolution before permit submittal
B11: TAB GUIDE
B12: 00_INSTRUCTIONS | C12: This sheet. Read before using.
B13: 01_PROJECT_ID | C13: Project name, address, jurisdiction, code edition, ALDi gate. Start here every project.
B14: 02_ZONING | C14: Zoning district inputs: FAR, coverage, setbacks, height. Frontage increase calculator built in.
B15: 03_IBC_AREA_HEIGHT | C15: IBC §504/506/508 — occupancy, construction type, height/area compliance with formula checks.
B16: 04_FIRE_PROTECTION | C16: Fire resistance rating matrix by building element (Table 601/602). Separation distance checks.
B17: 05_LIFE_SAFETY_IBC | C17: Commercial/institutional egress analysis — occupant load, exit count, travel distance.
B18: 06_LIFE_SAFETY_IRC | C18: Residential (IRC) — smoke alarms, egress windows, stair geometry, garage separation.
B19: 07_ACCESSIBILITY | C19: ADA / ICC A117.1 — accessible route, parking, fixtures, Type A/B dwelling unit counts.
B20: 08_PLUMBING_CALC | C20: IPC Table 403.1 fixture calculator — auto-calculates from occupant load. Editable ratios.
B21: 09_ENERGY_CODE | C21: IECC climate zone, compliance path, envelope values (prescriptive / REScheck / COMcheck).
B22: 10_STRUCTURAL | C22: Design load parameters, seismic/wind, risk category, special inspections list.
B23: 11_CODE_BLOCK | C23: Auto-generated uppercase code summary text block — copy/paste to Sheet A-001.
... B26: 14_AMENDMENTS | C26: Local amendment registry — jurisdiction-specific overrides by code section.
B28: WORKFLOW
B29: Step 1 | C29: Open 01_PROJECT_ID. Fill all yellow cells. Select jurisdiction from dropdown.
B30: Step 2 | C30: Open 14_AMENDMENTS. Verify any local overrides for this jurisdiction are logged.
B31: Step 3 | C31: Open 02_ZONING. Enter lot/zoning data. Confirm derived GFA values.
B32: Step 4 | C32: Open 03_IBC_AREA_HEIGHT. Select occupancy + construction type. Review pass/fail flags.
B33: Step 5 | C33: Complete 04 through 10 in order. Flag any fails and log in 13_FLAGS.
B34: Step 6 | C34: Open 11_CODE_BLOCK. Copy the auto-generated text block to your drawing set.
B35: Step 7 | C35: Complete 12_REVIEW_PROTOCOL sign-off at the appropriate ALDi gate.
B37: ICC UPDATE PROTOCOL
B38: When IBC/IRC/IPC edition changes: | C38: Update 14_AMENDMENTS with new edition. Update OLF_Library on 05/06 if factors change. Revise plumbing ratios on 08 per new IPC Table 403.1. All formulas reference named ranges — no sheet restructuring needed for minor updates.
B40: FOR NON-PROFESSIONALS
B41: Rule 1 | C41: Only fill YELLOW cells. Never edit blue or grey cells.
B42: Rule 2 | C42: If a cell turns RED, stop and flag for licensed professional review before proceeding.
B43: Rule 3 | C43: Document every source URL in the 14_AMENDMENTS tab when you look up a code value.
B44: Rule 4 | C44: Never override a formula output — create a new input cell if a value needs to change.
B45: 16_MULTI_OCCUPANCY | C45: §508.4.2 story-by-story ratio calculator with IBC Table 506.2 reference values. Aggregate sum check for NS (≤3) and S (≤4).
B46: 17_MECHANICAL | C46: IMC requirements + ASHRAE 62.1 ventilation calc + exhaust sizing table + combustion air + mechanical plan review checklist + load quick-calc.

Sheet 01_PROJECT_ID
B1: 01 — PROJECT IDENTIFICATION
B2: Complete this tab first. All other tabs reference these values.
B4: Project Name
B5: Project Number | D5: e.g., M2_2026_010
B6: Project Address | D6: Street, City, State, ZIP
B7: Client / Owner
B8: Date of Analysis | D8: MM/DD/YYYY
B9: Prepared By | D9: Name + Firm
B10: AOR — Architect of Record
B12: JURISDICTION & CODE
B13: Jurisdiction (City/County) | D13: e.g., City of Wilmington, DE
B14: AHJ — Authority Having Jurisdiction
B15: Zoning Ordinance URL | D15: Paste link — verify annually
B16: IBC Edition in Use | C16: 2021 | D16: 2021 / 2018 / 2015 / Local
B17: IRC Edition (Residential) | C17: 2021 | D17: 2021 / 2018 / 2015
B18: IPC Edition (Plumbing) | C18: 2021 | D18: 2021 / 2018
B19: IECC Edition (Energy) | C19: 2021
B20: NEC Edition (Electrical) | C20: 2020
B21: Local Amendments Active? | C21: Yes | D21: Yes / No — see 14_AMENDMENTS
B23: PROJECT TYPE & GATE
B24: Project Type | C24: Commercial | D24: Commercial / Residential / Mixed-Use / Institutional
B25: New / Addition / Alteration / Change of Use | C25: New Construction
B26: ALDi Gate at This Analysis | C26: G0 — ROM | D26: G0 ROM / G1 Feasibility / G2 75%DD / G3 GMP
B28: FIRM ASSIGNMENT
B29: Lead Firm | C29: Merge 4 Design LLC | D29: M4D / Aubyn Architecture
B30: AOR License State(s) | D30: DE / PA / CT
B31: Subconsultants (generic) | C31: Civil Engineer; Structural Engineer; MEP Engineer | D31: Do not name unless confirmed
B32: AMENDMENT CHECK
B33: Amendments logged for selected jurisdiction: | C33: =COUNTIF('14_AMENDMENTS'!B:B,C10)&" row(s) found in 14_AMENDMENTS — review before permit" -> 0 row(s) found in 14_AMENDMENTS — review before permit

Sheet 02_ZONING
B1: 02 — ZONING & SITE COMPLIANCE
B2: PARAMETER | C2: REQUIRED / ALLOWED | D2: PROVIDED / ACTUAL | E2: PASS/FAIL | F2: CODE REF / NOTES
B3: ZONING INPUTS
B4: Zoning District / Zone Label
B5: UDC Source URL | D5: Paste link
B6: Lot Area (SF) | C6: 43,560
B7: Maximum FAR | C7: 2.0
B8: Max Lot Coverage (%) | C8: 60%
B9: Front Setback (ft) | C9: 10
B10: Side Setback (ft) | C10: 5
B11: Rear Setback (ft) | C11: 20
B12: Max Building Height (ft) | C12: 60
B13: Max Stories (Zoning) | C13: 5
B14: Typical Floor-to-Floor (ft) | C14: 12
B15: DERIVED ZONING CAPACITY
B16: GFA by FAR (SF) | C16: =C17*C20 | E16: =IF(D16>C16,"FAIL","PASS") | F16: FAR × Lot Area
B17: GFA by Coverage (SF) | C17: =C18*C17 | F17: Coverage × Lot Area × Stories
B18: Max Stories by Height | C18: =INT(C24/C25) -> #DIV/0! | F18: Height ÷ Floor-to-Floor
B19: ZONING-ALLOWED GFA (SF) | C19: =MIN(C29,C30) -> 0 | F19: Controlling (lower of FAR, Coverage)
B20: FRONTAGE INCREASE (IBC §506.3)
B21: F — Qualifying Perimeter (ft) | C21: 0
B22: P — Total Perimeter (ft) | C22: 0
B23: W — Avg Open Width (ft, max 30) | C23: 30
B24: If = ((F/P)−0.25)×(W/30) | C24: =MAX(0,MIN(0.75,(C36/C37-0.25)*(C38/30))) -> #DIV/0! | F24: Capped 0–0.75 per §506.3
B25: ADU PERMITTED? | C25: Yes / No / Conditional
B26: Off-Street Parking Required (spaces)
B27: Off-Street Parking Provided
B28: Parking Compliance | D28: =IF(D43>=C43,"PASS","FAIL") -> PASS

Sheet 03_IBC_AREA_HEIGHT
B1: 03 — IBC AREA, HEIGHT & OCCUPANCY COMPLIANCE (§504 / §506 / §508)
B2: PARAMETER | C2: TABULAR (CODE) | D2: ACTUAL (DESIGN) | E2: PASS/FAIL | F2: NOTES / CODE REF
B3: OCCUPANCY & CONSTRUCTION
B4: Primary Occupancy Group (Ch. 3) | D4: e.g., B, R-2, A-3, I-2
B5: Secondary Occupancy Group (if mixed)
B6: Mixed Occupancy Method (§508) | D6: Accessory / Non-Sep / Separated
B7: Construction Type (Ch. 6) | D7: I-A / II-B / III-A / V-B etc.
B8: Sprinkler System | D8: None / NFPA 13 / NFPA 13R / 13D
B9: Risk Category (Table 1604.5) | D9: I / II / III / IV
B10: HEIGHT & STORIES
B11: Allowable Height — Feet (Table 504.3) | E11: =IF(D12<=C12,"PASS","FAIL") -> PASS | F11: Enter from IBC Table 504.3 for occ/const type
B12: Allowable Height — Stories (Table 504.4) | E12: =IF(D13<=C13,"PASS","FAIL") -> PASS | F12: Enter from IBC Table 504.4
B13: Actual Building Height (ft)
B14: Actual Stories Above Grade
B15: AREA CALCULATIONS (§506)
B16: At — Tabular Area, Non-Sprinklered (SF) | D16: From IBC 2021 Table 506.2
B17: NS — Tabular Sprinkler Increase (SF) | D17: From IBC 2021 Table 506.2
B18: If — Frontage Increase (from 02_ZONING) | C18: ='02_ZONING'!C39 -> 0 | F18: Linked from Zoning tab
B19: Number of Stories Above Grade (Sa, max 3 or 4)
B20: Aa per Story = (At + NS×If) | C20: =C17+(C18*C19) -> 0 | F20: Single-occ formula §506.2.1
B21: Total Allowable Area = Aa × Sa | C21: =C22*C21 | F21: Multi-story §506.2.3
B22: Actual Total Building Area (SF)
B23: Actual Area per Story (SF, largest)
B24: COMPLIANCE CHECK
B25: Area per Story vs. Allowable per Story | C25: =C22 -> 0 | D25: ='03_IBC_AREA_HEIGHT'!D26 -> 0 | E25: =IF(D28<=C28,"PASS","FAIL") -> PASS
B26: Total Building Area vs. Total Allowable | C26: =C23 -> 0 | D26: ='03_IBC_AREA_HEIGHT'!D24 -> 0 | E26: =IF(D29<=C29,"PASS","FAIL") -> PASS
B27: Height (ft) vs. Allowable | C27: =C9 -> 0 | D27: ='03_IBC_AREA_HEIGHT'!D11 -> 0 | E27: =IF(D30<=C30,"PASS","FAIL") -> PASS
B28: Stories vs. Allowable | C28: =C10 -> 0 | D28: ='03_IBC_AREA_HEIGHT'!D12 -> 0 | E28: =IF(D31<=C31,"PASS","FAIL") -> PASS
B29: MIXED OCCUPANCY — SEPARATION RATIOS (§508.4.2)
B30: Occupancy A: Actual / Allowable Ratio | F30: Enter manually or from Multi_Occ sheet
B31: Occupancy B: Actual / Allowable Ratio
B32: Sum of Ratios (must be ≤ 1.00 per story) | E32: =IF(D34+D35<=1,"PASS","FAIL") -> PASS | F32: §508.4.2

Sheet 04_FIRE_PROTECTION
B1: 04 — FIRE PROTECTION & RATING REQUIREMENTS (IBC TABLE 601 / 602)
B2: BUILDING ELEMENT | C2: FIRE SEP (FT) | D2: RATING REQ'D (HRS) | E2: RATING PROVIDED | F2: DETAIL / SHEET REF | G2: CODE REF
B3: BUILDING ELEMENT RATINGS — IBC TABLE 601 & 602
B4: Structural Frame (columns, girders, trusses)
B5: Bearing Walls — Exterior (North)
B6: Bearing Walls — Exterior (South)
B7: Bearing Walls — Exterior (East)
B8: Bearing Walls — Exterior (West)
B9: Bearing Walls — Interior
B10: Nonbearing Walls — Exterior (all faces)
B11: Nonbearing Walls / Partitions — Interior
B12: Floor Construction (incl. beams & joists)
B13: Floor/Ceiling Assembly
B14: Roof Construction (incl. beams & joists)
... B27: PERCENTAGE OF WALL OPENINGS — IBC TABLE 705.8
B28: WALL FACE | C28: FIRE SEP DIST (FT) | D28: OPENINGS ALLOWED (%) | E28: OPENINGS PROVIDED (%) | F28: PASS/FAIL | G28: NOTES
B29: North | F29: =IF(E29<="","-",IF(E29<=D29,"PASS","FAIL")) -> -
B30: South | F30: =IF(E30<="","-",IF(E30<=D30,"PASS","FAIL")) -> -
B31: East | F31: =IF(E31<="","-",IF(E31<=D31,"PASS","FAIL")) -> -
B32: West | F32: =IF(E32<="","-",IF(E32<=D32,"PASS","FAIL")) -> -
B33: LIFE SAFETY SYSTEM REQUIREMENTS
B34: SYSTEM | C34: REQUIRED? | D34: PROVIDED? | E34: TYPE/STANDARD | F34: PASS/FAIL | G34: NOTES
B35: Fire Sprinkler System | E35: NFPA 13 / 13R / 13D | F35: =IF(C35="No","-",IF(D35="Yes","PASS","FAIL")) -> FAIL
B36: Fire Alarm System | E36: Manual / Automatic / Addressable | F36: =IF(C36="No","-",IF(D36="Yes","PASS","FAIL")) -> FAIL
B37: Emergency Voice/Alarm Communication | F37: =IF(C37="No","-",IF(D37="Yes","PASS","FAIL")) -> FAIL
B38: Emergency Lighting (§1008.3) | F38: =IF(C38="No","-",IF(D38="Yes","PASS","FAIL")) -> FAIL
B39: Exit Signs (§1013) | F39: =IF(C39="No","-",IF(D39="Yes","PASS","FAIL")) -> FAIL
B40: Carbon Monoxide Detection | F40: =IF(C40="No","-",IF(D40="Yes","PASS","FAIL")) -> FAIL
B41: Smoke Control System (§909) | E41: If applicable | F41: =IF(C41="No","-",IF(D41="Yes","PASS","FAIL")) -> FAIL

Sheet 05_LIFE_SAFETY_IBC
B1: 05 — LIFE SAFETY & EGRESS ANALYSIS — COMMERCIAL / IBC (§1004 / §1006 / §1017)
B2: OCCUPANT LOAD CALCULATION — PER ZONE/SPACE (IBC §1004 / Table 1004.5)
B3: ZONE / AREA NAME | C3: USE / OCC GROUP | D3: AREA (SF) | E3: OLF (SF/PERSON) | F3: OCC LOAD (PERSONS)
B4: Zone 1 | F4: =IF(OR(D4="",E4=""),"-",CEILING(D4/E4,1)) -> -
B5: Zone 2 | F5: =IF(OR(D5="",E5=""),"-",CEILING(D5/E5,1)) -> -
B6: Zone 3 | F6: =IF(OR(D6="",E6=""),"-",CEILING(D6/E6,1)) -> -
B7: Zone 4 | F7: =IF(OR(D7="",E7=""),"-",CEILING(D7/E7,1)) -> -
B8: Zone 5 | F8: =IF(OR(D8="",E8=""),"-",CEILING(D8/E8,1)) -> -
B9: Zone 6 | F9: =IF(OR(D9="",E9=""),"-",CEILING(D9/E9,1)) -> -
B10: Zone 7 | F10: =IF(OR(D10="",E10=""),"-",CEILING(D10/E10,1)) -> -
B11: Zone 8 | F11: =IF(OR(D11="",E11=""),"-",CEILING(D11/E11,1)) -> -
B12: TOTAL DESIGN OCCUPANT LOAD (largest floor) | F12: =SUM(F4:F11) -> 0
B14: EGRESS COMPLIANCE CHECKS (IBC Ch. 10)
B15: PARAMETER | C15: REQUIRED (CODE) | D15: PROVIDED | E15: PASS/FAIL | F15: IBC SECTION
B16: Number of Exits Required (§1006) | F16: §1006.2.1 — 2 exits if OL>49
B17: Number of Exits Provided | E17: =IF(D17>=C17,"PASS","FAIL") -> PASS
B18: Minimum Exit Width (inches) — §1005 | E18: =IF(D18>=C18,"PASS","FAIL") -> PASS | F18: §1005.1
B19: Min Corridor Width (inches) — §1020.2 | C19: 44 | E19: =IF(D19>=C19,"PASS","FAIL") -> FAIL | F19: 44" min / 72" Group E
B20: Min Stair Width (inches) — §1011.2 | C20: 44 | E20: =IF(D20>=C20,"PASS","FAIL") -> FAIL | F20: §1011.2
B21: Min Door Clear Width (inches) — §1010.1.1 | C21: 32 | E21: =IF(D21>=C21,"PASS","FAIL") -> FAIL | F21: §1010.1.1
B22: Max Exit Access Travel Distance (ft) — §1017.2 | E22: =IF(D22<=C22,"PASS","FAIL") -> PASS | F22: Enter per occ group
B23: Max Common Path of Travel (ft) — §1006.2.1 | E23: =IF(D23<=C23,"PASS","FAIL") -> PASS
B24: Max Dead-End Corridor (ft) — §1020.4 | C24: 20 | E24: =IF(D24<=C24,"PASS","FAIL") -> PASS | F24: 20" max (no sprinkler)
B25: Panic Hardware — Required? (§1010.1.10) | F25: A/E occ ≥50 persons
B26: Emergency Lighting Provided — §1008.3
B27: Exit Signs Provided — §1013
B28: Life Safety Plan Sheet #

Sheet 06_LIFE_SAFETY_IRC
B1: 06 — LIFE SAFETY CHECKLIST — RESIDENTIAL / IRC 2021
B2: LIFE SAFETY REQUIREMENT | C2: STATUS (Y/N/N/A) | D2: NOTES / IRC SECTION
B3: SMOKE & CO DETECTION
B4: Smoke alarm in every sleeping room (R314.3) | C4: Y / N / N/A
B5: Smoke alarm outside each sleeping area on each level (R314.3)
B6: Smoke alarms interconnected (R314.4) | D6: Hardwired or wireless
B7: CO detector required — fuel-burning appliances or attached garage (R315.1)
B8: CO detector outside each sleeping area (R315.3)
B9: Battery backup provided for all alarms
B10: EGRESS & EMERGENCY ESCAPE
B11: Emergency escape openings in each sleeping room below 4th story (R310)
B12: Min. 5.7 SF net clear opening (R310.2.1)
B13: Min. 24" clear opening height (R310.2.2)
B14: Min. 20" clear opening width (R310.2.3)
B15: Max. 44" sill height AFF (R310.2.4)
B16: Egress door: min 32" clear width, 78" height at main egress (R311.2)
B17: Clear egress path from all sleeping rooms to exterior
B18: STAIRS, GUARDS & HANDRAILS
... B27: Garage/dwelling separation: 5/8" Type X GWB on garage side (R302.6)
B28: Townhouse party wall: 2-hour fire resistance, continuous (R302.2) | D28: If applicable
B29: Openings in party wall: protected (R302.2.4) | D29: If applicable
B30: ATTIC / CRAWLSPACE
B31: Attic access: min 22"x30" opening (R807.1) | D31: If used for storage/mech
B32: Crawlspace access: min 18"x24" (R408.4) | D32: If applicable
B33: GLAZING
B34: Safety glazing at tubs/showers, doors, sidelights (R308.4)
B35: Safety glazing within 24" of door edge (R308.4.2)

Sheet 07_ACCESSIBILITY
B1: 07 — ACCESSIBILITY — ADA / ICC A117.1 / IBC CH. 11
B2: ACCESSIBILITY REQUIREMENT | C2: STATUS (Y/N/N/A) | D2: COMPLIANT? | E2: IBC / SECTION
B3: ACCESSIBLE ROUTE
B4: Accessible route from public way to all building entrances (§1104) | E4: §1104.1
B5: All entrances accessible OR exemptions documented (§1105) | E5: §1105.1
B6: Accessible path through all public/common areas (§1104)
B7: ACCESSIBLE PARKING (§1106)
B8: Total parking spaces on lot
B9: Required accessible spaces (§1106.1) | E9: 1 per 25 up to 100
B10: Van spaces with 132" access aisle provided (§1106.4) | E10: Min. 1 van space
B11: Accessible spaces provided
B12: ACCESSIBLE RESTROOMS (ICC A117.1)
B13: Accessible WC clearances per A117.1 §603 | E13: 60" min turn space
B14: Grab bar blocking provided (A117.1 §604.5)
B15: Lavatory height and clearance (A117.1 §606)
B16: Accessible signage — Braille + raised characters (§1111)
B17: VERTICAL ACCESSIBILITY (§1109.7)
B18: Elevator provided (required if >2 stories or >3,000 SF/floor) | E18: §1109.7
B19: Platform lift (if allowed in lieu of elevator) (§1109.8)
B20: Ramps: max 1:12 slope, handrails both sides (§1010.1) | E20: If applicable
B21: DWELLING UNIT ACCESSIBILITY (§1107)
B22: Project triggers Fair Housing Act? (≥4 units)
B23: Type A Units Required (§1107.7.2) | E23: Enter count
B24: Type A Units Provided
B25: Type B Units Required (§1107.7.1.2) | E25: Enter count
B26: Type B Units Provided
B27: ACCESSIBLE SERVICE ELEMENTS
B28: Accessible drinking fountains per §1109.5 (hi/lo)
B29: Accessible service counters per §1109.12
B30: Accessible seating (assembly) per §1108.2 | E30: If applicable

Sheet 08_PLUMBING_CALC
B1: 08 — PLUMBING FIXTURE CALCULATOR — IPC 2021 TABLE 403.1
B2: Ratios are editable (yellow). Update for local IPC amendments. Reference: buildingcode.blog/plumbing-fixture-calculator.html
B3: INPUTS
B4: Total Design Occupant Load (from 05_LIFE_SAFETY_IBC) | C4: ='05_LIFE_SAFETY_IBC'!F12 -> 0 | D4: OR override: | F4: =IF(E4<>"",E4,C4) -> 0 | G4: F4 = used occupant load
B5: Male/Female Split (% male) | C5: 0.5 | D5: =1-C5 -> 0.5 | E5: Default 50/50
B6: Male Occupant Load | C6: =ROUND(F4*C5,0) -> 0 | D6: =ROUND(F4*D5,0) -> 0 | E6: Female Occupant Load
B8: FIXTURE RATIOS — EDITABLE (IPC TABLE 403.1 defaults — update per AHJ / local amendment)
B9: OCCUPANCY | C9: WC (M) ratio | D9: WC (F) ratio | E9: LAV ratio (M) | F9: LAV ratio (F) | G9: DF ratio
B10: B — Business / Office | C10: 100 | D10: 100 | E10: 100 | F10: 100 | G10: 500
B11: A-3 — Assembly (unconc.) | C11: 125 | D11: 65 | E11: 200 | F11: 200 | G11: 1000
B12: A-2 — Assembly (dining) | C12: 75 | D12: 75 | E12: 200 | F12: 200 | G12: 500
B13: E — Educational | C13: 50 | D13: 50 | E13: 50 | F13: 50 | G13: 100
B14: I-2 — Institutional (hospital) | C14: 1 | D14: 1 | E14: 1 | F14: 1 | G14: 100
B15: M — Mercantile | C15: 500 | D15: 500 | E15: 750 | F15: 750 | G15: 1000
B16: R-2 — Residential (per DU) | C16: 1 | D16: 1 | E16: 1 | F16: 1 | G16: 1
B17: S — Storage / Warehouse | C17: 100 | D17: 100 | E17: 100 | F17: 100 | G17: 1000
B19: CALCULATED REQUIREMENTS — SELECT OCCUPANCY ROW
B20: Selected Occupancy Row # (enter 1–8) | C20: 1 | D20: Matches rows above (1=B/Office, 2=A-3, etc.)
B21: FIXTURE | C21: RATIO USED | D21: MALE LOAD | E21: FEMALE LOAD | F21: REQUIRED | G21: PROVIDED
B22: Water Closets (Male) | C22: =INDEX(C10:C17,C20) -> 100 | D22: =C6 -> 0 | F22: =CEILING(D22/C22,1) -> 0
B23: Water Closets (Female) | C23: =INDEX(D10:D17,C20) -> 100 | E23: =D6 -> 0 | F23: =CEILING(E23/C23,1) -> 0
B24: Lavatories (Male) | C24: =INDEX(E10:E17,C20) -> 100 | D24: =C6 -> 0 | F24: =CEILING(D24/C24,1) -> 0
B25: Lavatories (Female) | C25: =INDEX(F10:F17,C20) -> 100 | E25: =D6 -> 0 | F25: =CEILING(E25/C25,1) -> 0
B26: Drinking Fountains | C26: =INDEX(G10:G17,C20) -> 500 | D26: =F4 -> 0 | F26: =CEILING(D26/C26,1) -> 0
B27: ⚠ Verify ratios against IPC 2021 Table 403.1 and local amendments. Urinals may sub for up to 67% of male WC requirement.

Sheet 09_ENERGY_CODE
B1: 09 — ENERGY CODE COMPLIANCE — IECC 2021 / ASHRAE 90.1
B3: ENERGY CODE INPUTS
B4: Climate Zone | C4: 4A | D4: 4A = DE/PA/MD/NJ typical — verify AHJ
B5: Compliance Method | C5: Prescriptive | D5: Prescriptive / Performance / ASHRAE 90.1 / REScheck
B6: Energy Calcs Stamped by Design Professional? | C6: Yes | D6: Required for permit
B7: COMMERCIAL ENVELOPE (IECC C402 / COMcheck)
B8: Roof/Ceiling Assembly Description
B9: Roof U-Value (max) | D9: Check IECC Table C402.1.3
B10: Roof R-Value (insulation)
B11: Exterior Wall Description
B12: Exterior Wall U-Value (max)
B13: Exterior Wall R-Value
B14: Glazing U-Factor (max)
B15: Glazing SHGC (max)
B16: COMMERCIAL ADDITIONAL EFFICIENCY (C406)
B17: C406.2 More Efficient HVAC Equipment | C17: No | D17: Yes / No
B18: C406.3 Reduced Lighting Power Density | C18: No
B19: C406.4 Enhanced Digital Lighting Controls | C19: No
B20: C406.5 On-Site Renewable Energy | C20: No
B21: RESIDENTIAL ENVELOPE (IECC R402 / REScheck)
B22: Ceiling/Attic R-Value | C22: R-49 | D22: Min R-49 Zone 4A typical
B23: Exterior Wall R-Value (cavity + continuous) | C23: R-20 | D23: R-20 or R-13+5ci Zone 4A
B24: Floor R-Value (over uncond. space) | C24: R-19
B25: Slab Perimeter R-Value | C25: R-10 | D25: If applicable
B26: Window U-Factor (max) | C26: 0.30 | D26: IECC Table R402.1.2
B27: Window SHGC (max) | C27: 0.25 | D27: Zone 4A
B28: Blower Door Test Required? | C28: Yes | D28: ≤3.0 ACH50 Zone 4A
B29: Measured ACH50 (post-construction)

Sheet 10_STRUCTURAL
B1: 10 — STRUCTURAL DESIGN PARAMETERS & SPECIAL INSPECTIONS
B3: DESIGN LOADS
B4: Risk Category (ASCE 7 / IBC Table 1604.5) | C4: II | D4: I / II / III / IV
B5: Roof Live Load (psf) | C5: 20
B6: Floor Live Load (psf) | C6: 40 | D6: Residential typical
B7: Ground Snow Load (psf) | C7: 25 | D7: Verify for jurisdiction
B8: Design Wind Speed (mph — ASCE 7-22)
B9: Exposure Category | C9: B | D9: B / C / D
B10: Importance Factor — Wind | C10: 1.0
B11: Importance Factor — Seismic | C11: 1.0
B12: SEISMIC
B13: Seismic Design Category (IBC §1613) | C13: B | D13: A / B / C / D
B14: Spectral Response — Ss (% g) | D14: From USGS hazard map
B15: Spectral Response — S1 (% g)
B16: Site Classification (ASCE 7) | C16: C | D16: A / B / C / D / E / F
B17: Data Source | C17: USGS Hazard Tool | D17: Field test / Presumptive / Historical
B18: Lateral Design Control | C18: Wind | D18: Earthquake / Wind
B19: SOIL
B20: Soil Bearing Capacity (psf) | D20: From geotech report or presumptive
B21: Geotechnical Report Required? | C21: Yes | D21: Required for new construction
B22: Foundation Type | D22: Slab / Spread footing / Pile / Caisson
B23: SPECIAL INSPECTIONS (IBC §1704 / §1705)
B24: Special Inspections Required? | C24: No | D24: Yes / No
B25: Concrete (§1705.3) | C25: No | D25: Yes / No
B26: Steel (§1705.2) | C26: No | D26: Yes / No
B27: Masonry (§1705.4) | C27: No | D27: Yes / No
B28: Wood — High-load diaphragms (§1705.5) | C28: No | D28: Yes / No
B29: SPRFR — Sprayed Fire Resistant Materials (§1705.14) | C29: No | D29: Yes / No
B30: EIFS (§1705.16) | C30: No | D30: Yes / No
B31: Wind-resisting components (§1705.11) | C31: No | D31: Yes / No
B32: Seismic resistance (§1705.12) | C32: No | D32: Yes / No
B33: Penetration firestops (§1705.17) | C33: No | D33: Yes / No
B34: Approved Fabricator (§1704.2.5) | D34: Name if applicable
B36: SEISMIC NONSTRUCTURAL COMPONENT CHECKLIST (IBC §1705.12 / ASCE 7 Ch. 13)
B37: Per IBC 1613.1. Mark each item: ON CD = shown on construction documents | DEF = deferred submittal | NR = not required (per ASCE 7 §13.1.4) | N/A = not on project
B38: COMPONENT | C38: NOT REQ'D | D38: ON CONST DOCS | E38: DEFERRED | F38: NOTES / SPEC REF
B39: ARCHITECTURAL COMPONENTS
B40: Interior nonstructural walls and partitions (§13.5.6)
B41: Cantilever elements — parapets, freestanding walls (§13.5.8)
B42: Exterior nonstructural wall elements and connections (§13.5.3)
...

Sheet 11_CODE_BLOCK
B1: 11 — AUTO-GENERATED CODE SUMMARY BLOCK (copy to Sheet A-001)
B2: ⚡ All fields pull from other tabs. Fill those tabs first. This sheet is read-only output.
B3: CODE SUMMARY — COPY THIS BLOCK TO SHEET A-001
B4: APPLICABLE CODES AS AMENDED BY THE STATE OF DELAWARE:
B5: BUILDING CODE: | C5: ='01_PROJECT_ID'!C13&" INTERNATIONAL BUILDING CODE (IBC)" -> INTERNATIONAL BUILDING CODE (IBC)
B6: EXISTING BUILDING CODE: | C6: ="INTERNATIONAL EXISTING BUILDING CODE (IEBC), "&'01_PROJECT_ID'!C13 -> INTERNATIONAL EXISTING BUILDING CODE (IEBC),
B7: FIRE CODE (STATEWIDE): | C7: ="DELAWARE STATE FIRE PREVENTION REGULATIONS INCL. NFPA 1, NFPA 101" -> DELAWARE STATE FIRE PREVENTION REGULATIONS INCL. NFPA 1, NFPA 101
B8: PLUMBING CODE (STATEWIDE): | C8: ="STATE OF DELAWARE PLUMBING CODE (IPC "&'01_PROJECT_ID'!C15&" WITH DE AMENDMENTS)" -> STATE OF DELAWARE PLUMBING CODE (IPC WITH DE AMENDMENTS)
B9: MECHANICAL CODE: | C9: ="INTERNATIONAL MECHANICAL CODE (IMC), "&'01_PROJECT_ID'!C13 -> INTERNATIONAL MECHANICAL CODE (IMC),
B10: FUEL GAS CODE: | C10: ="INTERNATIONAL FUEL GAS CODE (IFGC), "&'01_PROJECT_ID'!C13 -> INTERNATIONAL FUEL GAS CODE (IFGC),
B11: ENERGY CODE (STATEWIDE): | C11: ="DELAWARE STATE ENERGY CONSERVATION CODE — "&'01_PROJECT_ID'!C16&" IECC WITH DE AMENDMENTS" -> DELAWARE STATE ENERGY CONSERVATION CODE — 2021 IECC WITH DE AMENDMENTS
B12: ACCESSIBILITY: | C12: ="IBC CHAPTER 11 AND ICC A117.1 (2010 EDITION) — ADA STANDARDS 2010" -> IBC CHAPTER 11 AND ICC A117.1 (2010 EDITION) — ADA STANDARDS 2010
B13: LOCAL AMENDMENTS: | C13: =IF('01_PROJECT_ID'!C18="Yes","YES — SEE 14_AMENDMENTS TAB","NONE NOTED") -> NONE NOTED
B15: BUILDING DATA:
B16: PROJECT: | C16: ='01_PROJECT_ID'!C4 -> 0
B17: ADDRESS: | C17: ='01_PROJECT_ID'!C5 -> 0
B18: OCCUPANCY USE GROUP(S): | C18: ='03_IBC_AREA_HEIGHT'!C4 -> 0
B19: CONSTRUCTION TYPE (IBC TABLE 601): | C19: ='03_IBC_AREA_HEIGHT'!C7 -> 0
B20: RISK CATEGORY (IBC TABLE 1604.5): | C20: ='03_IBC_AREA_HEIGHT'!C9 -> 0
B21: SPRINKLER SYSTEM: | C21: ='03_IBC_AREA_HEIGHT'!C8 -> 0
B22: BUILDING AREA: | C22: ='03_IBC_AREA_HEIGHT'!D24&" SF TOTAL" -> SF TOTAL
B23: EXISTING HEIGHT ABOVE GRADE: | C23: ='03_IBC_AREA_HEIGHT'!D11&" FT / "&'03_IBC_AREA_HEIGHT'!D12&" STORIES" -> FT / STORIES
B24: ALLOWABLE HEIGHT: | C24: ='03_IBC_AREA_HEIGHT'!C9&" FT / "&'03_IBC_AREA_HEIGHT'!C10&" STORIES" -> FT / STORIES
B25: ALLOWABLE AREA: | C25: ='03_IBC_AREA_HEIGHT'!C22&" SF/STORY; "&'03_IBC_AREA_HEIGHT'!C23&" SF TOTAL" -> SF/STORY; SF TOTAL
B27: MEANS OF EGRESS (IBC CH. 10):
B28: DESIGN OCCUPANT LOAD: | C28: ='05_LIFE_SAFETY_IBC'!F12&" OCC" -> 0 OCC
B29: NUMBER OF EXITS PROVIDED: | C29: ='05_LIFE_SAFETY_IBC'!D17&" EXITS PROVIDED" -> EXITS PROVIDED
B30: CORRIDOR WIDTH MIN.: | C30: ='05_LIFE_SAFETY_IBC'!D19&" INCHES MIN. (PROVIDED)" -> INCHES MIN. (PROVIDED)
B31: MAX TRAVEL DISTANCE: | C31: ='05_LIFE_SAFETY_IBC'!C22&" FT ALLOWED / "&'05_LIFE_SAFETY_IBC'!D22&" FT PROVIDED" -> FT ALLOWED / FT PROVIDED
B32: FIRE RESISTANCE RATING REQ. (TABLE 601)
B33: STRUCTURAL FRAME: | C33: ='04_FIRE_PROTECTION'!D4 -> 0
B34: BEARING WALLS — EXTERIOR: | C34: ='04_FIRE_PROTECTION'!D5 -> 0
B35: BEARING WALLS — INTERIOR: | C35: ='04_FIRE_PROTECTION'!D10 -> 0
B36: NONBEARING WALLS — EXTERIOR: | C36: ='04_FIRE_PROTECTION'!D11 -> 0
B37: FLOOR CONSTRUCTION: | C37: ='04_FIRE_PROTECTION'!D13 -> 0
B38: ROOF CONSTRUCTION: | C38: ='04_FIRE_PROTECTION'!D15 -> 0
B40: PLUMBING FIXTURES (IPC CH. 4 / TABLE 403.1):
B41: WATER CLOSETS — MALE REQ'D: | C41: ='08_PLUMBING_CALC'!F22 -> 0
B42: WATER CLOSETS — FEMALE REQ'D: | C42: ='08_PLUMBING_CALC'!F23 -> 0
B43: LAVATORIES — MALE REQ'D: | C43: ='08_PLUMBING_CALC'!F24 -> 0
...

Sheet 12_REVIEW_PROTOCOL
B1: 12 — INTERNAL REVIEW PROTOCOL & ALDi GATE SIGN-OFF
B2: REVIEW TASK | C2: ALDi GATE | D2: REVIEWER / ROLE | E2: DATE | F2: INITIALS
B3: G0 — ROM GATE
B4: Jurisdiction confirmed — City vs. County — correct code applied | C4: G0 ROM
B5: Zoning district and UDC URL documented in 02_ZONING | C5: G0 ROM
B6: Occupancy group and construction type confirmed | C6: G0 ROM
B7: Preliminary height/area check — pass/fail noted | C7: G0 ROM
B8: G0 sign-off — David Ainsworth / Predevelopment Lead | C8: G0 ROM
B9: G1 — FEASIBILITY GATE
B10: Life safety schematic complete (egress windows, exits, paths) | C10: G1 Feasibility
B11: Fire separation matrix populated (Tab 04) | C11: G1 Feasibility
B12: Plumbing fixture count preliminary (Tab 08) | C12: G1 Feasibility
B13: Energy code compliance path selected (Tab 09) | C13: G1 Feasibility
B14: Local amendments reviewed and logged in Tab 14 | C14: G1 Feasibility
B15: G1 sign-off — AOR / Project Architect | C15: G1 Feasibility
B16: G2 — 75% DD GATE
B17: Code block verified and copied to Sheet A-001 | C17: G2 75% DD
B18: All Tab 03 pass/fail checks GREEN | C18: G2 75% DD
B19: Fire protection matrix complete with detail sheet refs | C19: G2 75% DD
B20: Structural parameters confirmed with EOR | C20: G2 75% DD
B21: ADA compliance verified — Tab 07 | C21: G2 75% DD
B22: Plumbing fixture count finalized vs. permit set | C22: G2 75% DD
B23: MEP systems summary reviewed by MEP engineers | C23: G2 75% DD
B24: All open flags in Tab 13 resolved or escalated | C24: G2 75% DD
B25: G2 sign-off — AOR + M4D Project Lead | C25: G2 75% DD
B26: G3 — GMP / PRE-PERMIT GATE
B27: Full checklist vs. AHJ submittal requirements | C27: G3 GMP
B28: Deferred submittals list prepared (Tab 10) | C28: G3 GMP
B29: Fire sprinkler / alarm deferred submittal listed if applicable | C29: G3 GMP
B30: Energy calcs stamped by design professional | C30: G3 GMP
B31: Special inspections list prepared and distributed (Tab 10) | C31: G3 GMP
B32: Permit set issued — code block final-checked | C32: G3 GMP
B33: G3 sign-off — AOR | C33: G3 GMP
B34: POST-PERMIT
B35: AHJ plan review comments received — log in Tab 13 | C35: G3 / G4
B36: Comments resolved — resubmission if required | C36: G4 Closeout

Sheet 13_FLAGS
B1: 13 — FLAGS, EXCEPTIONS & OPEN ITEMS LOG
B2: # | C2: DESCRIPTION | D2: CODE REF | E2: OPENED BY | F2: STATUS | G2: RESOLUTION / NOTES
B3: 1
B4: 2
B5: 3
B6: 4
B7: 5
B8: 6
B9: 7
B10: 8
B11: 9
B12: 10
B13: 11
B14: 12
... B22: 20
B23: STATUS OPTIONS: OPEN | IN REVIEW | AHJ COORDINATION | RESOLVED — NO ACTION | RESOLVED — DESIGN CHANGE

Sheet 14_AMENDMENTS
B1: 14 — LOCAL AMENDMENT REGISTRY — JURISDICTION-SPECIFIC CODE OVERRIDES
B2: Log every local amendment here. When ICC updates, review each row. Update IBC/IRC edition in 01_PROJECT_ID and check if amendments still apply.
B3: JURISDICTION | C3: CODE SECTION | D3: STANDARD VALUE | E3: LOCAL OVERRIDE / AMENDMENT | F3: SOURCE URL | G3: VERIFIED DATE
B4: State of Delaware | C4: Fire Code | D4: IFC | E4: Delaware State Fire Prevention Regulations — NFPA 1, NFPA 101, DE State Fire Marshal authority | F4: https://www.statefiredel.com/ | G4: 2026-04
B5: State of Delaware | C5: Plumbing Code | D5: IPC 2021 | E5: State of Delaware Plumbing Code (IPC 2021 with DE amendments) | F5: https://dpr.delaware.gov/ | G5: 2026-04
B6: State of Delaware | C6: Energy Code | D6: IECC 2021 | E6: Delaware State Energy Conservation Code — based on 2018/2021 IECC with DE amendments | F6: https://dnrec.delaware.gov/energy/ | G6: 2026-04
B7: City of Wilmington | C7: Zoning | D7: IBC / Local UDC | E7: Chapter 48, City of Wilmington Code of Ordinances — applies to City parcels only (NOT NCC UDC) | F7: https://library.municode.com/de/wilmington/codes/code_of_ordinances?nodeId=PTIIWICO_CH48ZO | G7: 2026-04
B8: New Castle County | C8: Zoning | D8: NCC UDC | E8: New Castle County Unified Development Code — applies to unincorporated NCC parcels ONLY | F8: https://www.nccde.org/156/Code-of-Ordinances | G8: 2026-04
B9: State of Delaware | C9: Accessibility | D9: ADA 2010 + ICC A117.1-2010 | E9: IBC Chapter 11 — referenced accessibility standard is ICC A117.1 (2010) | F9: https://dpr.delaware.gov/ | G9: 2026-04
B10: State of Delaware | C10: Professional Licensure | D10: AIA / NCARB | E10: Delaware State Board of Architects — Certificate of Authorization required for firm practice | F10: https://dpr.delaware.gov/boards/architects/ | G10: 2026-04
C11: ADD MORE BELOW
B24: JURISDICTION FILTER — amendments matching the jurisdiction selected in 01_PROJECT_ID!C10
B25: Active Jurisdiction (from 01_PROJECT_ID): | C25: ='01_PROJECT_ID'!C10 -> 0
B26: Amendment rows matching this jurisdiction: | C26: =COUNTIF(B4:B21,C25) -> 0 | D26: ↑ Review all matching rows before permit submittal

Sheet 15_DRAWING_CHECKLIST
B1: 15 — CONSTRUCTION DRAWING REQUIREMENTS CHECKLIST — PERMIT SUBMITTAL
B2: Based on IBC §107 submittal requirements + Pacific WA Drawing Requirements + Phoenix Plan Review Checklist. Check applicable type below.
B3: Project Type for This Checklist: | C3: Commercial | D3: Commercial / Residential / Mixed-Use
B5: STATUS KEY: Y = Complete | N = Missing/Incomplete | N/A = Not Applicable
B6: REQUIREMENT (COMMERCIAL — IBC §107) | C6: STATUS | D6: NOTES / SHEET REF
B7: COVER SHEET / CODE DATA (IBC §107.2.1 / Phoenix 1.A)
B8: Cover sheet or code data sheet provided with permit set | D8: IBC 107.2.1
B9: Designer's seal, signature, date on all sheets | D9: IBC 107.1
B10: Adopted code editions listed (IBC, IFC, IMC, IPC, IECC, NEC) | D10: IBC 107.2.1
B11: Complete drawing sheet list in permit scope | D11: IBC 107.2.1
B12: Detailed description of work scope | D12: IBC 105.3
B13: Deferred submittals list with note: 'Do not install until approved' | D13: IBC 107.3.4.1
B14: Registered design professional named with contact info | D14: IBC 107.3.4
B15: Occupancy classification shown on cover | D15: IBC 302.1
B16: Construction type shown on cover | D16: IBC 602.1
B17: Sprinkler system type specified (NFPA 13 / 13R / 13D) | D17: IBC §903
B18: Fire alarm system specified if required | D18: IBC 907.2
B19: Special inspections certificate / statement of SI (if req'd) | D19: IBC 1704.3 / 1705.1.1
B20: Code summary block on cover — completed and accurate | D20: M4Di standard
B21: SITE PLAN (IBC §107.2.6 / §2.A)
B22: Scaled site plan showing all buildings — scale noted with North arrow | D22: IBC 107.2.6
B23: Building footprint dimensions and distance to all property lines | D23: IBC 107.2.6
B24: Building height and stories shown for each structure | D24: IBC 503.1
B25: Building area shown for each structure | D25: IBC 503.1
B26: Fire separation distances (FSD) dimensioned to property lines and public ways | D26: IBC 602.1
B27: Exterior wall fire rating shown for each face vs FSD | D27: IBC 602.1
B28: Wall opening percentages shown for walls with FSD < 20 ft (NFPA 13) or <30 ft (13R) | D28: IBC 705.8
B29: Path of exit discharge shown to public way or safe dispersal area | D29: IBC 1028.5
B30: Photometric plan or 1 fc illumination shown at exit discharge path | D30: IBC 1008.2.1
B31: Accessible parking spaces shown — count, location, van spaces | D31: IBC 1106
B32: Utilities: water, sewer, gas, electricity located on site plan | D32: §107
B33: Site contours and drainage shown
B34: Frontage dimensions shown if used for area increase | D34: IBC 506.3
B35: FLOOR PLANS (IBC §107.2.1 / §3.A)
B36: Floor plan for each story, to scale (min. 1/4" = 1'-0" recommended) | D36: IBC 107.2.1
B37: All spaces labeled with name, occupancy classification, and use | D37: IBC 302.1
B38: Occupant load factor and count shown for each room/space | D38: IBC 1004.5
B39: Egress paths shown — start and stop of travel distance dimensioned | D39: IBC 1017.2
B40: Common path of travel dimensioned | D40: IBC 1006.2.1
B41: Dead-end corridor length dimensioned | D41: IBC 1020.4
...

Sheet 16_MULTI_OCCUPANCY
B1: 16 — MULTI-OCCUPANCY ANALYSIS — IBC §508 / §506.2.4
B2: Use for Separated (§508.4) or Non-Separated (§508.3) mixed occupancies. Yellow = input. Blue = calculated. Sum of story ratios must be ≤ 1.00 (per story, §508.4.2). Aggregate sum across all stories must be ≤ 3 (NS) or ≤ 4 (S).
B3: GLOBAL INPUTS — CONSTRUCTION TYPE & SPRINKLERS
B4: Construction Type | C4: V-B | D4: Sprinkler System | E4: NFPA 13 | F4: Mixed Occ. Method | G4: Separated | H4: Stories Above Grade | I4: 2
B6: STEP 1 — DEFINE OCCUPANCIES (up to 4)
B7: OCCUPANCY GROUP | C7: At (NS, T506.2) SF | D7: NS (T506.2) SF | E7: If (frontage, 0–0.75) | F7: Aa per Story (§506.2) | G7: Separation Required (hrs) | H7: Separation Provided | I7: Separation PASS/FAIL | J7: Notes
B8: Occupancy A | E8: 0 | F8: =IF(C8="","-",C8+(D8*E8)) -> - | I8: =IF(G8="","-",IF(H8>=G8,"PASS","FAIL")) -> - | J8: Enter IBC Table 506.2 values for occ group
B9: Occupancy B | E9: 0 | F9: =IF(C9="","-",C9+(D9*E9)) -> - | I9: =IF(G9="","-",IF(H9>=G9,"PASS","FAIL")) -> - | J9: Enter IBC Table 506.2 values for occ group
B10: Occupancy C | E10: 0 | F10: =IF(C10="","-",C10+(D10*E10)) -> - | I10: =IF(G10="","-",IF(H10>=G10,"PASS","FAIL")) -> - | J10: Enter IBC Table 506.2 values for occ group
B11: Occupancy D | E11: 0 | F11: =IF(C11="","-",C11+(D11*E11)) -> - | I11: =IF(G11="","-",IF(H11>=G11,"PASS","FAIL")) -> - | J11: Enter IBC Table 506.2 values for occ group
B13: STEP 2 — STORY-BY-STORY RATIO MATRIX (§508.4.2 — sum of ratios ≤ 1.00 per story)
B14: STORY | C14: Occ A Actual SF | D14: Occ A Aa | E14: Occ A Ratio | F14: Occ B Actual SF | G14: Occ B Aa | H14: Occ B Ratio | I14: Sum of Ratios | J14: PASS/FAIL (≤1.00)
B15: Story 1 | D15: =F8 -> - | E15: =IF(OR(C15="",D15=0),"-",ROUND(C15/D15,3)) -> - | G15: =F9 -> - | H15: =IF(OR(F15="",G15=0),"-",ROUND(F15/G15,3)) -> - | I15: =IF(E15="-","-",ROUND(E15+H15,3)) -> - | J15: =IF(I15="-","-",IF(I15<=1,"PASS","FAIL")) -> -
B16: Story 2 | D16: =F8 -> - | E16: =IF(OR(C16="",D16=0),"-",ROUND(C16/D16,3)) -> - | G16: =F9 -> - | H16: =IF(OR(F16="",G16=0),"-",ROUND(F16/G16,3)) -> - | I16: =IF(E16="-","-",ROUND(E16+H16,3)) -> - | J16: =IF(I16="-","-",IF(I16<=1,"PASS","FAIL")) -> -
B17: Story 3 | D17: =F8 -> - | E17: =IF(OR(C17="",D17=0),"-",ROUND(C17/D17,3)) -> - | G17: =F9 -> - | H17: =IF(OR(F17="",G17=0),"-",ROUND(F17/G17,3)) -> - | I17: =IF(E17="-","-",ROUND(E17+H17,3)) -> - | J17: =IF(I17="-","-",IF(I17<=1,"PASS","FAIL")) -> -
B18: Story 4 | D18: =F8 -> - | E18: =IF(OR(C18="",D18=0),"-",ROUND(C18/D18,3)) -> - | G18: =F9 -> - | H18: =IF(OR(F18="",G18=0),"-",ROUND(F18/G18,3)) -> - | I18: =IF(E18="-","-",ROUND(E18+H18,3)) -> - | J18: =IF(I18="-","-",IF(I18<=1,"PASS","FAIL")) -> -
B19: Story 5 | D19: =F8 -> - | E19: =IF(OR(C19="",D19=0),"-",ROUND(C19/D19,3)) -> - | G19: =F9 -> - | H19: =IF(OR(F19="",G19=0),"-",ROUND(F19/G19,3)) -> - | I19: =IF(E19="-","-",ROUND(E19+H19,3)) -> - | J19: =IF(I19="-","-",IF(I19<=1,"PASS","FAIL")) -> -
B20: Story 6 | D20: =F8 -> - | E20: =IF(OR(C20="",D20=0),"-",ROUND(C20/D20,3)) -> - | G20: =F9 -> - | H20: =IF(OR(F20="",G20=0),"-",ROUND(F20/G20,3)) -> - | I20: =IF(E20="-","-",ROUND(E20+H20,3)) -> - | J20: =IF(I20="-","-",IF(I20<=1,"PASS","FAIL")) -> -
B21: AGGREGATE SUM OF RATIOS — ALL STORIES (§506.2.4 — must be ≤ 3 for NS, ≤ 4 for S) | I21: =SUMIF(I15:I20,"<>-",I15:I20) -> 0 | J21: =IF(G4="Non-Separated",IF(I21<=3,"PASS","FAIL"),IF(I21<=4,"PASS","FAIL")) -> PASS
B23: REFERENCE — IBC 2021 TABLE 506.2 (COMMON VALUES — VERIFY WITH CURRENT CODE)
B24: OCCUPANCY | C24: TYPE V-B NS (SF) | D24: TYPE V-B S1 (SF) | E24: TYPE III-A NS (SF) | F24: TYPE III-A S1 (SF) | G24: TYPE II-B NS (SF) | H24: TYPE II-B S1 (SF) | I24: TYPE I-B NS (SF) | J24: TYPE I-B S1 (SF)
B25: B — Business | C25: 9500 | D25: 23750 | E25: 18000 | F25: 54000 | G25: 23000 | H25: 69000 | I25: UL | J25: UL
B26: R-2 — Residential | C26: 7000 | D26: 21000 | E26: 12000 | F26: 36000 | G26: 16000 | H26: 48000 | I26: UL | J26: UL
B27: A-2 — Assembly/dining | C27: 6000 | D27: 18000 | E27: 9500 | F27: 28500 | G27: 14000 | H27: 42000 | I27: UL | J27: UL
B28: E — Educational | C28: 14000 | D28: 35000 | E28: 23500 | F28: 58750 | G28: 26500 | H28: 66250 | I28: UL | J28: UL
B29: M — Mercantile | C29: 14000 | D29: 35000 | E29: 21500 | F29: 53750 | G29: 25500 | H29: 63750 | I29: UL | J29: UL
B30: I-2 — Institutional | C30: 12000 | D30: 25000 | E30: 18000 | F30: 45000 | G30: 24000 | H30: 60000 | I30: UL | J30: UL
B31: S-1 — Storage | C31: 17500 | D31: 26250 | E31: 26000 | F31: 39000 | G31: 26000 | H31: 39000 | I31: UL | J31: UL
B32: F-1 — Factory | C32: 15500 | D32: 38750 | E32: 25500 | F32: 63750 | G32: 25500 | H32: 63750 | I32: UL | J32: UL
B33: UL = Unlimited Area. Values shown are tabular At only — apply NS and Sa multipliers per §506.2. Always verify with adopted IBC edition.

Sheet 17_MECHANICAL
B1: 17 — MECHANICAL CODE REQUIREMENTS & CALCULATIONS — IMC 2021 / ASHRAE 62.1
B2: Yellow = input. Blue = calculated output. Ventilation values per ASHRAE 62.1-2019 / IMC §403. Equipment sizing is schematic — confirm with licensed MEP engineer.
B3: A — PROJECT CLIMATE & HVAC SYSTEM IDENTIFICATION
B4: PARAMETER | C4: VALUE | D4: UNIT / OPTION | E4: PASS/FAIL | F4: NOTES
B5: Climate Zone | C5: 4A | D5: IECC Zone | F5: DE/PA/MD/NJ = Zone 4A typical
B6: Winter Design Dry Bulb (°F) | C6: 14 | D6: °F | F6: ASHRAE 99% condition
B7: Summer Design Dry Bulb (°F) | C7: 91 | D7: °F | F7: ASHRAE 1% condition
B8: Summer Wet Bulb (°F) | C8: 76 | D8: °F | F8: Cooling coil sizing
B9: Interior Heating Setpoint (°F) | C9: 70 | D9: °F
B10: Interior Cooling Setpoint (°F) | C10: 75 | D10: °F
B11: Relative Humidity — Winter (%) | C11: 30 | D11: %
B12: Relative Humidity — Summer (%) | C12: 50 | D12: %
B13: Gross Building Area (SF) | D13: SF | F13: From 01_PROJECT_ID / 03_IBC
B14: HVAC System Type | C14: Forced Air / AHU | D14: System description | F14: Forced Air / Fan Coil / VRF / Radiant / Chilled Beam / GSHP
B15: Heating Source | C15: Gas Furnace / Boiler | F15: Gas / Electric / Heat Pump / District
B16: Cooling Source | C16: DX / Chiller | F16: DX / Chiller / VRF / Evap
B17: Zoning Strategy | C17: Single zone | F17: Single zone / Multi-zone VAV / Zone-by-zone
B18: Estimated Heating Load (BTUH) | D18: BTUH | F18: From Manual J or energy model
B19: Estimated Cooling Load (BTUH) | D19: BTUH
B20: Estimated Heating Load (Tons equiv.) | D20: Tons | F20: =BTUH/12000 -> #NAME?
B21: Estimated Cooling Load (Tons) | D21: Tons | F21: =BTUH/12000 -> #NAME?
B23: B — OUTDOOR AIR VENTILATION CALCULATION (ASHRAE 62.1-2019 / IMC §403)
B24: Vbz = Rp × Pz + Ra × Az | Rp = people rate (CFM/person) | Ra = area rate (CFM/SF) | Pz = zone occupant load | Az = zone floor area
B25: ZONE / SPACE | C25: Area Az (SF) | D25: Occ Load Pz | E25: Rp (CFM/person) | F25: Ra (CFM/SF) | G25: People OA (CFM) | H25: Area OA (CFM)
B26: Office / General | E26: 5 | F26: 0.06 | G26: =IF(D26="",0,D26*E26) -> 0 | H26: =IF(C26="",0,C26*F26) -> 0
B27: Conference / Meeting | E27: 5 | F27: 0.06 | G27: =IF(D27="",0,D27*E27) -> 0 | H27: =IF(C27="",0,C27*F27) -> 0
B28: Lobby / Reception | E28: 5 | F28: 0.06 | G28: =IF(D28="",0,D28*E28) -> 0 | H28: =IF(C28="",0,C28*F28) -> 0
B29: Retail Sales Area | E29: 3.8 | F29: 0.12 | G29: =IF(D29="",0,D29*E29) -> 0 | H29: =IF(C29="",0,C29*F29) -> 0
B30: Corridor | E30: 0 | G30: =IF(D30="",0,D30*E30) -> 0 | H30: =IF(C30="",0,C30*F30) -> 0
B31: Restrooms / Toilet | E31: 0 | F31: 0.06 | G31: =IF(D31="",0,D31*E31) -> 0 | H31: =IF(C31="",0,C31*F31) -> 0
B32: Kitchen / Break Room | E32: 7.5 | F32: 0.18 | G32: =IF(D32="",0,D32*E32) -> 0 | H32: =IF(C32="",0,C32*F32) -> 0
B33: Mechanical Room | E33: 0 | F33: 0 | G33: =IF(D33="",0,D33*E33) -> 0 | H33: =IF(C33="",0,C33*F33) -> 0
B34: TOTAL OUTDOOR AIR REQUIRED (Vbz) | G34: =SUM(G26:G33) -> 0 | H34: =SUM(H26:H33) -> 0
B36: TOTAL OUTDOOR AIR SUMMARY
B37: Total People-Based OA (CFM) | C37: =G35 -> 0
B38: Total Area-Based OA (CFM) | C38: =H36 -> 0
B39: TOTAL Vbz (People + Area, CFM) | C39: =C37+C38 -> 0
B40: Min. OA % of Supply Air (typical 20–30%) | C40: 0.25
B41: Estimated Total Supply CFM | C41: =IFERROR(C38/C40,"—") -> 0 | D41: =Vbz / OA% -> #NAME?
B43: C — EXHAUST SYSTEM REQUIREMENTS (IMC §501–504 / ASHRAE 62.1 TABLE 6.2)
...

Sheet DATA_LISTS
A1: Jurisdictions | B1: Occupancy Groups | C1: Construction Types | D1: Sprinkler Types | E1: IBC Editions | F1: Project Types | G1: ALDi Gates | H1: Risk Categories | I1: Y_N_NA | J1: Compliance Methods | K1: Exposure Categories | L1: Seismic Design Categories | M1: Lead Firms | N1: Mixed Occ Methods | O1: Ventilation Space Types | P1: HVAC System Types
A2: City of Wilmington, DE | B2: A-1 | C2: I-A | D2: None | E2: 2021 | F2: Commercial | G2: G0 — ROM | H2: I | I2: Y | J2: Prescriptive | K2: B | L2: A | M2: Merge 4 Design LLC | N2: Separated | O2: Office/General | P2: Forced Air / Single-Zone AHU
A3: New Castle County (unincorporated), DE | B3: A-2 | C3: I-B | D3: NFPA 13 | E3: 2018 | F3: Residential — 1-2 Family | G3: G1 — Feasibility | H3: II | I3: N | J3: Performance | K3: C | L3: B | M3: Aubyn Architecture LLC | N3: Non-Separated | O3: Conference Room | P3: Forced Air / Multi-Zone VAV
A4: City of Newark, DE | B4: A-3 | C4: II-A | D4: NFPA 13R | E4: 2015 | F4: Residential — 3-4 Family | G4: G2 — 75% DD | H4: III | I4: N/A | J4: ASHRAE 90.1 | K4: D | L4: C | N4: Accessory | O4: Reception/Lobby | P4: Fan Coil Units (FCU)
A5: City of Dover, DE | B5: A-4 | C5: II-B | D5: NFPA 13D | E5: 2012 | F5: Townhouse | G5: G3 — GMP / Pre-Permit | H5: IV | J5: REScheck | L5: D | N5: Incidental | O5: Break Room/Kitchen | P5: Variable Refrigerant Flow (VRF)
A6: City of Middletown, DE | B6: A-5 | C6: III-A | E6: Local amendment — see 14_AMENDMENTS | F6: Mixed-Use | G6: G4 — Closeout | J6: COMcheck | L6: E | O6: Retail Sales | P6: Chilled Beam
A7: City of Philadelphia, PA | B7: B | C7: III-B | F7: Institutional | L7: F | O7: Corridor/Utility | P7: Ground-Source Heat Pump (GSHP)
A8: Montgomery County, PA | B8: E | C8: IV-A | F8: Adaptive Reuse | O8: Toilet/Restroom | P8: Dedicated Outdoor Air System (DOAS)
A9: Delaware County, PA | B9: F-1 | C9: IV-B | F9: Addition | O9: Parking Garage | P9: Radiant Floor / Ceiling
A10: Chester County, PA | B10: F-2 | C10: IV-C | F10: Alteration — Level I | O10: Laboratory | P10: Packaged Rooftop Unit (RTU)
A11: Fairfield County, CT | B11: H-1 | C11: IV-HT | F11: Alteration — Level II | O11: Classroom | P11: Split System DX
A12: Other — see 14_AMENDMENTS | B12: H-2 | C12: V-A | F12: Alteration — Level III | O12: Medical Exam Room | P12: Mini-Split Ductless
B13: H-3 | C13: V-B | F13: Change of Use | O13: Patient Room | P13: Steam / Hot Water Radiant
B14: H-4 | O14: Assembly/Theater | P14: Evaporative Cooling
B15: H-5 | O15: Dining
B16: I-1 | O16: Hotel Room
B17: I-2 | O17: Health Club/Gym
B18: I-3 | O18: Warehouse/Storage
B19: I-4
B20: M
B21: R-1
B22: R-2
B23: R-3
B24: R-4
B25: S-1
B26: S-2
B27: U
